Workbook

Sheet Form responses 1
A1: Timestamp | B1: Nomor Tiket (Kode Loket/No Antrian/ddmmyy/No urut berkas) | C1: Nama Pemohon | D1: Nomor Telpon (pastikan nomor tlpn aktif) | E1: Jenis Permohonan | F1: Nomor Hak Sebelum Gandes (jika ada) *Format (Jenis Hak.Nomor Hak/Kelurahan-Sekarang;Jenis Hak.Nomor Hak/Kelurahan-Dahulu) *Jika tanpa Sertipikat beri "-" | G1: Nama Petugas Loket | H1: Pembetulan Berkas ke.... | I1: Kelurahan Sekarang | J1: Nomor Hak Sebelum Gandes (jika ada) *Format ( Jenis Hak.Nomor Hak/Kelurahan-Sekarang) *Jika tanpa Sertipikat beri atau tidak gandes beri tanda "-" | L1: Combine
A4: 45579.361 | B4: L/1/141024/1 | C4: CHAIRUL ANWAR SATAR | D4: 082175406622 | E4: ROYA | F4: HM 9463/GEDUNG MENENG | G4: Deby | H4: P0 | I4: GEDUNG MENENG
A5: 45579.377 | B5: L/2/141024/1 | C5: RIRIN OKTARINA | D5: 089632241202 | E5: ROYA | F5: HM 17565/SUKARAME I | G5: Deby | H5: P0 | I5: SUKARAME I
A6: 45579.399 | B6: K/3/141024/1 | C6: GURUH SAMODRA AJI, ST.MT/WAHYUDIN | D6: 082371259997 | E6: PTPGT | F6: - | G6: Baynur | H6: P0 | I6: WAY LAGA
A7: 45579.401 | B7: K/4/141024/2 | C7: GURUH SAMODRA AJI, ST.MT/WAHYUDIN | D7: 082371259997 | E7: PTPGT | F7: - | G7: Baynur | H7: P0 | I7: WAY LAGA
A8: 45579.403 | B8: L/5/141024/1 | C8: SITI NAZROH | D8: 08117208600 | E8: ROYA | F8: M.9974/TANJUNG BARU | G8: Nuraini | H8: P0 | I8: TANJUNG BARU
A9: 45579.405 | B9: L/6/141024/1 | C9: EMY MARSINEM | D9: 081272529928 | E9: PLOT SERTIPIKAT HILANG | F9: HM 154/SUSUNAN BARU | G9: Deby | H9: P0 | I9: SUSUNAN BARU
A10: 45579.41 | B10: K/7/141024/1 | C10: IKE FEBRINA, S.IP | D10: 081927983379 | E10: ANGKAT SITA | F10: M. 631/Pahoman- sekarang; M. 631/Pahoman-Dahulu | G10: Hananda | H10: P0 | I10: PAHOMAN
A11: 45579.416 | B11: L/8/141024/1 | C11: JUNAIDI | D11: 082377111476 | E11: HAPUS BPHTB | F11: M.1134/GULAK GALIK | G11: Nuraini | H11: P0 | I11: GULAK GALIK
A12: 45579.424 | B12: K/9/141024/1 | C12: LEOSA AUGDETA/LINGGA AYU B | D12: 082175944544 | E12: ROYA | F12: M.11980/JAGABAYA II | G12: Baynur | H12: P0 | I12: JAGABAYA II
A13: 45579.435 | B13: L/11/141024/1 | C13: HENNY INDRIYANI | D13: 081369690601 | E13: ROYA | F13: HM 1505 LABUHAN DALAM & HM 1506 LABUHAN DALAM | G13: Deby | H13: P0 | I13: LABUHAN DALAM
A14: 45579.445 | B14: K/10/141024/2 | C14: ANTONI SINULINGGA /LINGGA A | D14: 082175944544 | E14: GANDES | F14: - | G14: Baynur | H14: P0 | I14: TANJUNG SENENG
A15: 45579.446 | B15: K/12/141024/1 | C15: META ARIDHOTU PRANATA /PANARY SITOPU | D15: 081361444098 | E15: ROYA | F15: M.3326/LANGKAPURA | G15: Baynur | H15: P0 | I15: LANGKAPURA
... A1505: 45613.434 | B1505: L/1/171125/1 | C1505: MOH SOCHIB HIDAYATULLAH | D1505: 085378788988 | E1505: SKPT INFORMASI | F1505: B. 1356/TANJUNG SENENG | G1505: Hananda | H1505: P0 | I1505: TANJUNG SENENG
L1506: =if(A1506="","", CONCATENATE("Sekarang;",F1506," Dahulu;",J1506))
L1507: =if(A1507="","", CONCATENATE("Sekarang;",F1507," Dahulu;",J1507))
L1508: =if(A1508="","", CONCATENATE("Sekarang;",F1508," Dahulu;",J1508))
L1509: =if(A1509="","", CONCATENATE("Sekarang;",F1509," Dahulu;",J1509))
L1510: =if(A1510="","", CONCATENATE("Sekarang;",F1510," Dahulu;",J1510))
L1511: =if(A1511="","", CONCATENATE("Sekarang;",F1511," Dahulu;",J1511))
L1512: =if(A1512="","", CONCATENATE("Sekarang;",F1512," Dahulu;",J1512))
L1513: =if(A1513="","", CONCATENATE("Sekarang;",F1513," Dahulu;",J1513))
L1514: =if(A1514="","", CONCATENATE("Sekarang;",F1514," Dahulu;",J1514))
L1515: =if(A1515="","", CONCATENATE("Sekarang;",F1515," Dahulu;",J1515))
L1516: =if(A1516="","", CONCATENATE("Sekarang;",F1516," Dahulu;",J1516))
L1517: =if(A1517="","", CONCATENATE("Sekarang;",F1517," Dahulu;",J1517))
... L2604: =if(A2604="","", CONCATENATE("Sekarang;",F2604," Dahulu;",J2604))

Sheet Verifikator
A1: ` | B1: kf | C1: 2 | D1: =C1+1 -> 3 | E1: =D1+1 -> 4 | F1: =E1+1 -> 5 | G1: =F1+1 -> 6 | H1: =G1+1 -> 7 | J1: =H1+1 -> 8 | K1: =J1+1 -> 9 | L1: =K1+1 -> 10 | M1: =L1+1 -> 11 | N1: =M1+1 -> 12 | O1: =N1+1 -> 13 | P1: =O1+1 -> 14 | Q1: =P1+1 -> 15 | R1: =Q1+1 -> 16 | ... V1: =U1+1 -> 20 | X1: =V1+1 -> 21 | Y1: =X1+1 -> 22
B3: Nomor Tiket | C3: Tanggal Pemohonan Masuk | D3: Combine | E3: Nama Pemohon | F3: Nomor Telpon | G3: Jenis Permohonan | H3: Nomor Hak | I3: Kelurahan | J3: Nama Petugas Loket | K3: Nama Verifikator | L3: Tanggal Terima Berkas (Verifikator) | M3: Catatan 1 | N3: Catatan 2 | O3: Catatan 3 | P3: Catatan 4 | Q3: Catatan 5 | R3: Catatan 6 | S3: Catatan 7 | T3: Catatan 8 | U3: Catatan 9 | V3: Catatan 10 | W3: Status Berkas | X3: Tanggal Selesai Verifikasi | Y3: Cetak Form Perbaikan | Z3: Kolom sajian Perbaiakan | AA3: TANGGAL DIKEMBALIKAN | AB3: catatan
B4: L/17/141024/1 | C4: {=IF(B4="","",_xlfn.XLOOKUP(B4,'Form responses 1'!$B$2:$B$2604,'Form responses 1'!$A$2:$A$2604,""))} -> 45579.478 | D4: =if(and(B4="",C4=""),"",CONCATENATE(B4,"_",C4)) -> L/17/141024/1_45579.4777229977 | E4: {=IF(B4="","",_xlfn.XLOOKUP(B4,'Form responses 1'!$B$2:$B$2604,'Form responses 1'!$C$2:$C$2604,""))} -> SARIFUDDIN HUTAGALUNG | F4: {=IF(B4="","",_xlfn.XLOOKUP(B4,'Form responses 1'!$B$2:$B$2604,'Form responses 1'!$D$2:$D$2604,""))} -> 081369303456 | G4: {=IF(B4="","",_xlfn.XLOOKUP(B4,'Form responses 1'!$B$2:$B$2604,'Form responses 1'!$E$2:$E$2604,""))} -> ROYA | H4: {=IF(B4="","",_xlfn.XLOOKUP(B4,'Form responses 1'!$B$2:$B$2604,'Form responses 1'!$F$2:$F$2604,""))} -> HM 2144/WAY KANDIS | I4: {=IF(B4="","",_xlfn.XLOOKUP(B4,'Form responses 1'!$B$2:$B$2604,'Form responses 1'!$I$2:$I$2604,""))} -> WAY KANDIS | J4: {=IF(B4="","",_xlfn.XLOOKUP(B4,'Form responses 1'!$B$2:$B$2604,'Form responses 1'!$G$2:$G$2604,""))} -> Deby | K4: Fikka | L4: =IF(K4<>"",IF(L4<>"",L4,NOW()),"") -> 45579.712 | M4: PLOTING + VALBID | N4: BEDA NAMA PEMILIK ANTARA SERTIPIKAT DAN KTP | W4: PERBAIKAN | X4: =IF(W4<>"",IF(X4<>"",X4,NOW()),"") -> 45579.697 | Y4: Cetak | Z4: =COUNTA(M4:V4) -> 2
B5: K/41/141024/1 | C5: {=IF(B5="","",_xlfn.XLOOKUP(B5,'Form responses 1'!$B$2:$B$2604,'Form responses 1'!$A$2:$A$2604,""))} -> 45579.616 | D5: =if(and(B5="",C5=""),"",CONCATENATE(B5,"_",C5)) -> K/41/141024/1_45579.6163003704 | E5: {=IF(B5="","",_xlfn.XLOOKUP(B5,'Form responses 1'!$B$2:$B$2604,'Form responses 1'!$C$2:$C$2604,""))} -> RAHMADIYANTI | F5: {=IF(B5="","",_xlfn.XLOOKUP(B5,'Form responses 1'!$B$2:$B$2604,'Form responses 1'!$D$2:$D$2604,""))} -> 082182090051 | G5: {=IF(B5="","",_xlfn.XLOOKUP(B5,'Form responses 1'!$B$2:$B$2604,'Form responses 1'!$E$2:$E$2604,""))} -> ROYA | H5: {=IF(B5="","",_xlfn.XLOOKUP(B5,'Form responses 1'!$B$2:$B$2604,'Form responses 1'!$F$2:$F$2604,""))} -> M. 2283/ GEDONG AIR | I5: {=IF(B5="","",_xlfn.XLOOKUP(B5,'Form responses 1'!$B$2:$B$2604,'Form responses 1'!$I$2:$I$2604,""))} -> GEDONG AIR | J5: {=IF(B5="","",_xlfn.XLOOKUP(B5,'Form responses 1'!$B$2:$B$2604,'Form responses 1'!$G$2:$G$2604,""))} -> Hananda | K5: Ila Nofri | L5: =IF(K5<>"",IF(L5<>"",L5,NOW()),"") -> 45579.712 | M5: Validator (Tanggal lahir berbeda pada sertipikat dan kkp) (15-10-2024) | W5: SELESAI (LENGKAP) | X5: =IF(W5<>"",IF(X5<>"",X5,NOW()),"") -> 45580.626 | Y5: Cetak | Z5: =COUNTA(M5:V5) -> 1 | AB5: validator
B6: K/9/141024/1 | C6: {=IF(B6="","",_xlfn.XLOOKUP(B6,'Form responses 1'!$B$2:$B$2604,'Form responses 1'!$A$2:$A$2604,""))} -> 45579.424 | D6: =if(and(B6="",C6=""),"",CONCATENATE(B6,"_",C6)) -> K/9/141024/1_45579.4239733565 | E6: {=IF(B6="","",_xlfn.XLOOKUP(B6,'Form responses 1'!$B$2:$B$2604,'Form responses 1'!$C$2:$C$2604,""))} -> LEOSA AUGDETA/LINGGA AYU B | F6: {=IF(B6="","",_xlfn.XLOOKUP(B6,'Form responses 1'!$B$2:$B$2604,'Form responses 1'!$D$2:$D$2604,""))} -> 082175944544 | G6: {=IF(B6="","",_xlfn.XLOOKUP(B6,'Form responses 1'!$B$2:$B$2604,'Form responses 1'!$E$2:$E$2604,""))} -> ROYA | H6: {=IF(B6="","",_xlfn.XLOOKUP(B6,'Form responses 1'!$B$2:$B$2604,'Form responses 1'!$F$2:$F$2604,""))} -> M.11980/JAGABAYA II | I6: {=IF(B6="","",_xlfn.XLOOKUP(B6,'Form responses 1'!$B$2:$B$2604,'Form responses 1'!$I$2:$I$2604,""))} -> JAGABAYA II | J6: {=IF(B6="","",_xlfn.XLOOKUP(B6,'Form responses 1'!$B$2:$B$2604,'Form responses 1'!$G$2:$G$2604,""))} -> Baynur | K6: Ila Nofri | L6: =IF(K6<>"",IF(L6<>"",L6,NOW()),"") -> 45579.712 | M6: Validasi bidang /TT (15-10-2024) | N6: Legalisir KTP kreditur | W6: PERBAIKAN | X6: =IF(W6<>"",IF(X6<>"",X6,NOW()),"") -> 45580.583 | Y6: Cetak | Z6: =COUNTA(M6:V6) -> 2 | AB6: validator
B7: K/30/141024/1 | C7: {=IF(B7="","",_xlfn.XLOOKUP(B7,'Form responses 1'!$B$2:$B$2604,'Form responses 1'!$A$2:$A$2604,""))} -> 45579.58 | D7: =if(and(B7="",C7=""),"",CONCATENATE(B7,"_",C7)) -> K/30/141024/1_45579.5802127199 | E7: {=IF(B7="","",_xlfn.XLOOKUP(B7,'Form responses 1'!$B$2:$B$2604,'Form responses 1'!$C$2:$C$2604,""))} -> SUHARTONO/KRISTINA SIAHAAN | F7: {=IF(B7="","",_xlfn.XLOOKUP(B7,'Form responses 1'!$B$2:$B$2604,'Form responses 1'!$D$2:$D$2604,""))} -> 085359481748 | G7: {=IF(B7="","",_xlfn.XLOOKUP(B7,'Form responses 1'!$B$2:$B$2604,'Form responses 1'!$E$2:$E$2604,""))} -> ROYA | H7: {=IF(B7="","",_xlfn.XLOOKUP(B7,'Form responses 1'!$B$2:$B$2604,'Form responses 1'!$F$2:$F$2604,""))} -> M.2617/WAY KANDIS | I7: {=IF(B7="","",_xlfn.XLOOKUP(B7,'Form responses 1'!$B$2:$B$2604,'Form responses 1'!$I$2:$I$2604,""))} -> WAY KANDIS | J7: {=IF(B7="","",_xlfn.XLOOKUP(B7,'Form responses 1'!$B$2:$B$2604,'Form responses 1'!$G$2:$G$2604,""))} -> Baynur | K7: Ila Nofri | M7: ACC TGL 22-10-2024 | W7: SELESAI (LENGKAP) | X7: =IF(W7<>"",IF(X7<>"",X7,NOW()),"") -> 45583.598 | Y7: Cetak | Z7: =COUNTA(M7:V7) -> 1
B8: L/8/141024/1 | C8: {=IF(B8="","",_xlfn.XLOOKUP(B8,'Form responses 1'!$B$2:$B$2604,'Form responses 1'!$A$2:$A$2604,""))} -> 45579.416 | D8: =if(and(B8="",C8=""),"",CONCATENATE(B8,"_",C8)) -> L/8/141024/1_45579.4161745139 | E8: {=IF(B8="","",_xlfn.XLOOKUP(B8,'Form responses 1'!$B$2:$B$2604,'Form responses 1'!$C$2:$C$2604,""))} -> JUNAIDI | F8: {=IF(B8="","",_xlfn.XLOOKUP(B8,'Form responses 1'!$B$2:$B$2604,'Form responses 1'!$D$2:$D$2604,""))} -> 082377111476 | G8: {=IF(B8="","",_xlfn.XLOOKUP(B8,'Form responses 1'!$B$2:$B$2604,'Form responses 1'!$E$2:$E$2604,""))} -> HAPUS BPHTB | H8: {=IF(B8="","",_xlfn.XLOOKUP(B8,'Form responses 1'!$B$2:$B$2604,'Form responses 1'!$F$2:$F$2604,""))} -> M.1134/GULAK GALIK | I8: {=IF(B8="","",_xlfn.XLOOKUP(B8,'Form responses 1'!$B$2:$B$2604,'Form responses 1'!$I$2:$I$2604,""))} -> GULAK GALIK | J8: {=IF(B8="","",_xlfn.XLOOKUP(B8,'Form responses 1'!$B$2:$B$2604,'Form responses 1'!$G$2:$G$2604,""))} -> Nuraini | K8: Ila Nofri | L8: =IF(K8<>"",IF(L8<>"",L8,NOW()),"") -> 45579.712 | M8: ACC TGL15-10-2024 | W8: SELESAI (LENGKAP) | X8: =IF(W8<>"",IF(X8<>"",X8,NOW()),"") -> 45580.617 | Y8: Cetak | Z8: =COUNTA(M8:V8) -> 1
B9: K/36/141024/1 | C9: {=IF(B9="","",_xlfn.XLOOKUP(B9,'Form responses 1'!$B$2:$B$2604,'Form responses 1'!$A$2:$A$2604,""))} -> 45579.598 | D9: =if(and(B9="",C9=""),"",CONCATENATE(B9,"_",C9)) -> K/36/141024/1_45579.5983292708 | E9: {=IF(B9="","",_xlfn.XLOOKUP(B9,'Form responses 1'!$B$2:$B$2604,'Form responses 1'!$C$2:$C$2604,""))} -> YUDA SAPUTRA/I MADE RETUG | F9: {=IF(B9="","",_xlfn.XLOOKUP(B9,'Form responses 1'!$B$2:$B$2604,'Form responses 1'!$D$2:$D$2604,""))} -> 0853-8479-7293 | G9: {=IF(B9="","",_xlfn.XLOOKUP(B9,'Form responses 1'!$B$2:$B$2604,'Form responses 1'!$E$2:$E$2604,""))} -> PERALIHAN JUAL BELI | H9: {=IF(B9="","",_xlfn.XLOOKUP(B9,'Form responses 1'!$B$2:$B$2604,'Form responses 1'!$F$2:$F$2604,""))} -> M.250/LANGKAPURA BARU | I9: {=IF(B9="","",_xlfn.XLOOKUP(B9,'Form responses 1'!$B$2:$B$2604,'Form responses 1'!$I$2:$I$2604,""))} -> LANGKAPURA BARU | J9: {=IF(B9="","",_xlfn.XLOOKUP(B9,'Form responses 1'!$B$2:$B$2604,'Form responses 1'!$G$2:$G$2604,""))} -> Baynur | K9: Ila Nofri | L9: =IF(K9<>"",IF(L9<>"",L9,NOW()),"") -> 45579.713 | M9: Lampirkan fotokopi KTP penerima kuasa (15-10-2024) | N9: Tanda tangan pembeli berbeda pada KTP, akta, surat kuasa, surat pernyataan | W9: PERBAIKAN | X9: =IF(W9<>"",IF(X9<>"",X9,NOW()),"") -> 45580.626 | Y9: Cetak | Z9: =COUNTA(M9:V9) -> 2
B10: K/22/141024/1 | C10: {=IF(B10="","",_xlfn.XLOOKUP(B10,'Form responses 1'!$B$2:$B$2604,'Form responses 1'!$A$2:$A$2604,""))} -> 45579.497 | D10: =if(and(B10="",C10=""),"",CONCATENATE(B10,"_",C10)) -> K/22/141024/1_45579.4967951736 | E10: {=IF(B10="","",_xlfn.XLOOKUP(B10,'Form responses 1'!$B$2:$B$2604,'Form responses 1'!$C$2:$C$2604,""))} -> MURSALIN | F10: {=IF(B10="","",_xlfn.XLOOKUP(B10,'Form responses 1'!$B$2:$B$2604,'Form responses 1'!$D$2:$D$2604,""))} -> 085383885939 | G10: {=IF(B10="","",_xlfn.XLOOKUP(B10,'Form responses 1'!$B$2:$B$2604,'Form responses 1'!$E$2:$E$2604,""))} -> PERALIHAN JUAL BELI | H10: {=IF(B10="","",_xlfn.XLOOKUP(B10,'Form responses 1'!$B$2:$B$2604,'Form responses 1'!$F$2:$F$2604,""))} -> M. 6977/ TANJUNG SENANG | I10: {=IF(B10="","",_xlfn.XLOOKUP(B10,'Form responses 1'!$B$2:$B$2604,'Form responses 1'!$I$2:$I$2604,""))} -> TANJUNG SENANG | J10: {=IF(B10="","",_xlfn.XLOOKUP(B10,'Form responses 1'!$B$2:$B$2604,'Form responses 1'!$G$2:$G$2604,""))} -> Hananda | K10: Ila Nofri | L10: =IF(K10<>"",IF(L10<>"",L10,NOW()),"") -> 45579.713 | M10: Lampirkan PJB No.3 tgl. 2-8-2024 (15-10-2024) | N10: Kalimat penutup akta agar dilengkapi | O10: Lampirkan bukti Bayar BPHTB yang terbaca | P10: Nama pembeli pada SP BPHTB M. Ismunadi | Q10: Nama pembeli pada SP keterlambatan pendaftaran yusuf hasyim | R10: acc | W10: SELESAI (LENGKAP) | X10: =IF(W10<>"",IF(X10<>"",X10,NOW()),"") -> 45589.42 | Y10: Cetak | Z10: =COUNTA(M10:V10) -> 6
B11: L/21/141024/1 | C11: {=IF(B11="","",_xlfn.XLOOKUP(B11,'Form responses 1'!$B$2:$B$2604,'Form responses 1'!$A$2:$A$2604,""))} -> 45579.493 | D11: =if(and(B11="",C11=""),"",CONCATENATE(B11,"_",C11)) -> L/21/141024/1_45579.4926688773 | E11: {=IF(B11="","",_xlfn.XLOOKUP(B11,'Form responses 1'!$B$2:$B$2604,'Form responses 1'!$C$2:$C$2604,""))} -> DWI ASTANTO | F11: {=IF(B11="","",_xlfn.XLOOKUP(B11,'Form responses 1'!$B$2:$B$2604,'Form responses 1'!$D$2:$D$2604,""))} -> 081369408334 | G11: {=IF(B11="","",_xlfn.XLOOKUP(B11,'Form responses 1'!$B$2:$B$2604,'Form responses 1'!$E$2:$E$2604,""))} -> ROYA | H11: {=IF(B11="","",_xlfn.XLOOKUP(B11,'Form responses 1'!$B$2:$B$2604,'Form responses 1'!$F$2:$F$2604,""))} -> HM 1812/TANJUNG SENANG | I11: {=IF(B11="","",_xlfn.XLOOKUP(B11,'Form responses 1'!$B$2:$B$2604,'Form responses 1'!$I$2:$I$2604,""))} -> TANJUNG SENANG | J11: {=IF(B11="","",_xlfn.XLOOKUP(B11,'Form responses 1'!$B$2:$B$2604,'Form responses 1'!$G$2:$G$2604,""))} -> Deby | K11: Ginta Monita | L11: =IF(K11<>"",IF(L11<>"",L11,NOW()),"") -> 45580.372 | W11: SELESAI (LENGKAP) | X11: =IF(W11<>"",IF(X11<>"",X11,NOW()),"") -> 45580.433 | Y11: Cetak | Z11: =COUNTA(M11:V11) -> 0
B12: L/2/141024/1 | C12: {=IF(B12="","",_xlfn.XLOOKUP(B12,'Form responses 1'!$B$2:$B$2604,'Form responses 1'!$A$2:$A$2604,""))} -> 45579.377 | D12: =if(and(B12="",C12=""),"",CONCATENATE(B12,"_",C12)) -> L/2/141024/1_45579.3769424653 | E12: {=IF(B12="","",_xlfn.XLOOKUP(B12,'Form responses 1'!$B$2:$B$2604,'Form responses 1'!$C$2:$C$2604,""))} -> RIRIN OKTARINA | F12: {=IF(B12="","",_xlfn.XLOOKUP(B12,'Form responses 1'!$B$2:$B$2604,'Form responses 1'!$D$2:$D$2604,""))} -> 089632241202 | G12: {=IF(B12="","",_xlfn.XLOOKUP(B12,'Form responses 1'!$B$2:$B$2604,'Form responses 1'!$E$2:$E$2604,""))} -> ROYA | H12: {=IF(B12="","",_xlfn.XLOOKUP(B12,'Form responses 1'!$B$2:$B$2604,'Form responses 1'!$F$2:$F$2604,""))} -> HM 17565/SUKARAME I | I12: {=IF(B12="","",_xlfn.XLOOKUP(B12,'Form responses 1'!$B$2:$B$2604,'Form responses 1'!$I$2:$I$2604,""))} -> SUKARAME I | J12: {=IF(B12="","",_xlfn.XLOOKUP(B12,'Form responses 1'!$B$2:$B$2604,'Form responses 1'!$G$2:$G$2604,""))} -> Deby | K12: Ginta Monita | L12: =IF(K12<>"",IF(L12<>"",L12,NOW()),"") -> 45580.373 | W12: SELESAI (LENGKAP) | X12: =IF(W12<>"",IF(X12<>"",X12,NOW()),"") -> 45580.426 | Y12: Cetak | Z12: =COUNTA(M12:V12) -> 0
B13: L/35/141024/1 | C13: {=IF(B13="","",_xlfn.XLOOKUP(B13,'Form responses 1'!$B$2:$B$2604,'Form responses 1'!$A$2:$A$2604,""))} -> 45579.596 | D13: =if(and(B13="",C13=""),"",CONCATENATE(B13,"_",C13)) -> L/35/141024/1_45579.5956670602 | E13: {=IF(B13="","",_xlfn.XLOOKUP(B13,'Form responses 1'!$B$2:$B$2604,'Form responses 1'!$C$2:$C$2604,""))} -> DEBY JULISDA | F13: {=IF(B13="","",_xlfn.XLOOKUP(B13,'Form responses 1'!$B$2:$B$2604,'Form responses 1'!$D$2:$D$2604,""))} -> 088276777557 | G13: {=IF(B13="","",_xlfn.XLOOKUP(B13,'Form responses 1'!$B$2:$B$2604,'Form responses 1'!$E$2:$E$2604,""))} -> ROYA LELANG | H13: {=IF(B13="","",_xlfn.XLOOKUP(B13,'Form responses 1'!$B$2:$B$2604,'Form responses 1'!$F$2:$F$2604,""))} -> M.676/SAWAH BREBES | I13: {=IF(B13="","",_xlfn.XLOOKUP(B13,'Form responses 1'!$B$2:$B$2604,'Form responses 1'!$I$2:$I$2604,""))} -> SAWAH BREBES | J13: {=IF(B13="","",_xlfn.XLOOKUP(B13,'Form responses 1'!$B$2:$B$2604,'Form responses 1'!$G$2:$G$2604,""))} -> Nuraini | K13: Ginta Monita | L13: =IF(K13<>"",IF(L13<>"",L13,NOW()),"") -> 45580.374 | W13: SELESAI (LENGKAP) | X13: =IF(W13<>"",IF(X13<>"",X13,NOW()),"") -> 45580.437 | Y13: Cetak | Z13: =COUNTA(M13:V13) -> 0
B14: K/37/141024/1 | C14: {=IF(B14="","",_xlfn.XLOOKUP(B14,'Form responses 1'!$B$2:$B$2604,'Form responses 1'!$A$2:$A$2604,""))} -> 45579.601 | D14: =if(and(B14="",C14=""),"",CONCATENATE(B14,"_",C14)) -> K/37/141024/1_45579.600917419 | E14: {=IF(B14="","",_xlfn.XLOOKUP(B14,'Form responses 1'!$B$2:$B$2604,'Form responses 1'!$C$2:$C$2604,""))} -> PT KEONG NUSANTARA ABADI/KHRESNA DJUAINI | F14: {=IF(B14="","",_xlfn.XLOOKUP(B14,'Form responses 1'!$B$2:$B$2604,'Form responses 1'!$D$2:$D$2604,""))} -> 081369381711 | G14: {=IF(B14="","",_xlfn.XLOOKUP(B14,'Form responses 1'!$B$2:$B$2604,'Form responses 1'!$E$2:$E$2604,""))} -> PERALIHAN JUAL BELI | H14: {=IF(B14="","",_xlfn.XLOOKUP(B14,'Form responses 1'!$B$2:$B$2604,'Form responses 1'!$F$2:$F$2604,""))} -> - | I14: {=IF(B14="","",_xlfn.XLOOKUP(B14,'Form responses 1'!$B$2:$B$2604,'Form responses 1'!$I$2:$I$2604,""))} -> TELUK BETUNG | J14: {=IF(B14="","",_xlfn.XLOOKUP(B14,'Form responses 1'!$B$2:$B$2604,'Form responses 1'!$G$2:$G$2604,""))} -> Baynur | K14: Ginta Monita | L14: =IF(K14<>"",IF(L14<>"",L14,NOW()),"") -> 45580.374 | M14: ktp susy marduli | N14: PKKPR | W14: SELESAI (LENGKAP) | X14: =IF(W14<>"",IF(X14<>"",X14,NOW()),"") -> 45590.486 | Y14: Cetak | Z14: =COUNTA(M14:V14) -> 2
B15: K/15/141024/4 | C15: {=IF(B15="","",_xlfn.XLOOKUP(B15,'Form responses 1'!$B$2:$B$2604,'Form responses 1'!$A$2:$A$2604,""))} -> 45579.451 | D15: =if(and(B15="",C15=""),"",CONCATENATE(B15,"_",C15)) -> K/15/141024/4_45579.4505724884 | E15: {=IF(B15="","",_xlfn.XLOOKUP(B15,'Form responses 1'!$B$2:$B$2604,'Form responses 1'!$C$2:$C$2604,""))} -> PANGGARA PAGARISI/PANARY SITOPU | F15: {=IF(B15="","",_xlfn.XLOOKUP(B15,'Form responses 1'!$B$2:$B$2604,'Form responses 1'!$D$2:$D$2604,""))} -> 081361444098 | G15: {=IF(B15="","",_xlfn.XLOOKUP(B15,'Form responses 1'!$B$2:$B$2604,'Form responses 1'!$E$2:$E$2604,""))} -> PENINGKATAN HAK | H15: {=IF(B15="","",_xlfn.XLOOKUP(B15,'Form responses 1'!$B$2:$B$2604,'Form responses 1'!$F$2:$F$2604,""))} -> - | I15: {=IF(B15="","",_xlfn.XLOOKUP(B15,'Form responses 1'!$B$2:$B$2604,'Form responses 1'!$I$2:$I$2604,""))} -> NEGERI OLOK GADING | J15: {=IF(B15="","",_xlfn.XLOOKUP(B15,'Form responses 1'!$B$2:$B$2604,'Form responses 1'!$G$2:$G$2604,""))} -> Baynur | K15: Ginta Monita | L15: =IF(K15<>"",IF(L15<>"",L15,NOW()),"") -> 45580.374 | M15: Alamat di PBB dan IMB berbeda | N15: IMB nya ruko? | W15: SELESAI (LENGKAP) | X15: =IF(W15<>"",IF(X15<>"",X15,NOW()),"") -> 45580.401 | Y15: Cetak | Z15: =COUNTA(M15:V15) -> 2 | AA15: ACC TGL 22 OKT 24
B16: K/27/141024/4 | C16: {=IF(B16="","",_xlfn.XLOOKUP(B16,'Form responses 1'!$B$2:$B$2604,'Form responses 1'!$A$2:$A$2604,""))} -> 45579.57 | D16: =if(and(B16="",C16=""),"",CONCATENATE(B16,"_",C16)) -> K/27/141024/4_45579.5701433218 | E16: {=IF(B16="","",_xlfn.XLOOKUP(B16,'Form responses 1'!$B$2:$B$2604,'Form responses 1'!$C$2:$C$2604,""))} -> MURSALIN | F16: {=IF(B16="","",_xlfn.XLOOKUP(B16,'Form responses 1'!$B$2:$B$2604,'Form responses 1'!$D$2:$D$2604,""))} -> 085383885939 | G16: {=IF(B16="","",_xlfn.XLOOKUP(B16,'Form responses 1'!$B$2:$B$2604,'Form responses 1'!$E$2:$E$2604,""))} -> PERALIHAN JUAL BELI | H16: {=IF(B16="","",_xlfn.XLOOKUP(B16,'Form responses 1'!$B$2:$B$2604,'Form responses 1'!$F$2:$F$2604,""))} -> M. 13414/ SUKABUMI | I16: {=IF(B16="","",_xlfn.XLOOKUP(B16,'Form responses 1'!$B$2:$B$2604,'Form responses 1'!$I$2:$I$2604,""))} -> SUKABUMI | J16: {=IF(B16="","",_xlfn.XLOOKUP(B16,'Form responses 1'!$B$2:$B$2604,'Form responses 1'!$G$2:$G$2604,""))} -> Hananda | K16: Ginta Monita | L16: =IF(K16<>"",IF(L16<>"",L16,NOW()),"") -> 45580.374 | M16: Renvoi pekerjaan Henny Dewi (belum direnvoi) | W16: SELESAI (LENGKAP) | X16: =IF(W16<>"",IF(X16<>"",X16,NOW()),"") -> 45595.359 | Y16: Cetak | Z16: =COUNTA(M16:V16) -> 1
B17: K/25/141024/3 | C17: {=IF(B17="","",_xlfn.XLOOKUP(B17,'Form responses 1'!$B$2:$B$2604,'Form responses 1'!$A$2:$A$2604,""))} -> 45579.56 | D17: =if(and(B17="",C17=""),"",CONCATENATE(B17,"_",C17)) -> K/25/141024/3_45579.5598141551 | E17: {=IF(B17="","",_xlfn.XLOOKUP(B17,'Form responses 1'!$B$2:$B$2604,'Form responses 1'!$C$2:$C$2604,""))} -> MURSALIN | F17: {=IF(B17="","",_xlfn.XLOOKUP(B17,'Form responses 1'!$B$2:$B$2604,'Form responses 1'!$D$2:$D$2604,""))} -> 085383885939 | G17: {=IF(B17="","",_xlfn.XLOOKUP(B17,'Form responses 1'!$B$2:$B$2604,'Form responses 1'!$E$2:$E$2604,""))} -> PERALIHAN JUAL BELI | H17: {=IF(B17="","",_xlfn.XLOOKUP(B17,'Form responses 1'!$B$2:$B$2604,'Form responses 1'!$F$2:$F$2604,""))} -> M. 133/ SUKARAME BARU- SEKARANG; B. 144/ SUKARAME BARU-DAHULU; B. 4605/SUKARAME I-DAHULU | I17: {=IF(B17="","",_xlfn.XLOOKUP(B17,'Form responses 1'!$B$2:$B$2604,'Form responses 1'!$I$2:$I$2604,""))} -> SUKARAME BARU | J17: {=IF(B17="","",_xlfn.XLOOKUP(B17,'Form responses 1'!$B$2:$B$2604,'Form responses 1'!$G$2:$G$2604,""))} -> Hananda | K17: Ginta Monita | L17: =IF(K17<>"",IF(L17<>"",L17,NOW()),"") -> 45580.375 | M17: Renvoi NIB di AJB (15-10-2024) | W17: SELESAI (LENGKAP) | X17: =IF(W17<>"",IF(X17<>"",X17,NOW()),"") -> 45593.436 | Y17: Cetak | Z17: =COUNTA(M17:V17) -> 1
B18: L/33/141024/1 | C18: {=IF(B18="","",_xlfn.XLOOKUP(B18,'Form responses 1'!$B$2:$B$2604,'Form responses 1'!$A$2:$A$2604,""))} -> 45579.592 | D18: =if(and(B18="",C18=""),"",CONCATENATE(B18,"_",C18)) -> L/33/141024/1_45579.5919665972 | E18: {=IF(B18="","",_xlfn.XLOOKUP(B18,'Form responses 1'!$B$2:$B$2604,'Form responses 1'!$C$2:$C$2604,""))} -> MOCHAMAD MA'RUF | F18: {=IF(B18="","",_xlfn.XLOOKUP(B18,'Form responses 1'!$B$2:$B$2604,'Form responses 1'!$D$2:$D$2604,""))} -> 081369994969 | G18: {=IF(B18="","",_xlfn.XLOOKUP(B18,'Form responses 1'!$B$2:$B$2604,'Form responses 1'!$E$2:$E$2604,""))} -> ROYA | H18: {=IF(B18="","",_xlfn.XLOOKUP(B18,'Form responses 1'!$B$2:$B$2604,'Form responses 1'!$F$2:$F$2604,""))} -> M.1540/GUNUNG TERANG;B.17/GU TERANG-DAHULU | I18: {=IF(B18="","",_xlfn.XLOOKUP(B18,'Form responses 1'!$B$2:$B$2604,'Form responses 1'!$I$2:$I$2604,""))} -> GUNUNG TERANG | J18: {=IF(B18="","",_xlfn.XLOOKUP(B18,'Form responses 1'!$B$2:$B$2604,'Form responses 1'!$G$2:$G$2604,""))} -> Nuraini | K18: Fikka | L18: =IF(K18<>"",IF(L18<>"",L18,NOW()),"") -> 45580.375 | M18: VALBID | N18: KENAPA SHT PERINGKAT I TIDAK DI ROYA ? | W18: SELESAI (LENGKAP) | X18: =IF(W18<>"",IF(X18<>"",X18,NOW()),"") -> 45580.411 | Y18: Cetak | Z18: =COUNTA(M18:V18) -> 2
B19: K/14/141024/3 | C19: {=IF(B19="","",_xlfn.XLOOKUP(B19,'Form responses 1'!$B$2:$B$2604,'Form responses 1'!$A$2:$A$2604,""))} -> 45579.449 | D19: =if(and(B19="",C19=""),"",CONCATENATE(B19,"_",C19)) -> K/14/141024/3_45579.4491384607 | E19: {=IF(B19="","",_xlfn.XLOOKUP(B19,'Form responses 1'!$B$2:$B$2604,'Form responses 1'!$C$2:$C$2604,""))} -> APRILIA/PANARY SITOPU | F19: {=IF(B19="","",_xlfn.XLOOKUP(B19,'Form responses 1'!$B$2:$B$2604,'Form responses 1'!$D$2:$D$2604,""))} -> 081361444098 | G19: {=IF(B19="","",_xlfn.XLOOKUP(B19,'Form responses 1'!$B$2:$B$2604,'Form responses 1'!$E$2:$E$2604,""))} -> ROYA | H19: {=IF(B19="","",_xlfn.XLOOKUP(B19,'Form responses 1'!$B$2:$B$2604,'Form responses 1'!$F$2:$F$2604,""))} -> M.988/NEGERI OLOK GADING-SEKARANG;B.1050/NEGERI OLOK GADING-DAHULU | I19: {=IF(B19="","",_xlfn.XLOOKUP(B19,'Form responses 1'!$B$2:$B$2604,'Form responses 1'!$I$2:$I$2604,""))} -> NEGERI OLOK GADING | J19: {=IF(B19="","",_xlfn.XLOOKUP(B19,'Form responses 1'!$B$2:$B$2604,'Form responses 1'!$G$2:$G$2604,""))} -> Baynur | K19: Fikka | L19: =IF(K19<>"",IF(L19<>"",L19,NOW()),"") -> 45580.376 | W19: SELESAI (LENGKAP) | X19: =IF(W19<>"",IF(X19<>"",X19,NOW()),"") -> 45580.419 | Y19: Cetak | Z19: =COUNTA(M19:V19) -> 0
B20: L/18/141024/1 | C20: {=IF(B20="","",_xlfn.XLOOKUP(B20,'Form responses 1'!$B$2:$B$2604,'Form responses 1'!$A$2:$A$2604,""))} -> 45579.484 | D20: =if(and(B20="",C20=""),"",CONCATENATE(B20,"_",C20)) -> L/18/141024/1_45579.4840388426 | E20: {=IF(B20="","",_xlfn.XLOOKUP(B20,'Form responses 1'!$B$2:$B$2604,'Form responses 1'!$C$2:$C$2604,""))} -> SUNILA HAKI | F20: {=IF(B20="","",_xlfn.XLOOKUP(B20,'Form responses 1'!$B$2:$B$2604,'Form responses 1'!$D$2:$D$2604,""))} -> 082279144608 | G20: {=IF(B20="","",_xlfn.XLOOKUP(B20,'Form responses 1'!$B$2:$B$2604,'Form responses 1'!$E$2:$E$2604,""))} -> BLOKIR | H20: {=IF(B20="","",_xlfn.XLOOKUP(B20,'Form responses 1'!$B$2:$B$2604,'Form responses 1'!$F$2:$F$2604,""))} -> M.331/NUSANTARA PERMAI;B.389/CAMPANG RAYA-DAHULU | I20: {=IF(B20="","",_xlfn.XLOOKUP(B20,'Form responses 1'!$B$2:$B$2604,'Form responses 1'!$I$2:$I$2604,""))} -> NUSANTARA PERMAI | J20: {=IF(B20="","",_xlfn.XLOOKUP(B20,'Form responses 1'!$B$2:$B$2604,'Form responses 1'!$G$2:$G$2604,""))} -> Nuraini | K20: Fikka | L20: =IF(K20<>"",IF(L20<>"",L20,NOW()),"") -> 45580.376 | W20: SELESAI (LENGKAP) | X20: =IF(W20<>"",IF(X20<>"",X20,NOW()),"") -> 45580.57 | Y20: Cetak | Z20: =COUNTA(M20:V20) -> 0
B21: K/7/141024/1 | C21: {=IF(B21="","",_xlfn.XLOOKUP(B21,'Form responses 1'!$B$2:$B$2604,'Form responses 1'!$A$2:$A$2604,""))} -> 45579.41 | D21: =if(and(B21="",C21=""),"",CONCATENATE(B21,"_",C21)) -> K/7/141024/1_45579.4099811806 | E21: {=IF(B21="","",_xlfn.XLOOKUP(B21,'Form responses 1'!$B$2:$B$2604,'Form responses 1'!$C$2:$C$2604,""))} -> IKE FEBRINA, S.IP | F21: {=IF(B21="","",_xlfn.XLOOKUP(B21,'Form responses 1'!$B$2:$B$2604,'Form responses 1'!$D$2:$D$2604,""))} -> 081927983379 | G21: {=IF(B21="","",_xlfn.XLOOKUP(B21,'Form responses 1'!$B$2:$B$2604,'Form responses 1'!$E$2:$E$2604,""))} -> ANGKAT SITA | H21: {=IF(B21="","",_xlfn.XLOOKUP(B21,'Form responses 1'!$B$2:$B$2604,'Form responses 1'!$F$2:$F$2604,""))} -> M. 631/Pahoman- sekarang; M. 631/Pahoman-Dahulu | I21: {=IF(B21="","",_xlfn.XLOOKUP(B21,'Form responses 1'!$B$2:$B$2604,'Form responses 1'!$I$2:$I$2604,""))} -> PAHOMAN | J21: {=IF(B21="","",_xlfn.XLOOKUP(B21,'Form responses 1'!$B$2:$B$2604,'Form responses 1'!$G$2:$G$2604,""))} -> Hananda | K21: Fikka | L21: =IF(K21<>"",IF(L21<>"",L21,NOW()),"") -> 45580.376 | W21: SELESAI (LENGKAP) | X21: =IF(W21<>"",IF(X21<>"",X21,NOW()),"") -> 45580.571 | Y21: Cetak | Z21: =COUNTA(M21:V21) -> 0
B22: K/26/141024/1 | C22: {=IF(B22="","",_xlfn.XLOOKUP(B22,'Form responses 1'!$B$2:$B$2604,'Form responses 1'!$A$2:$A$2604,""))} -> 45579.566 | D22: =if(and(B22="",C22=""),"",CONCATENATE(B22,"_",C22)) -> K/26/141024/1_45579.5656653125 | E22: {=IF(B22="","",_xlfn.XLOOKUP(B22,'Form responses 1'!$B$2:$B$2604,'Form responses 1'!$C$2:$C$2604,""))} -> KHARISMA MANISHA CECILIYA/ILANUR | F22: {=IF(B22="","",_xlfn.XLOOKUP(B22,'Form responses 1'!$B$2:$B$2604,'Form responses 1'!$D$2:$D$2604,""))} -> 081295653816 | G22: {=IF(B22="","",_xlfn.XLOOKUP(B22,'Form responses 1'!$B$2:$B$2604,'Form responses 1'!$E$2:$E$2604,""))} -> PERALIHAN JUAL BELI | H22: {=IF(B22="","",_xlfn.XLOOKUP(B22,'Form responses 1'!$B$2:$B$2604,'Form responses 1'!$F$2:$F$2604,""))} -> M.2094/CAMPANG JAYA | I22: {=IF(B22="","",_xlfn.XLOOKUP(B22,'Form responses 1'!$B$2:$B$2604,'Form responses 1'!$I$2:$I$2604,""))} -> CAMPANG JAYA | J22: {=IF(B22="","",_xlfn.XLOOKUP(B22,'Form responses 1'!$B$2:$B$2604,'Form responses 1'!$G$2:$G$2604,""))} -> Baynur | K22: Fikka | L22: =IF(K22<>"",IF(L22<>"",L22,NOW()),"") -> 45580.376 | M22: PERBAIKI KELURAHAN PADA KUITANSI | W22: SELESAI (LENGKAP) | X22: =IF(W22<>"",IF(X22<>"",X22,NOW()),"") -> 45580.449 | Y22: Cetak | Z22: =COUNTA(M22:V22) -> 1
B23: K/19/141024/1 | C23: {=IF(B23="","",_xlfn.XLOOKUP(B23,'Form responses 1'!$B$2:$B$2604,'Form responses 1'!$A$2:$A$2604,""))} -> 45579.484 | D23: =if(and(B23="",C23=""),"",CONCATENATE(B23,"_",C23)) -> K/19/141024/1_45579.4839514005 | E23: {=IF(B23="","",_xlfn.XLOOKUP(B23,'Form responses 1'!$B$2:$B$2604,'Form responses 1'!$C$2:$C$2604,""))} -> ROSIDA LINGSA KENCANA/RAHMADIYANTI | F23: {=IF(B23="","",_xlfn.XLOOKUP(B23,'Form responses 1'!$B$2:$B$2604,'Form responses 1'!$D$2:$D$2604,""))} -> 082182090051 | G23: {=IF(B23="","",_xlfn.XLOOKUP(B23,'Form responses 1'!$B$2:$B$2604,'Form responses 1'!$E$2:$E$2604,""))} -> PERALIHAN JUAL BELI | H23: {=IF(B23="","",_xlfn.XLOOKUP(B23,'Form responses 1'!$B$2:$B$2604,'Form responses 1'!$F$2:$F$2604,""))} -> M.16678/SUKABUMI | I23: {=IF(B23="","",_xlfn.XLOOKUP(B23,'Form responses 1'!$B$2:$B$2604,'Form responses 1'!$I$2:$I$2604,""))} -> SUKABUMI | J23: {=IF(B23="","",_xlfn.XLOOKUP(B23,'Form responses 1'!$B$2:$B$2604,'Form responses 1'!$G$2:$G$2604,""))} -> Baynur | K23: Fikka | L23: =IF(K23<>"",IF(L23<>"",L23,NOW()),"") -> 45580.376 | W23: SELESAI (LENGKAP) | X23: =IF(W23<>"",IF(X23<>"",X23,NOW()),"") -> 45580.435 | Y23: Cetak | Z23: =COUNTA(M23:V23) -> 0
B24: K/16/141024/1 | C24: {=IF(B24="","",_xlfn.XLOOKUP(B24,'Form responses 1'!$B$2:$B$2604,'Form responses 1'!$A$2:$A$2604,""))} -> 45579.464 | D24: =if(and(B24="",C24=""),"",CONCATENATE(B24,"_",C24)) -> K/16/141024/1_45579.4638286343 | E24: {=IF(B24="","",_xlfn.XLOOKUP(B24,'Form responses 1'!$B$2:$B$2604,'Form responses 1'!$C$2:$C$2604,""))} -> TITIK WIJAYANTI/SENDI DINI HARIYATI | F24: {=IF(B24="","",_xlfn.XLOOKUP(B24,'Form responses 1'!$B$2:$B$2604,'Form responses 1'!$D$2:$D$2604,""))} -> 089618401409 | G24: {=IF(B24="","",_xlfn.XLOOKUP(B24,'Form responses 1'!$B$2:$B$2604,'Form responses 1'!$E$2:$E$2604,""))} -> SKPT | H24: {=IF(B24="","",_xlfn.XLOOKUP(B24,'Form responses 1'!$B$2:$B$2604,'Form responses 1'!$F$2:$F$2604,""))} -> M.9137/GEDONG MENENG | I24: {=IF(B24="","",_xlfn.XLOOKUP(B24,'Form responses 1'!$B$2:$B$2604,'Form responses 1'!$I$2:$I$2604,""))} -> GEDONG MENENG | J24: {=IF(B24="","",_xlfn.XLOOKUP(B24,'Form responses 1'!$B$2:$B$2604,'Form responses 1'!$G$2:$G$2604,""))} -> Baynur | K24: Kholfa | L24: =IF(K24<>"",IF(L24<>"",L24,NOW()),"") -> 45580.377 | M24: Beda nama pemilik SHAT pada Surat Permohonan KPKNL dengan Fc SHAT terlampir | N24: Kurang input data pemilik SHAT di KKP | W24: SELESAI (LENGKAP) | X24: =IF(W24<>"",IF(X24<>"",X24,NOW()),"") -> 45580.406 | Y24: Cetak | Z24: =COUNTA(M24:V24) -> 2
B25: L/5/141024/1 | C25: {=IF(B25="","",_xlfn.XLOOKUP(B25,'Form responses 1'!$B$2:$B$2604,'Form responses 1'!$A$2:$A$2604,""))} -> 45579.403 | D25: =if(and(B25="",C25=""),"",CONCATENATE(B25,"_",C25)) -> L/5/141024/1_45579.403285787 | E25: {=IF(B25="","",_xlfn.XLOOKUP(B25,'Form responses 1'!$B$2:$B$2604,'Form responses 1'!$C$2:$C$2604,""))} -> SITI NAZROH | F25: {=IF(B25="","",_xlfn.XLOOKUP(B25,'Form responses 1'!$B$2:$B$2604,'Form responses 1'!$D$2:$D$2604,""))} -> 08117208600 | G25: {=IF(B25="","",_xlfn.XLOOKUP(B25,'Form responses 1'!$B$2:$B$2604,'Form responses 1'!$E$2:$E$2604,""))} -> ROYA | H25: {=IF(B25="","",_xlfn.XLOOKUP(B25,'Form responses 1'!$B$2:$B$2604,'Form responses 1'!$F$2:$F$2604,""))} -> M.9974/TANJUNG BARU | I25: {=IF(B25="","",_xlfn.XLOOKUP(B25,'Form responses 1'!$B$2:$B$2604,'Form responses 1'!$I$2:$I$2604,""))} -> TANJUNG BARU | J25: {=IF(B25="","",_xlfn.XLOOKUP(B25,'Form responses 1'!$B$2:$B$2604,'Form responses 1'!$G$2:$G$2604,""))} -> Nuraini | K25: Kholfa | L25: =IF(K25<>"",IF(L25<>"",L25,NOW()),"") -> 45580.377 | M25: Beda tgl lahir pemilik pada SHAT dengan Fc KTP terlampir | W25: SELESAI (LENGKAP) | X25: =IF(W25<>"",IF(X25<>"",X25,NOW()),"") -> 45580.43 | Y25: Cetak | Z25: =COUNTA(M25:V25) -> 1 | AA25: acc 22/10/2024
B26: K/12/141024/1 | C26: {=IF(B26="","",_xlfn.XLOOKUP(B26,'Form responses 1'!$B$2:$B$2604,'Form responses 1'!$A$2:$A$2604,""))} -> 45579.446 | D26: =if(and(B26="",C26=""),"",CONCATENATE(B26,"_",C26)) -> K/12/141024/1_45579.4464756366 | E26: {=IF(B26="","",_xlfn.XLOOKUP(B26,'Form responses 1'!$B$2:$B$2604,'Form responses 1'!$C$2:$C$2604,""))} -> META ARIDHOTU PRANATA /PANARY SITOPU | F26: {=IF(B26="","",_xlfn.XLOOKUP(B26,'Form responses 1'!$B$2:$B$2604,'Form responses 1'!$D$2:$D$2604,""))} -> 081361444098 | G26: {=IF(B26="","",_xlfn.XLOOKUP(B26,'Form responses 1'!$B$2:$B$2604,'Form responses 1'!$E$2:$E$2604,""))} -> ROYA | H26: {=IF(B26="","",_xlfn.XLOOKUP(B26,'Form responses 1'!$B$2:$B$2604,'Form responses 1'!$F$2:$F$2604,""))} -> M.3326/LANGKAPURA | I26: {=IF(B26="","",_xlfn.XLOOKUP(B26,'Form responses 1'!$B$2:$B$2604,'Form responses 1'!$I$2:$I$2604,""))} -> LANGKAPURA | J26: {=IF(B26="","",_xlfn.XLOOKUP(B26,'Form responses 1'!$B$2:$B$2604,'Form responses 1'!$G$2:$G$2604,""))} -> Baynur | K26: Kholfa | L26: =IF(K26<>"",IF(L26<>"",L26,NOW()),"") -> 45580.377 | W26: SELESAI (LENGKAP) | X26: =IF(W26<>"",IF(X26<>"",X26,NOW()),"") -> 45580.43 | Y26: Cetak | Z26: =COUNTA(M26:V26) -> 0
B27: K/38/141024/1 | C27: {=IF(B27="","",_xlfn.XLOOKUP(B27,'Form responses 1'!$B$2:$B$2604,'Form responses 1'!$A$2:$A$2604,""))} -> 45579.601 | D27: =if(and(B27="",C27=""),"",CONCATENATE(B27,"_",C27)) -> K/38/141024/1_45579.6011142245 | E27: {=IF(B27="","",_xlfn.XLOOKUP(B27,'Form responses 1'!$B$2:$B$2604,'Form responses 1'!$C$2:$C$2604,""))} -> ISMARINA | F27: {=IF(B27="","",_xlfn.XLOOKUP(B27,'Form responses 1'!$B$2:$B$2604,'Form responses 1'!$D$2:$D$2604,""))} -> 081377641549 | G27: {=IF(B27="","",_xlfn.XLOOKUP(B27,'Form responses 1'!$B$2:$B$2604,'Form responses 1'!$E$2:$E$2604,""))} -> PERALIHAN HAK JUAL BELI | H27: {=IF(B27="","",_xlfn.XLOOKUP(B27,'Form responses 1'!$B$2:$B$2604,'Form responses 1'!$F$2:$F$2604,""))} -> M. 3157/ LABUHAN DALAM | I27: {=IF(B27="","",_xlfn.XLOOKUP(B27,'Form responses 1'!$B$2:$B$2604,'Form responses 1'!$I$2:$I$2604,""))} -> LABUHAN DALAM | J27: {=IF(B27="","",_xlfn.XLOOKUP(B27,'Form responses 1'!$B$2:$B$2604,'Form responses 1'!$G$2:$G$2604,""))} -> Hananda | K27: Kholfa | L27: =IF(K27<>"",IF(L27<>"",L27,NOW()),"") -> 45580.377 | M27: Surat Pernyataan Kuasa Jual masih berlaku dari pemberi kuasa | W27: SELESAI (LENGKAP) | X27: =IF(W27<>"",IF(X27<>"",X27,NOW()),"") -> 45580.435 | Y27: Cetak | Z27: =COUNTA(M27:V27) -> 1
B28: K/28/141024/1 | C28: {=IF(B28="","",_xlfn.XLOOKUP(B28,'Form responses 1'!$B$2:$B$2604,'Form responses 1'!$A$2:$A$2604,""))} -> 45579.573 | D28: =if(and(B28="",C28=""),"",CONCATENATE(B28,"_",C28)) -> K/28/141024/1_45579.5727725694 | E28: {=IF(B28="","",_xlfn.XLOOKUP(B28,'Form responses 1'!$B$2:$B$2604,'Form responses 1'!$C$2:$C$2604,""))} -> ADE HERDIANYAH/WHINDA YULIANTI | F28: {=IF(B28="","",_xlfn.XLOOKUP(B28,'Form responses 1'!$B$2:$B$2604,'Form responses 1'!$D$2:$D$2604,""))} -> 081255572168 | G28: {=IF(B28="","",_xlfn.XLOOKUP(B28,'Form responses 1'!$B$2:$B$2604,'Form responses 1'!$E$2:$E$2604,""))} -> PERALIHAN JUAL BELI | H28: {=IF(B28="","",_xlfn.XLOOKUP(B28,'Form responses 1'!$B$2:$B$2604,'Form responses 1'!$F$2:$F$2604,""))} -> B.895/BERINGIN JAYA | I28: {=IF(B28="","",_xlfn.XLOOKUP(B28,'Form responses 1'!$B$2:$B$2604,'Form responses 1'!$I$2:$I$2604,""))} -> BERINGIN JAYA | J28: {=IF(B28="","",_xlfn.XLOOKUP(B28,'Form responses 1'!$B$2:$B$2604,'Form responses 1'!$G$2:$G$2604,""))} -> Baynur | K28: Kholfa | L28: =IF(K28<>"",IF(L28<>"",L28,NOW()),"") -> 45580.377 | W28: SELESAI (LENGKAP) | X28: =IF(W28<>"",IF(X28<>"",X28,NOW()),"") -> 45580.448 | Y28: Cetak | Z28: =COUNTA(M28:V28) -> 0
B29: K/3/141024/1 | C29: {=IF(B29="","",_xlfn.XLOOKUP(B29,'Form responses 1'!$B$2:$B$2604,'Form responses 1'!$A$2:$A$2604,""))} -> 45579.399 | D29: =if(and(B29="",C29=""),"",CONCATENATE(B29,"_",C29)) -> K/3/141024/1_45579.3993955903 | E29: {=IF(B29="","",_xlfn.XLOOKUP(B29,'Form responses 1'!$B$2:$B$2604,'Form responses 1'!$C$2:$C$2604,""))} -> GURUH SAMODRA AJI, ST.MT/WAHYUDIN | F29: {=IF(B29="","",_xlfn.XLOOKUP(B29,'Form responses 1'!$B$2:$B$2604,'Form responses 1'!$D$2:$D$2604,""))} -> 082371259997 | G29: {=IF(B29="","",_xlfn.XLOOKUP(B29,'Form responses 1'!$B$2:$B$2604,'Form responses 1'!$E$2:$E$2604,""))} -> PTPGT | H29: {=IF(B29="","",_xlfn.XLOOKUP(B29,'Form responses 1'!$B$2:$B$2604,'Form responses 1'!$F$2:$F$2604,""))} -> - | I29: {=IF(B29="","",_xlfn.XLOOKUP(B29,'Form responses 1'!$B$2:$B$2604,'Form responses 1'!$I$2:$I$2604,""))} -> WAY LAGA | J29: {=IF(B29="","",_xlfn.XLOOKUP(B29,'Form responses 1'!$B$2:$B$2604,'Form responses 1'!$G$2:$G$2604,""))} -> Baynur | K29: Kholfa | L29: =IF(K29<>"",IF(L29<>"",L29,NOW()),"") -> 45580.377 | W29: SELESAI (LENGKAP) | X29: =IF(W29<>"",IF(X29<>"",X29,NOW()),"") -> 45580.456 | Y29: Cetak | Z29: =COUNTA(M29:V29) -> 0
B30: K/29/141024/1 | C30: {=IF(B30="","",_xlfn.XLOOKUP(B30,'Form responses 1'!$B$2:$B$2604,'Form responses 1'!$A$2:$A$2604,""))} -> 45579.578 | D30: =if(and(B30="",C30=""),"",CONCATENATE(B30,"_",C30)) -> K/29/141024/1_45579.5779375116 | E30: {=IF(B30="","",_xlfn.XLOOKUP(B30,'Form responses 1'!$B$2:$B$2604,'Form responses 1'!$C$2:$C$2604,""))} -> GUNAWAN | F30: {=IF(B30="","",_xlfn.XLOOKUP(B30,'Form responses 1'!$B$2:$B$2604,'Form responses 1'!$D$2:$D$2604,""))} -> 085273192152 | G30: {=IF(B30="","",_xlfn.XLOOKUP(B30,'Form responses 1'!$B$2:$B$2604,'Form responses 1'!$E$2:$E$2604,""))} -> PTPGT PEMECAHAN | H30: {=IF(B30="","",_xlfn.XLOOKUP(B30,'Form responses 1'!$B$2:$B$2604,'Form responses 1'!$F$2:$F$2604,""))} -> M. 2445/ SUKADANA HAM | I30: {=IF(B30="","",_xlfn.XLOOKUP(B30,'Form responses 1'!$B$2:$B$2604,'Form responses 1'!$I$2:$I$2604,""))} -> SUKADANA HAM | J30: {=IF(B30="","",_xlfn.XLOOKUP(B30,'Form responses 1'!$B$2:$B$2604,'Form responses 1'!$G$2:$G$2604,""))} -> Hananda | K30: Maharani | L30: =IF(K30<>"",IF(L30<>"",L30,NOW()),"") -> 45580.381 | M30: Beda nama antara KTP (Caecilia Sri Uji Hardiyanti) dan Sertipikat (Sri Uji Hardiyanti) terlalu jauh. Berkas sudah pernah masuk di loket 1 tgl 16/07/2024, lengkapi perbaikan sesuai catatan | W30: SELESAI (LENGKAP) | X30: =IF(W30<>"",IF(X30<>"",X30,NOW()),"") -> 45594.362 | Y30: Cetak | Z30: =COUNTA(M30:V30) -> 1
B31: K/31/141024/1 | C31: {=IF(B31="","",_xlfn.XLOOKUP(B31,'Form responses 1'!$B$2:$B$2604,'Form responses 1'!$A$2:$A$2604,""))} -> 45579.585 | D31: =if(and(B31="",C31=""),"",CONCATENATE(B31,"_",C31)) -> K/31/141024/1_45579.584890625 | E31: {=IF(B31="","",_xlfn.XLOOKUP(B31,'Form responses 1'!$B$2:$B$2604,'Form responses 1'!$C$2:$C$2604,""))} -> APRILLIYANI | F31: {=IF(B31="","",_xlfn.XLOOKUP(B31,'Form responses 1'!$B$2:$B$2604,'Form responses 1'!$D$2:$D$2604,""))} -> 081367846284 | G31: {=IF(B31="","",_xlfn.XLOOKUP(B31,'Form responses 1'!$B$2:$B$2604,'Form responses 1'!$E$2:$E$2604,""))} -> PERUBAHAN HAK | H31: {=IF(B31="","",_xlfn.XLOOKUP(B31,'Form responses 1'!$B$2:$B$2604,'Form responses 1'!$F$2:$F$2604,""))} -> NIBEL 1691/ SUKABUMI INDAH | I31: {=IF(B31="","",_xlfn.XLOOKUP(B31,'Form responses 1'!$B$2:$B$2604,'Form responses 1'!$I$2:$I$2604,""))} -> SUKABUMI INDAH | J31: {=IF(B31="","",_xlfn.XLOOKUP(B31,'Form responses 1'!$B$2:$B$2604,'Form responses 1'!$G$2:$G$2604,""))} -> Hananda | K31: Maharani | L31: =IF(K31<>"",IF(L31<>"",L31,NOW()),"") -> 45580.382 | M31: Data tidak di temukan di KKP dan TT | W31: SELESAI (LENGKAP) | X31: =IF(W31<>"",IF(X31<>"",X31,NOW()),"") -> 45580.46 | Y31: Cetak | Z31: =COUNTA(M31:V31) -> 1
B32: L/11/141024/1 | C32: {=IF(B32="","",_xlfn.XLOOKUP(B32,'Form responses 1'!$B$2:$B$2604,'Form responses 1'!$A$2:$A$2604,""))} -> 45579.435 | D32: =if(and(B32="",C32=""),"",CONCATENATE(B32,"_",C32)) -> L/11/141024/1_45579.4347999884 | E32: {=IF(B32="","",_xlfn.XLOOKUP(B32,'Form responses 1'!$B$2:$B$2604,'Form responses 1'!$C$2:$C$2604,""))} -> HENNY INDRIYANI | F32: {=IF(B32="","",_xlfn.XLOOKUP(B32,'Form responses 1'!$B$2:$B$2604,'Form responses 1'!$D$2:$D$2604,""))} -> 081369690601 | G32: {=IF(B32="","",_xlfn.XLOOKUP(B32,'Form responses 1'!$B$2:$B$2604,'Form responses 1'!$E$2:$E$2604,""))} -> ROYA | H32: {=IF(B32="","",_xlfn.XLOOKUP(B32,'Form responses 1'!$B$2:$B$2604,'Form responses 1'!$F$2:$F$2604,""))} -> HM 1505 LABUHAN DALAM & HM 1506 LABUHAN DALAM | I32: {=IF(B32="","",_xlfn.XLOOKUP(B32,'Form responses 1'!$B$2:$B$2604,'Form responses 1'!$I$2:$I$2604,""))} -> LABUHAN DALAM | J32: {=IF(B32="","",_xlfn.XLOOKUP(B32,'Form responses 1'!$B$2:$B$2604,'Form responses 1'!$G$2:$G$2604,""))} -> Deby | K32: Maharani | L32: =IF(K32<>"",IF(L32<>"",L32,NOW()),"") -> 45580.383 | W32: SELESAI (LENGKAP) | X32: =IF(W32<>"",IF(X32<>"",X32,NOW()),"") -> 45580.489 | Y32: Cetak | Z32: =COUNTA(M32:V32) -> 0
B33: L/24/141024/1 | C33: {=IF(B33="","",_xlfn.XLOOKUP(B33,'Form responses 1'!$B$2:$B$2604,'Form responses 1'!$A$2:$A$2604,""))} -> 45579.5 | D33: =if(and(B33="",C33=""),"",CONCATENATE(B33,"_",C33)) -> L/24/141024/1_45579.5003502199 | E33: {=IF(B33="","",_xlfn.XLOOKUP(B33,'Form responses 1'!$B$2:$B$2604,'Form responses 1'!$C$2:$C$2604,""))} -> DEWI YULIANA | F33: {=IF(B33="","",_xlfn.XLOOKUP(B33,'Form responses 1'!$B$2:$B$2604,'Form responses 1'!$D$2:$D$2604,""))} -> 082269444244 | G33: {=IF(B33="","",_xlfn.XLOOKUP(B33,'Form responses 1'!$B$2:$B$2604,'Form responses 1'!$E$2:$E$2604,""))} -> ROYA | H33: {=IF(B33="","",_xlfn.XLOOKUP(B33,'Form responses 1'!$B$2:$B$2604,'Form responses 1'!$F$2:$F$2604,""))} -> M.2064/GUNUNG TERANG | I33: {=IF(B33="","",_xlfn.XLOOKUP(B33,'Form responses 1'!$B$2:$B$2604,'Form responses 1'!$I$2:$I$2604,""))} -> GUNUNG TERANG | J33: {=IF(B33="","",_xlfn.XLOOKUP(B33,'Form responses 1'!$B$2:$B$2604,'Form responses 1'!$G$2:$G$2604,""))} -> Nuraini | K33: Maharani | L33: =IF(K33<>"",IF(L33<>"",L33,NOW()),"") -> 45580.383 | W33: SELESAI (LENGKAP) | X33: =IF(W33<>"",IF(X33<>"",X33,NOW()),"") -> 45580.46 | Y33: Cetak | Z33: =COUNTA(M33:V33) -> 0
B34: K/40/141024/5 | C34: {=IF(B34="","",_xlfn.XLOOKUP(B34,'Form responses 1'!$B$2:$B$2604,'Form responses 1'!$A$2:$A$2604,""))} -> 45579.608 | D34: =if(and(B34="",C34=""),"",CONCATENATE(B34,"_",C34)) -> K/40/141024/5_45579.6084455787 | E34: {=IF(B34="","",_xlfn.XLOOKUP(B34,'Form responses 1'!$B$2:$B$2604,'Form responses 1'!$C$2:$C$2604,""))} -> MURSALIN | F34: {=IF(B34="","",_xlfn.XLOOKUP(B34,'Form responses 1'!$B$2:$B$2604,'Form responses 1'!$D$2:$D$2604,""))} -> 085383885939 | G34: {=IF(B34="","",_xlfn.XLOOKUP(B34,'Form responses 1'!$B$2:$B$2604,'Form responses 1'!$E$2:$E$2604,""))} -> PERALIHAN JUAL BELI | H34: {=IF(B34="","",_xlfn.XLOOKUP(B34,'Form responses 1'!$B$2:$B$2604,'Form responses 1'!$F$2:$F$2604,""))} -> NIBEL 2507/ SUMUR BATU | I34: {=IF(B34="","",_xlfn.XLOOKUP(B34,'Form responses 1'!$B$2:$B$2604,'Form responses 1'!$I$2:$I$2604,""))} -> SUMUR BATU | J34: {=IF(B34="","",_xlfn.XLOOKUP(B34,'Form responses 1'!$B$2:$B$2604,'Form responses 1'!$G$2:$G$2604,""))} -> Hananda | K34: Maharani | L34: =IF(K34<>"",IF(L34<>"",L34,NOW()),"") -> 45580.384 | M34: Pada Surat Permohonan, Surat Kuasa, Surat Pernyataan Absentee, dan Surat Pernyataan BPHTB perbaiki alamat I Made Sukantra | N34: Beda Nama Aya Sophia dan Aya Sofia serta Beda Nama Eddy Mahdi dan Eddi Mahdi | O34: Kenapa di AJB anak Aya Sophia yang bernama Derra Rizka tidak memberi persetujuan ? | P34: AJB hlm 2 perbaiki nomor Akta Kematian, AJB hlm. 3 perbaiki tgl lahir I Made Sukantra dan Nomor NIBEL | Q34: Di AJB saksi bernama Cori Anggraini tetapi yang ttd saksinya bernama Selvi Meilinda ? | R34: Perbaikan ke dua : Poin 2 belum dipenuhi dan AJB setiap hlm kurang paraf | W34: SELESAI (LENGKAP) | X34: =IF(W34<>"",IF(X34<>"",X34,NOW()),"") -> 45607.417 | Y34: Cetak | Z34: =COUNTA(M34:V34) -> 6
B35: K/4/141024/2 | C35: {=IF(B35="","",_xlfn.XLOOKUP(B35,'Form responses 1'!$B$2:$B$2604,'Form responses 1'!$A$2:$A$2604,""))} -> 45579.401 | D35: =if(and(B35="",C35=""),"",CONCATENATE(B35,"_",C35)) -> K/4/141024/2_45579.400693507 | E35: {=IF(B35="","",_xlfn.XLOOKUP(B35,'Form responses 1'!$B$2:$B$2604,'Form responses 1'!$C$2:$C$2604,""))} -> GURUH SAMODRA AJI, ST.MT/WAHYUDIN | F35: {=IF(B35="","",_xlfn.XLOOKUP(B35,'Form responses 1'!$B$2:$B$2604,'Form responses 1'!$D$2:$D$2604,""))} -> 082371259997 | G35: {=IF(B35="","",_xlfn.XLOOKUP(B35,'Form responses 1'!$B$2:$B$2604,'Form responses 1'!$E$2:$E$2604,""))} -> PTPGT | H35: {=IF(B35="","",_xlfn.XLOOKUP(B35,'Form responses 1'!$B$2:$B$2604,'Form responses 1'!$F$2:$F$2604,""))} -> - | I35: {=IF(B35="","",_xlfn.XLOOKUP(B35,'Form responses 1'!$B$2:$B$2604,'Form responses 1'!$I$2:$I$2604,""))} -> WAY LAGA | J35: {=IF(B35="","",_xlfn.XLOOKUP(B35,'Form responses 1'!$B$2:$B$2604,'Form responses 1'!$G$2:$G$2604,""))} -> Baynur | K35: Maharani | L35: =IF(K35<>"",IF(L35<>"",L35,NOW()),"") -> 45580.384 | W35: SELESAI (LENGKAP) | X35: =IF(W35<>"",IF(X35<>"",X35,NOW()),"") -> 45580.586 | Y35: Cetak | Z35: =COUNTA(M35:V35) -> 0
B36: K/13/141024/2 | C36: {=IF(B36="","",_xlfn.XLOOKUP(B36,'Form responses 1'!$B$2:$B$2604,'Form responses 1'!$A$2:$A$2604,""))} -> 45579.448 | D36: =if(and(B36="",C36=""),"",CONCATENATE(B36,"_",C36)) -> K/13/141024/2_45579.4480105324 | E36: {=IF(B36="","",_xlfn.XLOOKUP(B36,'Form responses 1'!$B$2:$B$2604,'Form responses 1'!$C$2:$C$2604,""))} -> APRILIA/PANARY SITOPU | F36: {=IF(B36="","",_xlfn.XLOOKUP(B36,'Form responses 1'!$B$2:$B$2604,'Form responses 1'!$D$2:$D$2604,""))} -> 081361444098 | G36: {=IF(B36="","",_xlfn.XLOOKUP(B36,'Form responses 1'!$B$2:$B$2604,'Form responses 1'!$E$2:$E$2604,""))} -> ROYA | H36: {=IF(B36="","",_xlfn.XLOOKUP(B36,'Form responses 1'!$B$2:$B$2604,'Form responses 1'!$F$2:$F$2604,""))} -> M.1088/NEGERI OLOK GADING-SEKARANG;B.1201/NEGERI OLOK GADING-DAHULU | I36: {=IF(B36="","",_xlfn.XLOOKUP(B36,'Form responses 1'!$B$2:$B$2604,'Form responses 1'!$I$2:$I$2604,""))} -> NEGERI OLOK GADING | J36: {=IF(B36="","",_xlfn.XLOOKUP(B36,'Form responses 1'!$B$2:$B$2604,'Form responses 1'!$G$2:$G$2604,""))} -> Baynur | K36: Maharani | L36: =IF(K36<>"",IF(L36<>"",L36,NOW()),"") -> 45580.466 | W36: SELESAI (LENGKAP) | X36: =IF(W36<>"",IF(X36<>"",X36,NOW()),"") -> 45580.469 | Y36: Cetak | Z36: =COUNTA(M36:V36) -> 0
B37: L/35/151024/1 | C37: {=IF(B37="","",_xlfn.XLOOKUP(B37,'Form responses 1'!$B$2:$B$2604,'Form responses 1'!$A$2:$A$2604,""))} -> 45580.585 | D37: =if(and(B37="",C37=""),"",CONCATENATE(B37,"_",C37)) -> L/35/151024/1_45580.5852084491 | E37: {=IF(B37="","",_xlfn.XLOOKUP(B37,'Form responses 1'!$B$2:$B$2604,'Form responses 1'!$C$2:$C$2604,""))} -> FIRMANSYAH/CS | F37: {=IF(B37="","",_xlfn.XLOOKUP(B37,'Form responses 1'!$B$2:$B$2604,'Form responses 1'!$D$2:$D$2604,""))} -> 082278291330 | G37: {=IF(B37="","",_xlfn.XLOOKUP(B37,'Form responses 1'!$B$2:$B$2604,'Form responses 1'!$E$2:$E$2604,""))} -> BN PUTUSAN PENGADILAN (AHLI WARIS) | H37: {=IF(B37="","",_xlfn.XLOOKUP(B37,'Form responses 1'!$B$2:$B$2604,'Form responses 1'!$F$2:$F$2604,""))} -> HM 479/HARAPAN JAYA (DAHULU)-HM 49/KORPRI JAYA (SEKARANG) | I37: {=IF(B37="","",_xlfn.XLOOKUP(B37,'Form responses 1'!$B$2:$B$2604,'Form responses 1'!$I$2:$I$2604,""))} -> KORPRI JAYA | J37: {=IF(B37="","",_xlfn.XLOOKUP(B37,'Form responses 1'!$B$2:$B$2604,'Form responses 1'!$G$2:$G$2604,""))} -> Deby | K37: Kholfa | L37: =IF(K37<>"",IF(L37<>"",L37,NOW()),"") -> 45580.666 | M37: NIB 50 BLM VALBID | N37: S.Pernyataan BPHTB blm ditandatangani seluruh ahli waris | O37: Ada catatan Perkara di KKP(terlampir surat keterangan dari PN Tanjungkarang terkait Perkara No.67/Pdt.G/2023/PN.Tjk | P37: Lampirkan Bukti Bayar PBB 2024 | W37: PERBAIKAN | X37: =IF(W37<>"",IF(X37<>"",X37,NOW()),"") -> 45581.67 | Y37: Cetak | Z37: =COUNTA(M37:V37) -> 4
B38: K/47/151024/1 | C38: {=IF(B38="","",_xlfn.XLOOKUP(B38,'Form responses 1'!$B$2:$B$2604,'Form responses 1'!$A$2:$A$2604,""))} -> 45580.6 | D38: =if(and(B38="",C38=""),"",CONCATENATE(B38,"_",C38)) -> K/47/151024/1_45580.6001020602 | E38: {=IF(B38="","",_xlfn.XLOOKUP(B38,'Form responses 1'!$B$2:$B$2604,'Form responses 1'!$C$2:$C$2604,""))} -> NEDI HERYANDI/ YULIA IKA W | F38: {=IF(B38="","",_xlfn.XLOOKUP(B38,'Form responses 1'!$B$2:$B$2604,'Form responses 1'!$D$2:$D$2604,""))} -> 0811721165 | G38: {=IF(B38="","",_xlfn.XLOOKUP(B38,'Form responses 1'!$B$2:$B$2604,'Form responses 1'!$E$2:$E$2604,""))} -> BN JUAL BELI | H38: {=IF(B38="","",_xlfn.XLOOKUP(B38,'Form responses 1'!$B$2:$B$2604,'Form responses 1'!$F$2:$F$2604,""))} -> B. 176/ LABUHAN RATU RAYA | I38: {=IF(B38="","",_xlfn.XLOOKUP(B38,'Form responses 1'!$B$2:$B$2604,'Form responses 1'!$I$2:$I$2604,""))} -> LABUHAN RATU RAYA | J38: {=IF(B38="","",_xlfn.XLOOKUP(B38,'Form responses 1'!$B$2:$B$2604,'Form responses 1'!$G$2:$G$2604,""))} -> Hananda | K38: Kholfa | L38: =IF(K38<>"",IF(L38<>"",L38,NOW()),"") -> 45580.666 | M38: Perbaikan AJB= Alamat Direktur Utama PT, beda dengan Fc KTP terlampir | W38: SELESAI (LENGKAP) | X38: =IF(W38<>"",IF(X38<>"",X38,NOW()),"") -> 45588.391 | Y38: Cetak | Z38: =COUNTA(M38:V38) -> 1
B39: K/23/151024/3 | C39: {=IF(B39="","",_xlfn.XLOOKUP(B39,'Form responses 1'!$B$2:$B$2604,'Form responses 1'!$A$2:$A$2604,""))} -> 45580.48 | D39: =if(and(B39="",C39=""),"",CONCATENATE(B39,"_",C39)) -> K/23/151024/3_45580.4800118287 | E39: {=IF(B39="","",_xlfn.XLOOKUP(B39,'Form responses 1'!$B$2:$B$2604,'Form responses 1'!$C$2:$C$2604,""))} -> RAHMADIYANTI/ SELVI HELINA | F39: {=IF(B39="","",_xlfn.XLOOKUP(B39,'Form responses 1'!$B$2:$B$2604,'Form responses 1'!$D$2:$D$2604,""))} -> +62 821-8209-0051 | G39: {=IF(B39="","",_xlfn.XLOOKUP(B39,'Form responses 1'!$B$2:$B$2604,'Form responses 1'!$E$2:$E$2604,""))} -> BN JUAL BELI | H39: {=IF(B39="","",_xlfn.XLOOKUP(B39,'Form responses 1'!$B$2:$B$2604,'Form responses 1'!$F$2:$F$2604,""))} -> M. 509/ LABUHAN RATU RAYA | I39: {=IF(B39="","",_xlfn.XLOOKUP(B39,'Form responses 1'!$B$2:$B$2604,'Form responses 1'!$I$2:$I$2604,""))} -> LABUHAN RATU RAYA | J39: {=IF(B39="","",_xlfn.XLOOKUP(B39,'Form responses 1'!$B$2:$B$2604,'Form responses 1'!$G$2:$G$2604,""))} -> Hananda | K39: Kholfa | L39: =IF(K39<>"",IF(L39<>"",L39,NOW()),"") -> 45580.667 | W39: SELESAI (LENGKAP) | X39: =IF(W39<>"",IF(X39<>"",X39,NOW()),"") -> 45581.67 | Y39: Cetak | Z39: =COUNTA(M39:V39) -> 0
B40: K/11/151024/1 | C40: {=IF(B40="","",_xlfn.XLOOKUP(B40,'Form responses 1'!$B$2:$B$2604,'Form responses 1'!$A$2:$A$2604,""))} -> 45580.424 | D40: =if(and(B40="",C40=""),"",CONCATENATE(B40,"_",C40)) -> K/11/151024/1_45580.4240903357 | E40: {=IF(B40="","",_xlfn.XLOOKUP(B40,'Form responses 1'!$B$2:$B$2604,'Form responses 1'!$C$2:$C$2604,""))} -> Maryanti Kurniawan/ Suprapti R | F40: {=IF(B40="","",_xlfn.XLOOKUP(B40,'Form responses 1'!$B$2:$B$2604,'Form responses 1'!$D$2:$D$2604,""))} -> +62 811-7212-168 | G40: {=IF(B40="","",_xlfn.XLOOKUP(B40,'Form responses 1'!$B$2:$B$2604,'Form responses 1'!$E$2:$E$2604,""))} -> BN Jual Beli | H40: {=IF(B40="","",_xlfn.XLOOKUP(B40,'Form responses 1'!$B$2:$B$2604,'Form responses 1'!$F$2:$F$2604,""))} -> Nibel. M. 1869/ Sepang Jaya | I40: {=IF(B40="","",_xlfn.XLOOKUP(B40,'Form responses 1'!$B$2:$B$2604,'Form responses 1'!$I$2:$I$2604,""))} -> Sepang Jaya | J40: {=IF(B40="","",_xlfn.XLOOKUP(B40,'Form responses 1'!$B$2:$B$2604,'Form responses 1'!$G$2:$G$2604,""))} -> Rapita | K40: Kholfa | L40: =IF(K40<>"",IF(L40<>"",L40,NOW()),"") -> 45580.667 | W40: SELESAI (LENGKAP) | X40: =IF(W40<>"",IF(X40<>"",X40,NOW()),"") -> 45581.487 | Y40: Cetak | Z40: =COUNTA(M40:V40) -> 0
B41: K/34/151024/2 | C41: {=IF(B41="","",_xlfn.XLOOKUP(B41,'Form responses 1'!$B$2:$B$2604,'Form responses 1'!$A$2:$A$2604,""))} -> 45580.579 | D41: =if(and(B41="",C41=""),"",CONCATENATE(B41,"_",C41)) -> K/34/151024/2_45580.5789332523 | E41: {=IF(B41="","",_xlfn.XLOOKUP(B41,'Form responses 1'!$B$2:$B$2604,'Form responses 1'!$C$2:$C$2604,""))} -> Ayi Ruhiat/ Eri Yulianti | F41: {=IF(B41="","",_xlfn.XLOOKUP(B41,'Form responses 1'!$B$2:$B$2604,'Form responses 1'!$D$2:$D$2604,""))} -> 081272519799 | G41: {=IF(B41="","",_xlfn.XLOOKUP(B41,'Form responses 1'!$B$2:$B$2604,'Form responses 1'!$E$2:$E$2604,""))} -> BN Hibah | H41: {=IF(B41="","",_xlfn.XLOOKUP(B41,'Form responses 1'!$B$2:$B$2604,'Form responses 1'!$F$2:$F$2604,""))} -> M. 1311/ Beringin Jaya; dahulu B. 2093/ Beringin Raya | I41: {=IF(B41="","",_xlfn.XLOOKUP(B41,'Form responses 1'!$B$2:$B$2604,'Form responses 1'!$I$2:$I$2604,""))} -> Beringin Jaya | J41: {=IF(B41="","",_xlfn.XLOOKUP(B41,'Form responses 1'!$B$2:$B$2604,'Form responses 1'!$G$2:$G$2604,""))} -> Rapita | K41: Kholfa | L41: =IF(K41<>"",IF(L41<>"",L41,NOW()),"") -> 45580.667 | M41: Surat Keterlambatan Pendaftaran | W41: SELESAI (LENGKAP) | X41: =IF(W41<>"",IF(X41<>"",X41,NOW()),"") -> 45581.436 | Y41: Cetak | Z41: =COUNTA(M41:V41) -> 1
...

Sheet JS
B3: FORM CETAK ILA NOFRI | C3: Klik Disini
B4: FORM CETAK KHOLFA | C4: Klik Disini
B5: FORM CETAK GINTA MONITA | C5: Klik Disini
B6: FORM CETAK MAHARANI | C6: Klik Disini
B7: FORM CETAK ZEVINA | C7: Klik Disini
B8: FORM CETAK FIKKA | C8: Klik Disini

Sheet C1
A1: 25 | C1: m.2442/tanjung seneng / 3
D2: HOME
B3: FORM CETAK PERBAIKAN
B5: Nomor Tiket | C5: K/24/211024/1 | D5: =IF(C5="","",VLOOKUP(C5,Table_Kerja_Verifiaktor_Berkas[],A1,0)) -> 2
B6: Pembetulan Berkas Ke | C6: P0
C7: =CONCATENATE(C5,"_",C6) -> K/24/211024/1_P0
B8: Nomor | C8: Catatan
A9: 12 | B9: 1 | C9: =IF(C5="","",VLOOKUP($C$5,Verifikator!$B$4:$V$4002,$A9,0)) -> Tanggal. 25-10-2024 1. Validasi bidang 2. PBB kurang bayar tahun 3. Perbaiki Alamat ahli waris (nurmasnyah extrasona) pada permohonan, surat kuasa,surat pernyataan 4. Lampirkan surat keterangan beda nama pewaris pada akta kelahiran ahli waris
A10: =A9+1 -> 13 | B10: =IF(B9<$D$5,B9+1,"") -> 2 | C10: =IF(C6="","",VLOOKUP($C$5,Verifikator!$B$4:$V$4002,$A10,0)) -> SELESAI
A11: =A10+1 -> 14 | B11: =IF(B10<$D$5,B10+1,"") | C11: =IF(C7="","",VLOOKUP($C$5,Verifikator!$B$4:$V$4002,$A11,0))
A12: =A11+1 -> 15 | B12: =IF(B11<$D$5,B11+1,"") | C12: =IF(C8="","",VLOOKUP($C$5,Verifikator!$B$4:$V$4002,$A12,0))
A13: =A12+1 -> 16 | B13: =IF(B12<$D$5,B12+1,"") | C13: =IF(C9="","",VLOOKUP($C$5,Verifikator!$B$4:$V$4002,$A13,0))
A14: =A13+1 -> 17 | B14: =IF(B13<$D$5,B13+1,"") | C14: =IF(C10="","",VLOOKUP($C$5,Verifikator!$B$4:$V$4002,$A14,0))
A15: =A14+1 -> 18 | B15: =IF(B14<$D$5,B14+1,"") | C15: =IF(C11="","",VLOOKUP($C$5,Verifikator!$B$4:$V$4002,$A15,0))
A16: =A15+1 -> 19 | B16: =IF(B15<$D$5,B15+1,"") | C16: =IF(C12="","",VLOOKUP($C$5,Verifikator!$B$4:$V$4002,$A16,0))
A17: =A16+1 -> 20 | B17: =IF(B16<$D$5,B16+1,"") | C17: =IF(C13="","",VLOOKUP($C$5,Verifikator!$B$4:$V$4002,$A17,0))
A18: =A17+1 -> 21 | B18: =IF(B17<$D$5,B17+1,"") | C18: =IF(C14="","",VLOOKUP($C$5,Verifikator!$B$4:$V$4002,$A18,0))
C20: =Today() -> 46261

Sheet C2
A1: 25
D2: HOME
B3: FORM CETAK PERBAIKAN
B5: Nomor Tiket | C5: K/11/211024/2 | D5: =IF(C5="","",VLOOKUP(C5,Table_Kerja_Verifiaktor_Berkas[],A1,0)) -> 2
B6: Pembetulan Berkas Ke | C6: P0
C7: =CONCATENATE(C5,"_",C6) -> K/11/211024/2_P0
B8: Nomor | C8: Catatan
A9: 12 | B9: 1 | C9: =IF(C5="","",VLOOKUP($C$5,Verifikator!$B$4:$V$4002,$A9,0)) -> Isi lengkap SPernyataan BPHTB
A10: =A9+1 -> 13 | B10: =IF(B9<$D$5,B9+1,"") -> 2 | C10: =IF(C6="","",VLOOKUP($C$5,Verifikator!$B$4:$V$4002,$A10,0)) -> Fc RUPS dan Akta pendirian PT terlampir blm di cap &paraf notaris tiap halaman
A11: =A10+1 -> 14 | B11: =IF(B10<$D$5,B10+1,"") | C11: =IF(C7="","",VLOOKUP($C$5,Verifikator!$B$4:$V$4002,$A11,0))
A12: =A11+1 -> 15 | B12: =IF(B11<$D$5,B11+1,"") | C12: =IF(C8="","",VLOOKUP($C$5,Verifikator!$B$4:$V$4002,$A12,0))
A13: =A12+1 -> 16 | B13: =IF(B12<$D$5,B12+1,"") | C13: =IF(C9="","",VLOOKUP($C$5,Verifikator!$B$4:$V$4002,$A13,0))
A14: =A13+1 -> 17 | B14: =IF(B13<$D$5,B13+1,"") | C14: =IF(C10="","",VLOOKUP($C$5,Verifikator!$B$4:$V$4002,$A14,0))
A15: =A14+1 -> 18 | B15: =IF(B14<$D$5,B14+1,"") | C15: =IF(C11="","",VLOOKUP($C$5,Verifikator!$B$4:$V$4002,$A15,0))
A16: =A15+1 -> 19 | B16: =IF(B15<$D$5,B15+1,"") | C16: =IF(C12="","",VLOOKUP($C$5,Verifikator!$B$4:$V$4002,$A16,0))
A17: =A16+1 -> 20 | B17: =IF(B16<$D$5,B16+1,"") | C17: =IF(C13="","",VLOOKUP($C$5,Verifikator!$B$4:$V$4002,$A17,0))
A18: =A17+1 -> 21 | B18: =IF(B17<$D$5,B17+1,"") | C18: =IF(C14="","",VLOOKUP($C$5,Verifikator!$B$4:$V$4002,$A18,0))
C20: =Today() -> 46261

Sheet C3
A1: 25
D2: HOME
B3: FORM CETAK PERBAIKAN
B5: Nomor Tiket | C5: K/36/131124/1 | D5: =IF(C5="","",VLOOKUP(C5,Table_Kerja_Verifiaktor_Berkas[],A1,0)) -> 3
B6: Pembetulan Berkas Ke | C6: P0
C7: =CONCATENATE(C5,"_",C6) -> K/36/131124/1_P0
B8: Nomor | C8: Catatan
A9: 12 | B9: 1 | C9: =IF(C5="","",VLOOKUP($C$5,Verifikator!$B$4:$V$4002,$A9,0)) -> SURAT KUASA DAN PERNYATAAN TGL 4-9-2019? MENGAPA? APAKAH MASIH BERLAKU
A10: =A9+1 -> 13 | B10: =IF(B9<$D$5,B9+1,"") -> 2 | C10: =IF(C6="","",VLOOKUP($C$5,Verifikator!$B$4:$V$4002,$A10,0)) -> MENGAPA MEMBUAT AJB TAHUN 2019 BARU DI DAFTARKAN SEKARANG?
A11: =A10+1 -> 14 | B11: =IF(B10<$D$5,B10+1,"") -> 3 | C11: =IF(C7="","",VLOOKUP($C$5,Verifikator!$B$4:$V$4002,$A11,0)) -> RENVOI NOMOR SURAT PERSETUJUAN ANAK DI AJB
A12: =A11+1 -> 15 | B12: =IF(B11<$D$5,B11+1,"") | C12: =IF(C8="","",VLOOKUP($C$5,Verifikator!$B$4:$V$4002,$A12,0))
A13: =A12+1 -> 16 | B13: =IF(B12<$D$5,B12+1,"") | C13: =IF(C9="","",VLOOKUP($C$5,Verifikator!$B$4:$V$4002,$A13,0))
A14: =A13+1 -> 17 | B14: =IF(B13<$D$5,B13+1,"") | C14: =IF(C10="","",VLOOKUP($C$5,Verifikator!$B$4:$V$4002,$A14,0))
A15: =A14+1 -> 18 | B15: =IF(B14<$D$5,B14+1,"") | C15: =IF(C11="","",VLOOKUP($C$5,Verifikator!$B$4:$V$4002,$A15,0))
A16: =A15+1 -> 19 | B16: =IF(B15<$D$5,B15+1,"") | C16: =IF(C12="","",VLOOKUP($C$5,Verifikator!$B$4:$V$4002,$A16,0))
A17: =A16+1 -> 20 | B17: =IF(B16<$D$5,B16+1,"") | C17: =IF(C13="","",VLOOKUP($C$5,Verifikator!$B$4:$V$4002,$A17,0))
A18: =A17+1 -> 21 | B18: =IF(B17<$D$5,B17+1,"") | C18: =IF(C14="","",VLOOKUP($C$5,Verifikator!$B$4:$V$4002,$A18,0))
C20: =Today() -> 46261

Sheet C4
A1: 25
D2: HOME
B3: FORM CETAK PERBAIKAN
B5: Nomor Tiket | C5: K/25/011124/2 | D5: =IF(C5="","",VLOOKUP(C5,Table_Kerja_Verifiaktor_Berkas[],A1,0)) -> 1
B6: Pembetulan Berkas Ke | C6: P0
C7: =CONCATENATE(C5,"_",C6) -> K/25/011124/2_P0
B8: Nomor | C8: Catatan
A9: 12 | B9: 1 | C9: =IF(C5="","",VLOOKUP($C$5,Verifikator!$B$4:$V$4002,$A9,0)) -> 1. TT 2. Cek luas pemecahan pada sket lokasi yang digambarkan
A10: =A9+1 -> 13 | B10: =IF(B9<$D$5,B9+1,"") | C10: =IF(C6="","",VLOOKUP($C$5,Verifikator!$B$4:$V$4002,$A10,0))
A11: =A10+1 -> 14 | B11: =IF(B10<$D$5,B10+1,"") | C11: =IF(C7="","",VLOOKUP($C$5,Verifikator!$B$4:$V$4002,$A11,0))
A12: =A11+1 -> 15 | B12: =IF(B11<$D$5,B11+1,"") | C12: =IF(C8="","",VLOOKUP($C$5,Verifikator!$B$4:$V$4002,$A12,0))
A13: =A12+1 -> 16 | B13: =IF(B12<$D$5,B12+1,"") | C13: =IF(C9="","",VLOOKUP($C$5,Verifikator!$B$4:$V$4002,$A13,0))
A14: =A13+1 -> 17 | B14: =IF(B13<$D$5,B13+1,"") | C14: =IF(C10="","",VLOOKUP($C$5,Verifikator!$B$4:$V$4002,$A14,0))
A15: =A14+1 -> 18 | B15: =IF(B14<$D$5,B14+1,"") | C15: =IF(C11="","",VLOOKUP($C$5,Verifikator!$B$4:$V$4002,$A15,0))
A16: =A15+1 -> 19 | B16: =IF(B15<$D$5,B15+1,"") | C16: =IF(C12="","",VLOOKUP($C$5,Verifikator!$B$4:$V$4002,$A16,0))
A17: =A16+1 -> 20 | B17: =IF(B16<$D$5,B16+1,"") | C17: =IF(C13="","",VLOOKUP($C$5,Verifikator!$B$4:$V$4002,$A17,0))
A18: =A17+1 -> 21 | B18: =IF(B17<$D$5,B17+1,"") | C18: =IF(C14="","",VLOOKUP($C$5,Verifikator!$B$4:$V$4002,$A18,0))
C20: =Today() -> 46261

Sheet C5
A1: 25
D2: HOME
B3: FORM CETAK PERBAIKAN
B5: Nomor Tiket | C5: L/17/141024/1 | D5: =IF(C5="","",VLOOKUP(C5,Table_Kerja_Verifiaktor_Berkas[],A1,0)) -> 2
B6: Pembetulan Berkas Ke | C6: P0
C7: =CONCATENATE(C5,"_",C6) -> L/17/141024/1_P0
B8: Nomor | C8: Catatan
A9: 12 | B9: 1 | C9: =IF(C5="","",VLOOKUP($C$5,Verifikator!$B$4:$V$4002,$A9,0)) -> PLOTING + VALBID
A10: =A9+1 -> 13 | B10: =IF(B9<$D$5,B9+1,"") -> 2 | C10: =IF(C6="","",VLOOKUP($C$5,Verifikator!$B$4:$V$4002,$A10,0)) -> BEDA NAMA PEMILIK ANTARA SERTIPIKAT DAN KTP
A11: =A10+1 -> 14 | B11: =IF(B10<$D$5,B10+1,"") | C11: =IF(C7="","",VLOOKUP($C$5,Verifikator!$B$4:$V$4002,$A11,0))
A12: =A11+1 -> 15 | B12: =IF(B11<$D$5,B11+1,"") | C12: =IF(C8="","",VLOOKUP($C$5,Verifikator!$B$4:$V$4002,$A12,0))
