Workbook

Sheet Form Responses Loket
B1: https://docs.google.com/spreadsheets/d/1BiVpi0WpqThm5wAzoeAIKEkTsofTP81O3MZ4f8L-uXo/edit?gid=1040887655#gid=1040887655
B3: Nomor Tiket | C3: Daftar Nomor Hak | D3: Time Stamp | E3: Jenis Permohonan | F3: Nama Pemohon | G3: Count | H3: Pembetulan Berkas
B4: =IFERROR(__xludf.DUMMYFUNCTION("IMPORTRANGE($B$1,""Form responses 1!B2:B10000"")"),"") | C4: =IFERROR(__xludf.DUMMYFUNCTION("IMPORTRANGE($B$1,""Form responses 1!F2:F10000"")"),"") | D4: =IFERROR(__xludf.DUMMYFUNCTION("IMPORTRANGE($B$1,""Form responses 1!A2:A10000"")"),"") | E4: =IFERROR(__xludf.DUMMYFUNCTION("IMPORTRANGE($B$1,""Form responses 1!E2:E10000"")"),"") | F4: =IFERROR(__xludf.DUMMYFUNCTION("IMPORTRANGE($B$1,""Form responses 1!C2:C10000"")"),"") | G4: 1 | H4: =IFERROR(__xludf.DUMMYFUNCTION("IMPORTRANGE($B$1,""Form responses 1!H2:H10000"")"),"")
G5: =IF(OR(C5="-",C5="",H5<>"P0"),G4,G4+1) -> 1
B6: =IFERROR(__xludf.DUMMYFUNCTION("""COMPUTED_VALUE"""),"L/1/141024/1") -> L/1/141024/1 | C6: =IFERROR(__xludf.DUMMYFUNCTION("""COMPUTED_VALUE"""),"HM 9463/GEDUNG MENENG") -> HM 9463/GEDUNG MENENG | D6: =IFERROR(__xludf.DUMMYFUNCTION("""COMPUTED_VALUE"""),45579.36115568287) -> 45579.361 | E6: =IFERROR(__xludf.DUMMYFUNCTION("""COMPUTED_VALUE"""),"ROYA") -> ROYA | F6: =IFERROR(__xludf.DUMMYFUNCTION("""COMPUTED_VALUE"""),"CHAIRUL ANWAR SATAR") -> CHAIRUL ANWAR SATAR | G6: =IF(OR(C6="-",C6="",H6<>"P0"),G5,G5+1) -> 2 | H6: =IFERROR(__xludf.DUMMYFUNCTION("""COMPUTED_VALUE"""),"P0") -> P0
B7: =IFERROR(__xludf.DUMMYFUNCTION("""COMPUTED_VALUE"""),"L/2/141024/1") -> L/2/141024/1 | C7: =IFERROR(__xludf.DUMMYFUNCTION("""COMPUTED_VALUE"""),"HM 17565/SUKARAME I") -> HM 17565/SUKARAME I | D7: =IFERROR(__xludf.DUMMYFUNCTION("""COMPUTED_VALUE"""),45579.37694246528) -> 45579.377 | E7: =IFERROR(__xludf.DUMMYFUNCTION("""COMPUTED_VALUE"""),"ROYA") -> ROYA | F7: =IFERROR(__xludf.DUMMYFUNCTION("""COMPUTED_VALUE"""),"RIRIN OKTARINA") -> RIRIN OKTARINA | G7: =IF(OR(C7="-",C7="",H7<>"P0"),G6,G6+1) -> 3 | H7: =IFERROR(__xludf.DUMMYFUNCTION("""COMPUTED_VALUE"""),"P0") -> P0
B8: =IFERROR(__xludf.DUMMYFUNCTION("""COMPUTED_VALUE"""),"K/3/141024/1") -> K/3/141024/1 | C8: =IFERROR(__xludf.DUMMYFUNCTION("""COMPUTED_VALUE"""),"-") -> - | D8: =IFERROR(__xludf.DUMMYFUNCTION("""COMPUTED_VALUE"""),45579.39939559028) -> 45579.399 | E8: =IFERROR(__xludf.DUMMYFUNCTION("""COMPUTED_VALUE"""),"PTPGT") -> PTPGT | F8: =IFERROR(__xludf.DUMMYFUNCTION("""COMPUTED_VALUE"""),"GURUH SAMODRA AJI, ST.MT/WAHYUDIN") -> GURUH SAMODRA AJI, ST.MT/WAHYUDIN | G8: =IF(OR(C8="-",C8="",H8<>"P0"),G7,G7+1) -> 3 | H8: =IFERROR(__xludf.DUMMYFUNCTION("""COMPUTED_VALUE"""),"P0") -> P0
B9: =IFERROR(__xludf.DUMMYFUNCTION("""COMPUTED_VALUE"""),"K/4/141024/2") -> K/4/141024/2 | C9: =IFERROR(__xludf.DUMMYFUNCTION("""COMPUTED_VALUE"""),"-") -> - | D9: =IFERROR(__xludf.DUMMYFUNCTION("""COMPUTED_VALUE"""),45579.40069350695) -> 45579.401 | E9: =IFERROR(__xludf.DUMMYFUNCTION("""COMPUTED_VALUE"""),"PTPGT") -> PTPGT | F9: =IFERROR(__xludf.DUMMYFUNCTION("""COMPUTED_VALUE"""),"GURUH SAMODRA AJI, ST.MT/WAHYUDIN") -> GURUH SAMODRA AJI, ST.MT/WAHYUDIN | G9: =IF(OR(C9="-",C9="",H9<>"P0"),G8,G8+1) -> 3 | H9: =IFERROR(__xludf.DUMMYFUNCTION("""COMPUTED_VALUE"""),"P0") -> P0
B10: =IFERROR(__xludf.DUMMYFUNCTION("""COMPUTED_VALUE"""),"L/5/141024/1") -> L/5/141024/1 | C10: =IFERROR(__xludf.DUMMYFUNCTION("""COMPUTED_VALUE"""),"M.9974/TANJUNG BARU") -> M.9974/TANJUNG BARU | D10: =IFERROR(__xludf.DUMMYFUNCTION("""COMPUTED_VALUE"""),45579.40328578703) -> 45579.403 | E10: =IFERROR(__xludf.DUMMYFUNCTION("""COMPUTED_VALUE"""),"ROYA") -> ROYA | F10: =IFERROR(__xludf.DUMMYFUNCTION("""COMPUTED_VALUE"""),"SITI NAZROH") -> SITI NAZROH | G10: =IF(OR(C10="-",C10="",H10<>"P0"),G9,G9+1) -> 4 | H10: =IFERROR(__xludf.DUMMYFUNCTION("""COMPUTED_VALUE"""),"P0") -> P0
B11: =IFERROR(__xludf.DUMMYFUNCTION("""COMPUTED_VALUE"""),"L/6/141024/1") -> L/6/141024/1 | C11: =IFERROR(__xludf.DUMMYFUNCTION("""COMPUTED_VALUE""")," HM 154/SUSUNAN BARU") -> HM 154/SUSUNAN BARU | D11: =IFERROR(__xludf.DUMMYFUNCTION("""COMPUTED_VALUE"""),45579.40467556713) -> 45579.405 | E11: =IFERROR(__xludf.DUMMYFUNCTION("""COMPUTED_VALUE"""),"PLOT SERTIPIKAT HILANG") -> PLOT SERTIPIKAT HILANG | F11: =IFERROR(__xludf.DUMMYFUNCTION("""COMPUTED_VALUE"""),"EMY MARSINEM") -> EMY MARSINEM | G11: =IF(OR(C11="-",C11="",H11<>"P0"),G10,G10+1) -> 5 | H11: =IFERROR(__xludf.DUMMYFUNCTION("""COMPUTED_VALUE"""),"P0") -> P0
B12: =IFERROR(__xludf.DUMMYFUNCTION("""COMPUTED_VALUE"""),"K/7/141024/1") -> K/7/141024/1 | C12: =IFERROR(__xludf.DUMMYFUNCTION("""COMPUTED_VALUE"""),"M. 631/Pahoman- sekarang; M. 631/Pahoman-Dahulu") -> M. 631/Pahoman- sekarang; M. 631/Pahoman-Dahulu | D12: =IFERROR(__xludf.DUMMYFUNCTION("""COMPUTED_VALUE"""),45579.40998118056) -> 45579.41 | E12: =IFERROR(__xludf.DUMMYFUNCTION("""COMPUTED_VALUE"""),"ANGKAT SITA") -> ANGKAT SITA | F12: =IFERROR(__xludf.DUMMYFUNCTION("""COMPUTED_VALUE"""),"IKE FEBRINA, S.IP") -> IKE FEBRINA, S.IP | G12: =IF(OR(C12="-",C12="",H12<>"P0"),G11,G11+1) -> 6 | H12: =IFERROR(__xludf.DUMMYFUNCTION("""COMPUTED_VALUE"""),"P0") -> P0
B13: =IFERROR(__xludf.DUMMYFUNCTION("""COMPUTED_VALUE"""),"L/8/141024/1") -> L/8/141024/1 | C13: =IFERROR(__xludf.DUMMYFUNCTION("""COMPUTED_VALUE"""),"M.1134/GULAK GALIK") -> M.1134/GULAK GALIK | D13: =IFERROR(__xludf.DUMMYFUNCTION("""COMPUTED_VALUE"""),45579.416174513884) -> 45579.416 | E13: =IFERROR(__xludf.DUMMYFUNCTION("""COMPUTED_VALUE"""),"HAPUS BPHTB") -> HAPUS BPHTB | F13: =IFERROR(__xludf.DUMMYFUNCTION("""COMPUTED_VALUE"""),"JUNAIDI") -> JUNAIDI | G13: =IF(OR(C13="-",C13="",H13<>"P0"),G12,G12+1) -> 7 | H13: =IFERROR(__xludf.DUMMYFUNCTION("""COMPUTED_VALUE"""),"P0") -> P0
B14: =IFERROR(__xludf.DUMMYFUNCTION("""COMPUTED_VALUE"""),"K/9/141024/1") -> K/9/141024/1 | C14: =IFERROR(__xludf.DUMMYFUNCTION("""COMPUTED_VALUE"""),"M.11980/JAGABAYA II") -> M.11980/JAGABAYA II | D14: =IFERROR(__xludf.DUMMYFUNCTION("""COMPUTED_VALUE"""),45579.42397335648) -> 45579.424 | E14: =IFERROR(__xludf.DUMMYFUNCTION("""COMPUTED_VALUE"""),"ROYA") -> ROYA | F14: =IFERROR(__xludf.DUMMYFUNCTION("""COMPUTED_VALUE"""),"LEOSA AUGDETA/LINGGA AYU B") -> LEOSA AUGDETA/LINGGA AYU B | G14: =IF(OR(C14="-",C14="",H14<>"P0"),G13,G13+1) -> 8 | H14: =IFERROR(__xludf.DUMMYFUNCTION("""COMPUTED_VALUE"""),"P0") -> P0
B15: =IFERROR(__xludf.DUMMYFUNCTION("""COMPUTED_VALUE"""),"L/11/141024/1") -> L/11/141024/1 | C15: =IFERROR(__xludf.DUMMYFUNCTION("""COMPUTED_VALUE"""),"HM 1505 LABUHAN DALAM & HM 1506 LABUHAN DALAM") -> HM 1505 LABUHAN DALAM & HM 1506 LABUHAN DALAM | D15: =IFERROR(__xludf.DUMMYFUNCTION("""COMPUTED_VALUE"""),45579.43479998843) -> 45579.435 | E15: =IFERROR(__xludf.DUMMYFUNCTION("""COMPUTED_VALUE"""),"ROYA") -> ROYA | F15: =IFERROR(__xludf.DUMMYFUNCTION("""COMPUTED_VALUE"""),"HENNY INDRIYANI") -> HENNY INDRIYANI | G15: =IF(OR(C15="-",C15="",H15<>"P0"),G14,G14+1) -> 9 | H15: =IFERROR(__xludf.DUMMYFUNCTION("""COMPUTED_VALUE"""),"P0") -> P0
B16: =IFERROR(__xludf.DUMMYFUNCTION("""COMPUTED_VALUE"""),"K/10/141024/2") -> K/10/141024/2 | C16: =IFERROR(__xludf.DUMMYFUNCTION("""COMPUTED_VALUE"""),"-") -> - | D16: =IFERROR(__xludf.DUMMYFUNCTION("""COMPUTED_VALUE"""),45579.4453597338) -> 45579.445 | E16: =IFERROR(__xludf.DUMMYFUNCTION("""COMPUTED_VALUE"""),"GANDES") -> GANDES | F16: =IFERROR(__xludf.DUMMYFUNCTION("""COMPUTED_VALUE"""),"ANTONI SINULINGGA /LINGGA A") -> ANTONI SINULINGGA /LINGGA A | G16: =IF(OR(C16="-",C16="",H16<>"P0"),G15,G15+1) -> 9 | H16: =IFERROR(__xludf.DUMMYFUNCTION("""COMPUTED_VALUE"""),"P0") -> P0
B17: =IFERROR(__xludf.DUMMYFUNCTION("""COMPUTED_VALUE"""),"K/12/141024/1") -> K/12/141024/1 | C17: =IFERROR(__xludf.DUMMYFUNCTION("""COMPUTED_VALUE"""),"M.3326/LANGKAPURA") -> M.3326/LANGKAPURA | D17: =IFERROR(__xludf.DUMMYFUNCTION("""COMPUTED_VALUE"""),45579.44647563658) -> 45579.446 | E17: =IFERROR(__xludf.DUMMYFUNCTION("""COMPUTED_VALUE"""),"ROYA") -> ROYA | F17: =IFERROR(__xludf.DUMMYFUNCTION("""COMPUTED_VALUE"""),"META ARIDHOTU PRANATA /PANARY SITOPU") -> META ARIDHOTU PRANATA /PANARY SITOPU | G17: =IF(OR(C17="-",C17="",H17<>"P0"),G16,G16+1) -> 10 | H17: =IFERROR(__xludf.DUMMYFUNCTION("""COMPUTED_VALUE"""),"P0") -> P0
B18: =IFERROR(__xludf.DUMMYFUNCTION("""COMPUTED_VALUE"""),"K/13/141024/2") -> K/13/141024/2 | C18: =IFERROR(__xludf.DUMMYFUNCTION("""COMPUTED_VALUE"""),"M.1088/NEGERI OLOK GADING-SEKARANG;B.1201/NEGERI OLOK GADING-DAHULU") -> M.1088/NEGERI OLOK GADING-SEKARANG;B.1201/NEGERI OLOK GADING-DAHULU | D18: =IFERROR(__xludf.DUMMYFUNCTION("""COMPUTED_VALUE"""),45579.448010532404) -> 45579.448 | E18: =IFERROR(__xludf.DUMMYFUNCTION("""COMPUTED_VALUE"""),"ROYA") -> ROYA | F18: =IFERROR(__xludf.DUMMYFUNCTION("""COMPUTED_VALUE"""),"APRILIA/PANARY SITOPU") -> APRILIA/PANARY SITOPU | G18: =IF(OR(C18="-",C18="",H18<>"P0"),G17,G17+1) -> 11 | H18: =IFERROR(__xludf.DUMMYFUNCTION("""COMPUTED_VALUE"""),"P0") -> P0
B19: =IFERROR(__xludf.DUMMYFUNCTION("""COMPUTED_VALUE"""),"K/14/141024/3") -> K/14/141024/3 | C19: =IFERROR(__xludf.DUMMYFUNCTION("""COMPUTED_VALUE"""),"M.988/NEGERI OLOK GADING-SEKARANG;B.1050/NEGERI OLOK GADING-DAHULU") -> M.988/NEGERI OLOK GADING-SEKARANG;B.1050/NEGERI OLOK GADING-DAHULU | D19: =IFERROR(__xludf.DUMMYFUNCTION("""COMPUTED_VALUE"""),45579.44913846065) -> 45579.449 | E19: =IFERROR(__xludf.DUMMYFUNCTION("""COMPUTED_VALUE"""),"ROYA") -> ROYA | F19: =IFERROR(__xludf.DUMMYFUNCTION("""COMPUTED_VALUE"""),"APRILIA/PANARY SITOPU") -> APRILIA/PANARY SITOPU | G19: =IF(OR(C19="-",C19="",H19<>"P0"),G18,G18+1) -> 12 | H19: =IFERROR(__xludf.DUMMYFUNCTION("""COMPUTED_VALUE"""),"P0") -> P0
B20: =IFERROR(__xludf.DUMMYFUNCTION("""COMPUTED_VALUE"""),"K/15/141024/4") -> K/15/141024/4 | C20: =IFERROR(__xludf.DUMMYFUNCTION("""COMPUTED_VALUE"""),"-") -> - | D20: =IFERROR(__xludf.DUMMYFUNCTION("""COMPUTED_VALUE"""),45579.45057248842) -> 45579.451 | E20: =IFERROR(__xludf.DUMMYFUNCTION("""COMPUTED_VALUE"""),"PENINGKATAN HAK") -> PENINGKATAN HAK | F20: =IFERROR(__xludf.DUMMYFUNCTION("""COMPUTED_VALUE"""),"PANGGARA PAGARISI/PANARY SITOPU") -> PANGGARA PAGARISI/PANARY SITOPU | G20: =IF(OR(C20="-",C20="",H20<>"P0"),G19,G19+1) -> 12 | H20: =IFERROR(__xludf.DUMMYFUNCTION("""COMPUTED_VALUE"""),"P0") -> P0
B21: =IFERROR(__xludf.DUMMYFUNCTION("""COMPUTED_VALUE"""),"K/16/141024/1") -> K/16/141024/1 | C21: =IFERROR(__xludf.DUMMYFUNCTION("""COMPUTED_VALUE"""),"M.9137/GEDONG MENENG") -> M.9137/GEDONG MENENG | D21: =IFERROR(__xludf.DUMMYFUNCTION("""COMPUTED_VALUE"""),45579.46382863426) -> 45579.464 | E21: =IFERROR(__xludf.DUMMYFUNCTION("""COMPUTED_VALUE"""),"SKPT") -> SKPT | F21: =IFERROR(__xludf.DUMMYFUNCTION("""COMPUTED_VALUE"""),"TITIK WIJAYANTI/SENDI DINI HARIYATI") -> TITIK WIJAYANTI/SENDI DINI HARIYATI | G21: =IF(OR(C21="-",C21="",H21<>"P0"),G20,G20+1) -> 13 | H21: =IFERROR(__xludf.DUMMYFUNCTION("""COMPUTED_VALUE"""),"P0") -> P0
B22: =IFERROR(__xludf.DUMMYFUNCTION("""COMPUTED_VALUE"""),"L/17/141024/1") -> L/17/141024/1 | C22: =IFERROR(__xludf.DUMMYFUNCTION("""COMPUTED_VALUE"""),"HM 2144/WAY KANDIS") -> HM 2144/WAY KANDIS | D22: =IFERROR(__xludf.DUMMYFUNCTION("""COMPUTED_VALUE"""),45579.47772299769) -> 45579.478 | E22: =IFERROR(__xludf.DUMMYFUNCTION("""COMPUTED_VALUE"""),"ROYA") -> ROYA | F22: =IFERROR(__xludf.DUMMYFUNCTION("""COMPUTED_VALUE"""),"SARIFUDDIN HUTAGALUNG") -> SARIFUDDIN HUTAGALUNG | G22: =IF(OR(C22="-",C22="",H22<>"P0"),G21,G21+1) -> 14 | H22: =IFERROR(__xludf.DUMMYFUNCTION("""COMPUTED_VALUE"""),"P0") -> P0
B23: =IFERROR(__xludf.DUMMYFUNCTION("""COMPUTED_VALUE"""),"K/19/141024/1") -> K/19/141024/1 | C23: =IFERROR(__xludf.DUMMYFUNCTION("""COMPUTED_VALUE"""),"M.16678/SUKABUMI") -> M.16678/SUKABUMI | D23: =IFERROR(__xludf.DUMMYFUNCTION("""COMPUTED_VALUE"""),45579.48395140046) -> 45579.484 | E23: =IFERROR(__xludf.DUMMYFUNCTION("""COMPUTED_VALUE"""),"PERALIHAN JUAL BELI") -> PERALIHAN JUAL BELI | F23: =IFERROR(__xludf.DUMMYFUNCTION("""COMPUTED_VALUE"""),"ROSIDA LINGSA KENCANA/RAHMADIYANTI") -> ROSIDA LINGSA KENCANA/RAHMADIYANTI | G23: =IF(OR(C23="-",C23="",H23<>"P0"),G22,G22+1) -> 15 | H23: =IFERROR(__xludf.DUMMYFUNCTION("""COMPUTED_VALUE"""),"P0") -> P0
B24: =IFERROR(__xludf.DUMMYFUNCTION("""COMPUTED_VALUE"""),"L/18/141024/1") -> L/18/141024/1 | C24: =IFERROR(__xludf.DUMMYFUNCTION("""COMPUTED_VALUE"""),"M.331/NUSANTARA PERMAI;B.389/CAMPANG RAYA-DAHULU") -> M.331/NUSANTARA PERMAI;B.389/CAMPANG RAYA-DAHULU | D24: =IFERROR(__xludf.DUMMYFUNCTION("""COMPUTED_VALUE"""),45579.484038842595) -> 45579.484 | E24: =IFERROR(__xludf.DUMMYFUNCTION("""COMPUTED_VALUE"""),"BLOKIR") -> BLOKIR | F24: =IFERROR(__xludf.DUMMYFUNCTION("""COMPUTED_VALUE"""),"SUNILA HAKI") -> SUNILA HAKI | G24: =IF(OR(C24="-",C24="",H24<>"P0"),G23,G23+1) -> 16 | H24: =IFERROR(__xludf.DUMMYFUNCTION("""COMPUTED_VALUE"""),"P0") -> P0
B25: =IFERROR(__xludf.DUMMYFUNCTION("""COMPUTED_VALUE"""),"K/20/141024/1") -> K/20/141024/1 | C25: =IFERROR(__xludf.DUMMYFUNCTION("""COMPUTED_VALUE"""),"M.12883/RAJABASA-SEKARANG;B.1210/RAJABASA-DAHULU") -> M.12883/RAJABASA-SEKARANG;B.1210/RAJABASA-DAHULU | D25: =IFERROR(__xludf.DUMMYFUNCTION("""COMPUTED_VALUE"""),45579.48986872685) -> 45579.49 | E25: =IFERROR(__xludf.DUMMYFUNCTION("""COMPUTED_VALUE"""),"GANDES") -> GANDES | F25: =IFERROR(__xludf.DUMMYFUNCTION("""COMPUTED_VALUE"""),"BERRYAN AULIA UMAM J/HARITO WIDODO") -> BERRYAN AULIA UMAM J/HARITO WIDODO | G25: =IF(OR(C25="-",C25="",H25<>"P0"),G24,G24+1) -> 17 | H25: =IFERROR(__xludf.DUMMYFUNCTION("""COMPUTED_VALUE"""),"P0") -> P0
B26: =IFERROR(__xludf.DUMMYFUNCTION("""COMPUTED_VALUE"""),"L/21/141024/1") -> L/21/141024/1 | C26: =IFERROR(__xludf.DUMMYFUNCTION("""COMPUTED_VALUE"""),"HM 1812/TANJUNG SENANG") -> HM 1812/TANJUNG SENANG | D26: =IFERROR(__xludf.DUMMYFUNCTION("""COMPUTED_VALUE"""),45579.49266887731) -> 45579.493 | E26: =IFERROR(__xludf.DUMMYFUNCTION("""COMPUTED_VALUE"""),"ROYA") -> ROYA | F26: =IFERROR(__xludf.DUMMYFUNCTION("""COMPUTED_VALUE"""),"DWI ASTANTO") -> DWI ASTANTO | G26: =IF(OR(C26="-",C26="",H26<>"P0"),G25,G25+1) -> 18 | H26: =IFERROR(__xludf.DUMMYFUNCTION("""COMPUTED_VALUE"""),"P0") -> P0
B27: =IFERROR(__xludf.DUMMYFUNCTION("""COMPUTED_VALUE"""),"K/22/141024/1") -> K/22/141024/1 | C27: =IFERROR(__xludf.DUMMYFUNCTION("""COMPUTED_VALUE"""),"M. 6977/ TANJUNG SENANG") -> M. 6977/ TANJUNG SENANG | D27: =IFERROR(__xludf.DUMMYFUNCTION("""COMPUTED_VALUE"""),45579.49679517361) -> 45579.497 | E27: =IFERROR(__xludf.DUMMYFUNCTION("""COMPUTED_VALUE"""),"PERALIHAN JUAL BELI") -> PERALIHAN JUAL BELI | F27: =IFERROR(__xludf.DUMMYFUNCTION("""COMPUTED_VALUE"""),"MURSALIN") -> MURSALIN | G27: =IF(OR(C27="-",C27="",H27<>"P0"),G26,G26+1) -> 19 | H27: =IFERROR(__xludf.DUMMYFUNCTION("""COMPUTED_VALUE"""),"P0") -> P0
B28: =IFERROR(__xludf.DUMMYFUNCTION("""COMPUTED_VALUE"""),"K/23/141024/2") -> K/23/141024/2 | C28: =IFERROR(__xludf.DUMMYFUNCTION("""COMPUTED_VALUE"""),"M. 246/ GUNUNG SULAH") -> M. 246/ GUNUNG SULAH | D28: =IFERROR(__xludf.DUMMYFUNCTION("""COMPUTED_VALUE"""),45579.500235740736) -> 45579.5 | E28: =IFERROR(__xludf.DUMMYFUNCTION("""COMPUTED_VALUE"""),"PLOTTING") -> PLOTTING | F28: =IFERROR(__xludf.DUMMYFUNCTION("""COMPUTED_VALUE"""),"MURSALIN") -> MURSALIN | G28: =IF(OR(C28="-",C28="",H28<>"P0"),G27,G27+1) -> 20 | H28: =IFERROR(__xludf.DUMMYFUNCTION("""COMPUTED_VALUE"""),"P0") -> P0
B29: =IFERROR(__xludf.DUMMYFUNCTION("""COMPUTED_VALUE"""),"L/24/141024/1") -> L/24/141024/1 | C29: =IFERROR(__xludf.DUMMYFUNCTION("""COMPUTED_VALUE"""),"M.2064/GUNUNG TERANG") -> M.2064/GUNUNG TERANG | D29: =IFERROR(__xludf.DUMMYFUNCTION("""COMPUTED_VALUE"""),45579.50035021991) -> 45579.5 | E29: =IFERROR(__xludf.DUMMYFUNCTION("""COMPUTED_VALUE"""),"ROYA") -> ROYA | F29: =IFERROR(__xludf.DUMMYFUNCTION("""COMPUTED_VALUE"""),"DEWI YULIANA") -> DEWI YULIANA | G29: =IF(OR(C29="-",C29="",H29<>"P0"),G28,G28+1) -> 21 | H29: =IFERROR(__xludf.DUMMYFUNCTION("""COMPUTED_VALUE"""),"P0") -> P0
B30: =IFERROR(__xludf.DUMMYFUNCTION("""COMPUTED_VALUE"""),"K/25/141024/3") -> K/25/141024/3 | C30: =IFERROR(__xludf.DUMMYFUNCTION("""COMPUTED_VALUE"""),"M. 133/ SUKARAME BARU- SEKARANG; B. 144/ SUKARAME BARU-DAHULU; B. 4605/SUKARAME I-DAHULU") -> M. 133/ SUKARAME BARU- SEKARANG; B. 144/ SUKARAME BARU-DAHULU; B. 4605/SUKARAME I-DAHULU | D30: =IFERROR(__xludf.DUMMYFUNCTION("""COMPUTED_VALUE"""),45579.55981415509) -> 45579.56 | E30: =IFERROR(__xludf.DUMMYFUNCTION("""COMPUTED_VALUE"""),"PERALIHAN JUAL BELI") -> PERALIHAN JUAL BELI | F30: =IFERROR(__xludf.DUMMYFUNCTION("""COMPUTED_VALUE"""),"MURSALIN") -> MURSALIN | G30: =IF(OR(C30="-",C30="",H30<>"P0"),G29,G29+1) -> 22 | H30: =IFERROR(__xludf.DUMMYFUNCTION("""COMPUTED_VALUE"""),"P0") -> P0
B31: =IFERROR(__xludf.DUMMYFUNCTION("""COMPUTED_VALUE"""),"K/26/141024/1") -> K/26/141024/1 | C31: =IFERROR(__xludf.DUMMYFUNCTION("""COMPUTED_VALUE"""),"M.2094/CAMPANG JAYA") -> M.2094/CAMPANG JAYA | D31: =IFERROR(__xludf.DUMMYFUNCTION("""COMPUTED_VALUE"""),45579.565665312504) -> 45579.566 | E31: =IFERROR(__xludf.DUMMYFUNCTION("""COMPUTED_VALUE"""),"PERALIHAN JUAL BELI") -> PERALIHAN JUAL BELI | F31: =IFERROR(__xludf.DUMMYFUNCTION("""COMPUTED_VALUE"""),"KHARISMA MANISHA CECILIYA/ILANUR") -> KHARISMA MANISHA CECILIYA/ILANUR | G31: =IF(OR(C31="-",C31="",H31<>"P0"),G30,G30+1) -> 23 | H31: =IFERROR(__xludf.DUMMYFUNCTION("""COMPUTED_VALUE"""),"P0") -> P0
B32: =IFERROR(__xludf.DUMMYFUNCTION("""COMPUTED_VALUE"""),"K/27/141024/4") -> K/27/141024/4 | C32: =IFERROR(__xludf.DUMMYFUNCTION("""COMPUTED_VALUE"""),"M. 13414/ SUKABUMI") -> M. 13414/ SUKABUMI | D32: =IFERROR(__xludf.DUMMYFUNCTION("""COMPUTED_VALUE"""),45579.57014332176) -> 45579.57 | E32: =IFERROR(__xludf.DUMMYFUNCTION("""COMPUTED_VALUE"""),"PERALIHAN JUAL BELI") -> PERALIHAN JUAL BELI | F32: =IFERROR(__xludf.DUMMYFUNCTION("""COMPUTED_VALUE"""),"MURSALIN") -> MURSALIN | G32: =IF(OR(C32="-",C32="",H32<>"P0"),G31,G31+1) -> 24 | H32: =IFERROR(__xludf.DUMMYFUNCTION("""COMPUTED_VALUE"""),"P0") -> P0
B33: =IFERROR(__xludf.DUMMYFUNCTION("""COMPUTED_VALUE"""),"K/28/141024/1") -> K/28/141024/1 | C33: =IFERROR(__xludf.DUMMYFUNCTION("""COMPUTED_VALUE"""),"B.895/BERINGIN JAYA") -> B.895/BERINGIN JAYA | D33: =IFERROR(__xludf.DUMMYFUNCTION("""COMPUTED_VALUE"""),45579.572772569445) -> 45579.573 | E33: =IFERROR(__xludf.DUMMYFUNCTION("""COMPUTED_VALUE"""),"PERALIHAN JUAL BELI") -> PERALIHAN JUAL BELI | F33: =IFERROR(__xludf.DUMMYFUNCTION("""COMPUTED_VALUE"""),"ADE HERDIANYAH/WHINDA YULIANTI") -> ADE HERDIANYAH/WHINDA YULIANTI | G33: =IF(OR(C33="-",C33="",H33<>"P0"),G32,G32+1) -> 25 | H33: =IFERROR(__xludf.DUMMYFUNCTION("""COMPUTED_VALUE"""),"P0") -> P0
B34: =IFERROR(__xludf.DUMMYFUNCTION("""COMPUTED_VALUE"""),"K/29/141024/1") -> K/29/141024/1 | C34: =IFERROR(__xludf.DUMMYFUNCTION("""COMPUTED_VALUE"""),"M. 2445/ SUKADANA HAM") -> M. 2445/ SUKADANA HAM | D34: =IFERROR(__xludf.DUMMYFUNCTION("""COMPUTED_VALUE"""),45579.577937511574) -> 45579.578 | E34: =IFERROR(__xludf.DUMMYFUNCTION("""COMPUTED_VALUE"""),"PTPGT PEMECAHAN") -> PTPGT PEMECAHAN | F34: =IFERROR(__xludf.DUMMYFUNCTION("""COMPUTED_VALUE"""),"GUNAWAN") -> GUNAWAN | G34: =IF(OR(C34="-",C34="",H34<>"P0"),G33,G33+1) -> 26 | H34: =IFERROR(__xludf.DUMMYFUNCTION("""COMPUTED_VALUE"""),"P0") -> P0
B35: =IFERROR(__xludf.DUMMYFUNCTION("""COMPUTED_VALUE"""),"K/30/141024/1") -> K/30/141024/1 | C35: =IFERROR(__xludf.DUMMYFUNCTION("""COMPUTED_VALUE"""),"M.2617/WAY KANDIS") -> M.2617/WAY KANDIS | D35: =IFERROR(__xludf.DUMMYFUNCTION("""COMPUTED_VALUE"""),45579.580212719906) -> 45579.58 | E35: =IFERROR(__xludf.DUMMYFUNCTION("""COMPUTED_VALUE"""),"ROYA") -> ROYA | F35: =IFERROR(__xludf.DUMMYFUNCTION("""COMPUTED_VALUE"""),"SUHARTONO/KRISTINA SIAHAAN") -> SUHARTONO/KRISTINA SIAHAAN | G35: =IF(OR(C35="-",C35="",H35<>"P0"),G34,G34+1) -> 27 | H35: =IFERROR(__xludf.DUMMYFUNCTION("""COMPUTED_VALUE"""),"P0") -> P0
B36: =IFERROR(__xludf.DUMMYFUNCTION("""COMPUTED_VALUE"""),"K/31/141024/1") -> K/31/141024/1 | C36: =IFERROR(__xludf.DUMMYFUNCTION("""COMPUTED_VALUE"""),"NIBEL 1691/ SUKABUMI INDAH") -> NIBEL 1691/ SUKABUMI INDAH | D36: =IFERROR(__xludf.DUMMYFUNCTION("""COMPUTED_VALUE"""),45579.584890625) -> 45579.585 | E36: =IFERROR(__xludf.DUMMYFUNCTION("""COMPUTED_VALUE"""),"PERUBAHAN HAK") -> PERUBAHAN HAK | F36: =IFERROR(__xludf.DUMMYFUNCTION("""COMPUTED_VALUE"""),"APRILLIYANI") -> APRILLIYANI | G36: =IF(OR(C36="-",C36="",H36<>"P0"),G35,G35+1) -> 28 | H36: =IFERROR(__xludf.DUMMYFUNCTION("""COMPUTED_VALUE"""),"P0") -> P0
B37: =IFERROR(__xludf.DUMMYFUNCTION("""COMPUTED_VALUE"""),"L/34/141024/1") -> L/34/141024/1 | C37: =IFERROR(__xludf.DUMMYFUNCTION("""COMPUTED_VALUE"""),"KORPRI JAYA") -> KORPRI JAYA | D37: =IFERROR(__xludf.DUMMYFUNCTION("""COMPUTED_VALUE"""),45579.591902245375) -> 45579.592 | E37: =IFERROR(__xludf.DUMMYFUNCTION("""COMPUTED_VALUE"""),"PERTAMA KALI") -> PERTAMA KALI | F37: =IFERROR(__xludf.DUMMYFUNCTION("""COMPUTED_VALUE"""),"RENNY SILALAHI") -> RENNY SILALAHI | G37: =IF(OR(C37="-",C37="",H37<>"P0"),G36,G36+1) -> 29 | H37: =IFERROR(__xludf.DUMMYFUNCTION("""COMPUTED_VALUE"""),"P0") -> P0
B38: =IFERROR(__xludf.DUMMYFUNCTION("""COMPUTED_VALUE"""),"L/33/141024/1") -> L/33/141024/1 | C38: =IFERROR(__xludf.DUMMYFUNCTION("""COMPUTED_VALUE"""),"M.1540/GUNUNG TERANG;B.17/GU TERANG-DAHULU") -> M.1540/GUNUNG TERANG;B.17/GU TERANG-DAHULU | D38: =IFERROR(__xludf.DUMMYFUNCTION("""COMPUTED_VALUE"""),45579.59196659722) -> 45579.592 | E38: =IFERROR(__xludf.DUMMYFUNCTION("""COMPUTED_VALUE"""),"ROYA") -> ROYA | F38: =IFERROR(__xludf.DUMMYFUNCTION("""COMPUTED_VALUE"""),"MOCHAMAD MA'RUF") -> MOCHAMAD MA'RUF | G38: =IF(OR(C38="-",C38="",H38<>"P0"),G37,G37+1) -> 30 | H38: =IFERROR(__xludf.DUMMYFUNCTION("""COMPUTED_VALUE"""),"P0") -> P0
B39: =IFERROR(__xludf.DUMMYFUNCTION("""COMPUTED_VALUE"""),"K/32/141024/1") -> K/32/141024/1 | C39: =IFERROR(__xludf.DUMMYFUNCTION("""COMPUTED_VALUE"""),"M.10108/LABUHAN RATU") -> M.10108/LABUHAN RATU | D39: =IFERROR(__xludf.DUMMYFUNCTION("""COMPUTED_VALUE"""),45579.59303643518) -> 45579.593 | E39: =IFERROR(__xludf.DUMMYFUNCTION("""COMPUTED_VALUE"""),"GANDES") -> GANDES | F39: =IFERROR(__xludf.DUMMYFUNCTION("""COMPUTED_VALUE"""),"ICHWANTO/BUDI KRISTIYANTO") -> ICHWANTO/BUDI KRISTIYANTO | G39: =IF(OR(C39="-",C39="",H39<>"P0"),G38,G38+1) -> 31 | H39: =IFERROR(__xludf.DUMMYFUNCTION("""COMPUTED_VALUE"""),"P0") -> P0
B40: =IFERROR(__xludf.DUMMYFUNCTION("""COMPUTED_VALUE"""),"L/35/141024/1") -> L/35/141024/1 | C40: =IFERROR(__xludf.DUMMYFUNCTION("""COMPUTED_VALUE"""),"M.676/SAWAH BREBES") -> M.676/SAWAH BREBES | D40: =IFERROR(__xludf.DUMMYFUNCTION("""COMPUTED_VALUE"""),45579.59566706019) -> 45579.596 | E40: =IFERROR(__xludf.DUMMYFUNCTION("""COMPUTED_VALUE"""),"ROYA LELANG") -> ROYA LELANG | F40: =IFERROR(__xludf.DUMMYFUNCTION("""COMPUTED_VALUE"""),"DEBY JULISDA") -> DEBY JULISDA | G40: =IF(OR(C40="-",C40="",H40<>"P0"),G39,G39+1) -> 32 | H40: =IFERROR(__xludf.DUMMYFUNCTION("""COMPUTED_VALUE"""),"P0") -> P0
B41: =IFERROR(__xludf.DUMMYFUNCTION("""COMPUTED_VALUE"""),"K/36/141024/1") -> K/36/141024/1 | C41: =IFERROR(__xludf.DUMMYFUNCTION("""COMPUTED_VALUE"""),"M.250/LANGKAPURA BARU") -> M.250/LANGKAPURA BARU | D41: =IFERROR(__xludf.DUMMYFUNCTION("""COMPUTED_VALUE"""),45579.59832927083) -> 45579.598 | E41: =IFERROR(__xludf.DUMMYFUNCTION("""COMPUTED_VALUE"""),"PERALIHAN JUAL BELI ") -> PERALIHAN JUAL BELI | F41: =IFERROR(__xludf.DUMMYFUNCTION("""COMPUTED_VALUE"""),"YUDA SAPUTRA/I MADE RETUG") -> YUDA SAPUTRA/I MADE RETUG | G41: =IF(OR(C41="-",C41="",H41<>"P0"),G40,G40+1) -> 33 | H41: =IFERROR(__xludf.DUMMYFUNCTION("""COMPUTED_VALUE"""),"P0") -> P0
...

Sheet a 01
A1: https://docs.google.com/spreadsheets/d/1caGeSM59WVEFjQpGbUW7We7Zr97jHfvg94KgbsFlB2I/edit?usp=sharing
B5: No | C5: Nomor Sertipikat | D5: Nomor TIket | E5: Nama Petugas BT | F5: Status BT | G5: Tanggal Selesai Validasi BT | H5: Nama Petugas Validator SU | I5: Status Validasi SU | J5: Tanggal Selesai Validasi SU | K5: Kesimupulan Validator | L5: Tangal BT SU Selesai | M5: Diberikan kepada Petugas Alih Media | N5: DIberikan Kepada Warkah Sementara | O5: Count
B6: =IFERROR(__xludf.DUMMYFUNCTION("IMPORTRANGE($A$1,""Validator!B7:D10000"")"),1.0) -> 1 | C6: =IFERROR(__xludf.DUMMYFUNCTION("""COMPUTED_VALUE"""),"B.895/BERINGIN JAYA") -> B.895/BERINGIN JAYA | D6: =IFERROR(__xludf.DUMMYFUNCTION("""COMPUTED_VALUE"""),"K/28/141024/1") -> K/28/141024/1 | E6: =IFERROR(__xludf.DUMMYFUNCTION("IMPORTRANGE($A$1,""Validator!H7:J10000"")"),"Afriza (BT)") -> Afriza (BT) | F6: =IFERROR(__xludf.DUMMYFUNCTION("""COMPUTED_VALUE"""),"SELESAI") -> SELESAI | G6: =IFERROR(__xludf.DUMMYFUNCTION("""COMPUTED_VALUE"""),45580.70099516204) -> 45580.701 | H6: =IFERROR(__xludf.DUMMYFUNCTION("IMPORTRANGE($A$1,""Validator!K7:O10000"")"),"Aprill (SU)") -> Aprill (SU) | I6: =IFERROR(__xludf.DUMMYFUNCTION("""COMPUTED_VALUE"""),"SELESAI") -> SELESAI | J6: =IFERROR(__xludf.DUMMYFUNCTION("""COMPUTED_VALUE"""),45580.72456549769) -> 45580.725 | K6: =IFERROR(__xludf.DUMMYFUNCTION("""COMPUTED_VALUE"""),"SELESAI") -> SELESAI | L6: =IFERROR(__xludf.DUMMYFUNCTION("""COMPUTED_VALUE"""),45580.72456549769) -> 45580.725 | M6: =IFERROR(__xludf.DUMMYFUNCTION("IMPORTRANGE($A$1,""Validator!Q7:Q1000"")"),"") | N6: =IFERROR(__xludf.DUMMYFUNCTION("IMPORTRANGE($A$1,""Validator!S7:S10000"")"),45581.419803032404) -> 45581.42 | O6: =IF(N6="","",1) -> 1
B7: =IFERROR(__xludf.DUMMYFUNCTION("""COMPUTED_VALUE"""),2.0) -> 2 | C7: =IFERROR(__xludf.DUMMYFUNCTION("""COMPUTED_VALUE"""),"M.11980/JAGABAYA II") -> M.11980/JAGABAYA II | D7: =IFERROR(__xludf.DUMMYFUNCTION("""COMPUTED_VALUE"""),"K/9/141024/1") -> K/9/141024/1 | E7: =IFERROR(__xludf.DUMMYFUNCTION("""COMPUTED_VALUE"""),"Afriza (BT)") -> Afriza (BT) | F7: =IFERROR(__xludf.DUMMYFUNCTION("""COMPUTED_VALUE"""),"SELESAI") -> SELESAI | G7: =IFERROR(__xludf.DUMMYFUNCTION("""COMPUTED_VALUE"""),45580.70099516204) -> 45580.701 | H7: =IFERROR(__xludf.DUMMYFUNCTION("""COMPUTED_VALUE"""),"Aprill (SU)") -> Aprill (SU) | I7: =IFERROR(__xludf.DUMMYFUNCTION("""COMPUTED_VALUE"""),"SELESAI") -> SELESAI | J7: =IFERROR(__xludf.DUMMYFUNCTION("""COMPUTED_VALUE"""),45580.72456756944) -> 45580.725 | K7: =IFERROR(__xludf.DUMMYFUNCTION("""COMPUTED_VALUE"""),"SELESAI") -> SELESAI | L7: =IFERROR(__xludf.DUMMYFUNCTION("""COMPUTED_VALUE"""),45580.72456756944) -> 45580.725 | M7: =IFERROR(__xludf.DUMMYFUNCTION("""COMPUTED_VALUE"""),"") | N7: =IFERROR(__xludf.DUMMYFUNCTION("""COMPUTED_VALUE"""),45581.41975490741) -> 45581.42 | O7: =IF(N7="","",O6+1) -> 2
B8: =IFERROR(__xludf.DUMMYFUNCTION("""COMPUTED_VALUE"""),3.0) -> 3 | C8: =IFERROR(__xludf.DUMMYFUNCTION("""COMPUTED_VALUE"""),"HM 1527/RAJABASA NUNYAI (SUPER PRIORITAS)") -> HM 1527/RAJABASA NUNYAI (SUPER PRIORITAS) | D8: =IFERROR(__xludf.DUMMYFUNCTION("""COMPUTED_VALUE"""),"L/18/151024/1") -> L/18/151024/1 | E8: =IFERROR(__xludf.DUMMYFUNCTION("""COMPUTED_VALUE"""),"Afriza (BT)") -> Afriza (BT) | F8: =IFERROR(__xludf.DUMMYFUNCTION("""COMPUTED_VALUE"""),"SELESAI") -> SELESAI | G8: =IFERROR(__xludf.DUMMYFUNCTION("""COMPUTED_VALUE"""),45581.486162685185) -> 45581.486 | H8: =IFERROR(__xludf.DUMMYFUNCTION("""COMPUTED_VALUE"""),"Aprill (SU)") -> Aprill (SU) | I8: =IFERROR(__xludf.DUMMYFUNCTION("""COMPUTED_VALUE"""),"SELESAI") -> SELESAI | J8: =IFERROR(__xludf.DUMMYFUNCTION("""COMPUTED_VALUE"""),45581.48314606481) -> 45581.483 | K8: =IFERROR(__xludf.DUMMYFUNCTION("""COMPUTED_VALUE"""),"SELESAI") -> SELESAI | L8: =IFERROR(__xludf.DUMMYFUNCTION("""COMPUTED_VALUE"""),45581.48314606481) -> 45581.483 | M8: =IFERROR(__xludf.DUMMYFUNCTION("""COMPUTED_VALUE"""),45581.483226701384) -> 45581.483 | N8: =IFERROR(__xludf.DUMMYFUNCTION("""COMPUTED_VALUE"""),"") | O8: =IF(N8="","",O7+1)
B9: =IFERROR(__xludf.DUMMYFUNCTION("""COMPUTED_VALUE"""),4.0) -> 4 | C9: =IFERROR(__xludf.DUMMYFUNCTION("""COMPUTED_VALUE"""),"HM 4010/TANJUNG SENANG") -> HM 4010/TANJUNG SENANG | D9: =IFERROR(__xludf.DUMMYFUNCTION("""COMPUTED_VALUE"""),"L/43/151024/1") -> L/43/151024/1 | E9: =IFERROR(__xludf.DUMMYFUNCTION("""COMPUTED_VALUE"""),"Afriza (BT)") -> Afriza (BT) | F9: =IFERROR(__xludf.DUMMYFUNCTION("""COMPUTED_VALUE"""),"SELESAI") -> SELESAI | G9: =IFERROR(__xludf.DUMMYFUNCTION("""COMPUTED_VALUE"""),45581.58696482639) -> 45581.587 | H9: =IFERROR(__xludf.DUMMYFUNCTION("""COMPUTED_VALUE"""),"Bu Eva (SU)") -> Bu Eva (SU) | I9: =IFERROR(__xludf.DUMMYFUNCTION("""COMPUTED_VALUE"""),"SELESAI") -> SELESAI | J9: =IFERROR(__xludf.DUMMYFUNCTION("""COMPUTED_VALUE"""),45582.61317506945) -> 45582.613 | K9: =IFERROR(__xludf.DUMMYFUNCTION("""COMPUTED_VALUE"""),"SELESAI") -> SELESAI | L9: =IFERROR(__xludf.DUMMYFUNCTION("""COMPUTED_VALUE"""),45582.61317506945) -> 45582.613 | M9: =IFERROR(__xludf.DUMMYFUNCTION("""COMPUTED_VALUE"""),"") | N9: =IFERROR(__xludf.DUMMYFUNCTION("""COMPUTED_VALUE"""),45582.61317506945) -> 45582.613 | O9: =IF(N9="","",O8+1) -> 1
B10: =IFERROR(__xludf.DUMMYFUNCTION("""COMPUTED_VALUE"""),5.0) -> 5 | C10: =IFERROR(__xludf.DUMMYFUNCTION("""COMPUTED_VALUE"""),"M. 2589/ Kota Baru") -> M. 2589/ Kota Baru | D10: =IFERROR(__xludf.DUMMYFUNCTION("""COMPUTED_VALUE"""),"K/42/151024/3") -> K/42/151024/3 | E10: =IFERROR(__xludf.DUMMYFUNCTION("""COMPUTED_VALUE"""),"Afriza (BT)") -> Afriza (BT) | F10: =IFERROR(__xludf.DUMMYFUNCTION("""COMPUTED_VALUE"""),"SELESAI") -> SELESAI | G10: =IFERROR(__xludf.DUMMYFUNCTION("""COMPUTED_VALUE"""),45581.58894203704) -> 45581.589 | H10: =IFERROR(__xludf.DUMMYFUNCTION("""COMPUTED_VALUE"""),"Bu Eva (SU)") -> Bu Eva (SU) | I10: =IFERROR(__xludf.DUMMYFUNCTION("""COMPUTED_VALUE"""),"SELESAI") -> SELESAI | J10: =IFERROR(__xludf.DUMMYFUNCTION("""COMPUTED_VALUE"""),45582.61317506945) -> 45582.613 | K10: =IFERROR(__xludf.DUMMYFUNCTION("""COMPUTED_VALUE"""),"SELESAI") -> SELESAI | L10: =IFERROR(__xludf.DUMMYFUNCTION("""COMPUTED_VALUE"""),45582.61317506945) -> 45582.613 | M10: =IFERROR(__xludf.DUMMYFUNCTION("""COMPUTED_VALUE"""),"") | N10: =IFERROR(__xludf.DUMMYFUNCTION("""COMPUTED_VALUE"""),45582.61317506945) -> 45582.613 | O10: =IF(N10="","",O9+1) -> 2
B11: =IFERROR(__xludf.DUMMYFUNCTION("""COMPUTED_VALUE"""),6.0) -> 6 | C11: =IFERROR(__xludf.DUMMYFUNCTION("""COMPUTED_VALUE"""),"HM 401/KALI BALAU KENCANA") -> HM 401/KALI BALAU KENCANA | D11: =IFERROR(__xludf.DUMMYFUNCTION("""COMPUTED_VALUE"""),"L/26/151024/1") -> L/26/151024/1 | E11: =IFERROR(__xludf.DUMMYFUNCTION("""COMPUTED_VALUE"""),"Afriza (BT)") -> Afriza (BT) | F11: =IFERROR(__xludf.DUMMYFUNCTION("""COMPUTED_VALUE"""),"SELESAI") -> SELESAI | G11: =IFERROR(__xludf.DUMMYFUNCTION("""COMPUTED_VALUE"""),45581.624271574074) -> 45581.624 | H11: =IFERROR(__xludf.DUMMYFUNCTION("""COMPUTED_VALUE"""),"Bu Eva (SU)") -> Bu Eva (SU) | I11: =IFERROR(__xludf.DUMMYFUNCTION("""COMPUTED_VALUE"""),"SELESAI") -> SELESAI | J11: =IFERROR(__xludf.DUMMYFUNCTION("""COMPUTED_VALUE"""),45594.40356861112) -> 45594.404 | K11: =IFERROR(__xludf.DUMMYFUNCTION("""COMPUTED_VALUE"""),"SELESAI") -> SELESAI | L11: =IFERROR(__xludf.DUMMYFUNCTION("""COMPUTED_VALUE"""),45594.40356861112) -> 45594.404 | M11: =IFERROR(__xludf.DUMMYFUNCTION("""COMPUTED_VALUE"""),"") | N11: =IFERROR(__xludf.DUMMYFUNCTION("""COMPUTED_VALUE"""),"") | O11: =IF(N11="","",O10+1)
B12: =IFERROR(__xludf.DUMMYFUNCTION("""COMPUTED_VALUE"""),7.0) -> 7 | C12: =IFERROR(__xludf.DUMMYFUNCTION("""COMPUTED_VALUE"""),"M. 11294/ Labuhan Ratu") -> M. 11294/ Labuhan Ratu | D12: =IFERROR(__xludf.DUMMYFUNCTION("""COMPUTED_VALUE"""),"K/41/151024/2") -> K/41/151024/2 | E12: =IFERROR(__xludf.DUMMYFUNCTION("""COMPUTED_VALUE"""),"Nadian (BT)") -> Nadian (BT) | F12: =IFERROR(__xludf.DUMMYFUNCTION("""COMPUTED_VALUE"""),"SELESAI") -> SELESAI | G12: =IFERROR(__xludf.DUMMYFUNCTION("""COMPUTED_VALUE"""),45581.64831726852) -> 45581.648 | H12: =IFERROR(__xludf.DUMMYFUNCTION("""COMPUTED_VALUE"""),"Bu Eva (SU)") -> Bu Eva (SU) | I12: =IFERROR(__xludf.DUMMYFUNCTION("""COMPUTED_VALUE"""),"SELESAI") -> SELESAI | J12: =IFERROR(__xludf.DUMMYFUNCTION("""COMPUTED_VALUE"""),45582.61377324074) -> 45582.614 | K12: =IFERROR(__xludf.DUMMYFUNCTION("""COMPUTED_VALUE"""),"SELESAI") -> SELESAI | L12: =IFERROR(__xludf.DUMMYFUNCTION("""COMPUTED_VALUE"""),45582.61377324074) -> 45582.614 | M12: =IFERROR(__xludf.DUMMYFUNCTION("""COMPUTED_VALUE"""),"") | N12: =IFERROR(__xludf.DUMMYFUNCTION("""COMPUTED_VALUE"""),45582.61379209491) -> 45582.614 | O12: =IF(N12="","",O11+1) -> 1
B13: =IFERROR(__xludf.DUMMYFUNCTION("""COMPUTED_VALUE"""),8.0) -> 8 | C13: =IFERROR(__xludf.DUMMYFUNCTION("""COMPUTED_VALUE"""),"M. 288/ Kaliawi") -> M. 288/ Kaliawi | D13: =IFERROR(__xludf.DUMMYFUNCTION("""COMPUTED_VALUE"""),"K/12/151024/2") -> K/12/151024/2 | E13: =IFERROR(__xludf.DUMMYFUNCTION("""COMPUTED_VALUE"""),"Afriza (BT)") -> Afriza (BT) | F13: =IFERROR(__xludf.DUMMYFUNCTION("""COMPUTED_VALUE"""),"SELESAI") -> SELESAI | G13: =IFERROR(__xludf.DUMMYFUNCTION("""COMPUTED_VALUE"""),45582.48802722222) -> 45582.488 | H13: =IFERROR(__xludf.DUMMYFUNCTION("""COMPUTED_VALUE"""),"Bu Eva (SU)") -> Bu Eva (SU) | I13: =IFERROR(__xludf.DUMMYFUNCTION("""COMPUTED_VALUE"""),"SELESAI") -> SELESAI | J13: =IFERROR(__xludf.DUMMYFUNCTION("""COMPUTED_VALUE"""),45587.66803207176) -> 45587.668 | K13: =IFERROR(__xludf.DUMMYFUNCTION("""COMPUTED_VALUE"""),"SELESAI") -> SELESAI | L13: =IFERROR(__xludf.DUMMYFUNCTION("""COMPUTED_VALUE"""),45587.66803207176) -> 45587.668 | M13: =IFERROR(__xludf.DUMMYFUNCTION("""COMPUTED_VALUE"""),"") | N13: =IFERROR(__xludf.DUMMYFUNCTION("""COMPUTED_VALUE"""),45587.66803207176) -> 45587.668 | O13: =IF(N13="","",O12+1) -> 2
B14: =IFERROR(__xludf.DUMMYFUNCTION("""COMPUTED_VALUE"""),9.0) -> 9 | C14: =IFERROR(__xludf.DUMMYFUNCTION("""COMPUTED_VALUE"""),"M. 1186/ Enggal") -> M. 1186/ Enggal | D14: =IFERROR(__xludf.DUMMYFUNCTION("""COMPUTED_VALUE"""),"K/13/161024/1") -> K/13/161024/1 | E14: =IFERROR(__xludf.DUMMYFUNCTION("""COMPUTED_VALUE"""),"Nadian (BT)") -> Nadian (BT) | F14: =IFERROR(__xludf.DUMMYFUNCTION("""COMPUTED_VALUE"""),"SELESAI") -> SELESAI | G14: =IFERROR(__xludf.DUMMYFUNCTION("""COMPUTED_VALUE"""),45582.617769351855) -> 45582.618 | H14: =IFERROR(__xludf.DUMMYFUNCTION("""COMPUTED_VALUE"""),"Bu Eva (SU)") -> Bu Eva (SU) | I14: =IFERROR(__xludf.DUMMYFUNCTION("""COMPUTED_VALUE"""),"SELESAI") -> SELESAI | J14: =IFERROR(__xludf.DUMMYFUNCTION("""COMPUTED_VALUE"""),45583.71007164352) -> 45583.71 | K14: =IFERROR(__xludf.DUMMYFUNCTION("""COMPUTED_VALUE"""),"SELESAI") -> SELESAI | L14: =IFERROR(__xludf.DUMMYFUNCTION("""COMPUTED_VALUE"""),45583.71007164352) -> 45583.71 | M14: =IFERROR(__xludf.DUMMYFUNCTION("""COMPUTED_VALUE"""),"") | N14: =IFERROR(__xludf.DUMMYFUNCTION("""COMPUTED_VALUE"""),45583.7101121875) -> 45583.71 | O14: =IF(N14="","",O13+1) -> 3
B15: =IFERROR(__xludf.DUMMYFUNCTION("""COMPUTED_VALUE"""),10.0) -> 10 | C15: =IFERROR(__xludf.DUMMYFUNCTION("""COMPUTED_VALUE"""),"M.1095/NOG") -> M.1095/NOG | D15: =IFERROR(__xludf.DUMMYFUNCTION("""COMPUTED_VALUE"""),"L/16/161024/1") -> L/16/161024/1 | E15: =IFERROR(__xludf.DUMMYFUNCTION("""COMPUTED_VALUE"""),"Nadian (BT)") -> Nadian (BT) | F15: =IFERROR(__xludf.DUMMYFUNCTION("""COMPUTED_VALUE"""),"SELESAI") -> SELESAI | G15: =IFERROR(__xludf.DUMMYFUNCTION("""COMPUTED_VALUE"""),45582.61887318287) -> 45582.619 | H15: =IFERROR(__xludf.DUMMYFUNCTION("""COMPUTED_VALUE"""),"Bu Eva (SU)") -> Bu Eva (SU) | I15: =IFERROR(__xludf.DUMMYFUNCTION("""COMPUTED_VALUE"""),"SELESAI") -> SELESAI | J15: =IFERROR(__xludf.DUMMYFUNCTION("""COMPUTED_VALUE"""),45583.7103685301) -> 45583.71 | K15: =IFERROR(__xludf.DUMMYFUNCTION("""COMPUTED_VALUE"""),"SELESAI") -> SELESAI | L15: =IFERROR(__xludf.DUMMYFUNCTION("""COMPUTED_VALUE"""),45583.7103685301) -> 45583.71 | M15: =IFERROR(__xludf.DUMMYFUNCTION("""COMPUTED_VALUE"""),"") | N15: =IFERROR(__xludf.DUMMYFUNCTION("""COMPUTED_VALUE"""),"") | O15: =IF(N15="","",O14+1)
B16: =IFERROR(__xludf.DUMMYFUNCTION("""COMPUTED_VALUE"""),11.0) -> 11 | C16: =IFERROR(__xludf.DUMMYFUNCTION("""COMPUTED_VALUE"""),"M.13036/SUKABUMI") -> M.13036/SUKABUMI | D16: =IFERROR(__xludf.DUMMYFUNCTION("""COMPUTED_VALUE"""),"L/6/171024/1") -> L/6/171024/1 | E16: =IFERROR(__xludf.DUMMYFUNCTION("""COMPUTED_VALUE"""),"Nadian (BT)") -> Nadian (BT) | F16: =IFERROR(__xludf.DUMMYFUNCTION("""COMPUTED_VALUE"""),"SELESAI") -> SELESAI | G16: =IFERROR(__xludf.DUMMYFUNCTION("""COMPUTED_VALUE"""),45582.689037777775) -> 45582.689 | H16: =IFERROR(__xludf.DUMMYFUNCTION("""COMPUTED_VALUE"""),"Bu Eva (SU)") -> Bu Eva (SU) | I16: =IFERROR(__xludf.DUMMYFUNCTION("""COMPUTED_VALUE"""),"SELESAI") -> SELESAI | J16: =IFERROR(__xludf.DUMMYFUNCTION("""COMPUTED_VALUE"""),45583.7100703125) -> 45583.71 | K16: =IFERROR(__xludf.DUMMYFUNCTION("""COMPUTED_VALUE"""),"SELESAI") -> SELESAI | L16: =IFERROR(__xludf.DUMMYFUNCTION("""COMPUTED_VALUE"""),45583.7100703125) -> 45583.71 | M16: =IFERROR(__xludf.DUMMYFUNCTION("""COMPUTED_VALUE"""),"") | N16: =IFERROR(__xludf.DUMMYFUNCTION("""COMPUTED_VALUE"""),45583.7100703125) -> 45583.71 | O16: =IF(N16="","",O15+1) -> 1
B17: =IFERROR(__xludf.DUMMYFUNCTION("""COMPUTED_VALUE"""),12.0) -> 12 | C17: =IFERROR(__xludf.DUMMYFUNCTION("""COMPUTED_VALUE"""),"HGB 416/WAY KANDIS") -> HGB 416/WAY KANDIS | D17: =IFERROR(__xludf.DUMMYFUNCTION("""COMPUTED_VALUE"""),"L/11/171024/1") -> L/11/171024/1 | E17: =IFERROR(__xludf.DUMMYFUNCTION("""COMPUTED_VALUE"""),"Nadian (BT)") -> Nadian (BT) | F17: =IFERROR(__xludf.DUMMYFUNCTION("""COMPUTED_VALUE"""),"SELESAI") -> SELESAI | G17: =IFERROR(__xludf.DUMMYFUNCTION("""COMPUTED_VALUE"""),45582.68917092592) -> 45582.689 | H17: =IFERROR(__xludf.DUMMYFUNCTION("""COMPUTED_VALUE"""),"Bu Eva (SU)") -> Bu Eva (SU) | I17: =IFERROR(__xludf.DUMMYFUNCTION("""COMPUTED_VALUE"""),"SELESAI") -> SELESAI | J17: =IFERROR(__xludf.DUMMYFUNCTION("""COMPUTED_VALUE"""),45583.7100703125) -> 45583.71 | K17: =IFERROR(__xludf.DUMMYFUNCTION("""COMPUTED_VALUE"""),"SELESAI") -> SELESAI | L17: =IFERROR(__xludf.DUMMYFUNCTION("""COMPUTED_VALUE"""),45583.7100703125) -> 45583.71 | M17: =IFERROR(__xludf.DUMMYFUNCTION("""COMPUTED_VALUE"""),"") | N17: =IFERROR(__xludf.DUMMYFUNCTION("""COMPUTED_VALUE"""),45583.7100703125) -> 45583.71 | O17: =IF(N17="","",O16+1) -> 2
B18: =IFERROR(__xludf.DUMMYFUNCTION("""COMPUTED_VALUE"""),13.0) -> 13 | C18: =IFERROR(__xludf.DUMMYFUNCTION("""COMPUTED_VALUE"""),"M. 2465/ Pinang jaya") -> M. 2465/ Pinang jaya | D18: =IFERROR(__xludf.DUMMYFUNCTION("""COMPUTED_VALUE"""),"K/14/171024/5") -> K/14/171024/5 | E18: =IFERROR(__xludf.DUMMYFUNCTION("""COMPUTED_VALUE"""),"Nadian (BT)") -> Nadian (BT) | F18: =IFERROR(__xludf.DUMMYFUNCTION("""COMPUTED_VALUE"""),"SELESAI") -> SELESAI | G18: =IFERROR(__xludf.DUMMYFUNCTION("""COMPUTED_VALUE"""),45582.68930762731) -> 45582.689 | H18: =IFERROR(__xludf.DUMMYFUNCTION("""COMPUTED_VALUE"""),"Bu Eva (SU)") -> Bu Eva (SU) | I18: =IFERROR(__xludf.DUMMYFUNCTION("""COMPUTED_VALUE"""),"SELESAI") -> SELESAI | J18: =IFERROR(__xludf.DUMMYFUNCTION("""COMPUTED_VALUE"""),45594.40396957176) -> 45594.404 | K18: =IFERROR(__xludf.DUMMYFUNCTION("""COMPUTED_VALUE"""),"SELESAI") -> SELESAI | L18: =IFERROR(__xludf.DUMMYFUNCTION("""COMPUTED_VALUE"""),45594.40396957176) -> 45594.404 | M18: =IFERROR(__xludf.DUMMYFUNCTION("""COMPUTED_VALUE"""),"") | N18: =IFERROR(__xludf.DUMMYFUNCTION("""COMPUTED_VALUE"""),"") | O18: =IF(N18="","",O17+1)
B19: =IFERROR(__xludf.DUMMYFUNCTION("""COMPUTED_VALUE"""),14.0) -> 14 | C19: =IFERROR(__xludf.DUMMYFUNCTION("""COMPUTED_VALUE"""),"M.1552/PESAWAHAN") -> M.1552/PESAWAHAN | D19: =IFERROR(__xludf.DUMMYFUNCTION("""COMPUTED_VALUE"""),"K/34/181024/2") -> K/34/181024/2 | E19: =IFERROR(__xludf.DUMMYFUNCTION("""COMPUTED_VALUE"""),"Afriza (BT)") -> Afriza (BT) | F19: =IFERROR(__xludf.DUMMYFUNCTION("""COMPUTED_VALUE"""),"SELESAI") -> SELESAI | G19: =IFERROR(__xludf.DUMMYFUNCTION("""COMPUTED_VALUE"""),45586.59689925926) -> 45586.597 | H19: =IFERROR(__xludf.DUMMYFUNCTION("""COMPUTED_VALUE"""),"Bu Eva (SU)") -> Bu Eva (SU) | I19: =IFERROR(__xludf.DUMMYFUNCTION("""COMPUTED_VALUE"""),"SELESAI") -> SELESAI | J19: =IFERROR(__xludf.DUMMYFUNCTION("""COMPUTED_VALUE"""),45587.691420138886) -> 45587.691 | K19: =IFERROR(__xludf.DUMMYFUNCTION("""COMPUTED_VALUE"""),"SELESAI") -> SELESAI | L19: =IFERROR(__xludf.DUMMYFUNCTION("""COMPUTED_VALUE"""),45587.691420138886) -> 45587.691 | M19: =IFERROR(__xludf.DUMMYFUNCTION("""COMPUTED_VALUE"""),"") | N19: =IFERROR(__xludf.DUMMYFUNCTION("""COMPUTED_VALUE"""),45587.69146971065) -> 45587.691 | O19: =IF(N19="","",O18+1) -> 1
B20: =IFERROR(__xludf.DUMMYFUNCTION("""COMPUTED_VALUE"""),15.0) -> 15 | C20: =IFERROR(__xludf.DUMMYFUNCTION("""COMPUTED_VALUE"""),"B. 653; 654/ Pesawahan dan SHT 1213/2008 dan SHT 3013/2006") -> B. 653; 654/ Pesawahan dan SHT 1213/2008 dan SHT 3013/2006 | D20: =IFERROR(__xludf.DUMMYFUNCTION("""COMPUTED_VALUE"""),"K/6/181024/1") -> K/6/181024/1 | E20: =IFERROR(__xludf.DUMMYFUNCTION("""COMPUTED_VALUE"""),"Afriza (BT)") -> Afriza (BT) | F20: =IFERROR(__xludf.DUMMYFUNCTION("""COMPUTED_VALUE"""),"SELESAI") -> SELESAI | G20: =IFERROR(__xludf.DUMMYFUNCTION("""COMPUTED_VALUE"""),45586.60736440972) -> 45586.607 | H20: =IFERROR(__xludf.DUMMYFUNCTION("""COMPUTED_VALUE"""),"Bu Eva (SU)") -> Bu Eva (SU) | I20: =IFERROR(__xludf.DUMMYFUNCTION("""COMPUTED_VALUE"""),"SELESAI") -> SELESAI | J20: =IFERROR(__xludf.DUMMYFUNCTION("""COMPUTED_VALUE"""),45587.69120581019) -> 45587.691 | K20: =IFERROR(__xludf.DUMMYFUNCTION("""COMPUTED_VALUE"""),"SELESAI") -> SELESAI | L20: =IFERROR(__xludf.DUMMYFUNCTION("""COMPUTED_VALUE"""),45587.69120581019) -> 45587.691 | M20: =IFERROR(__xludf.DUMMYFUNCTION("""COMPUTED_VALUE"""),"") | N20: =IFERROR(__xludf.DUMMYFUNCTION("""COMPUTED_VALUE"""),45587.691239884254) -> 45587.691 | O20: =IF(N20="","",O19+1) -> 2
B21: =IFERROR(__xludf.DUMMYFUNCTION("""COMPUTED_VALUE"""),16.0) -> 16 | C21: =IFERROR(__xludf.DUMMYFUNCTION("""COMPUTED_VALUE"""),"HM 1375/TANJUNG SENENG") -> HM 1375/TANJUNG SENENG | D21: =IFERROR(__xludf.DUMMYFUNCTION("""COMPUTED_VALUE"""),"L/40/171024/1") -> L/40/171024/1 | E21: =IFERROR(__xludf.DUMMYFUNCTION("""COMPUTED_VALUE"""),"Nadian (BT)") -> Nadian (BT) | F21: =IFERROR(__xludf.DUMMYFUNCTION("""COMPUTED_VALUE"""),"SELESAI") -> SELESAI | G21: =IFERROR(__xludf.DUMMYFUNCTION("""COMPUTED_VALUE"""),45586.63063859954) -> 45586.631 | H21: =IFERROR(__xludf.DUMMYFUNCTION("""COMPUTED_VALUE"""),"Bu Eva (SU)") -> Bu Eva (SU) | I21: =IFERROR(__xludf.DUMMYFUNCTION("""COMPUTED_VALUE"""),"SELESAI") -> SELESAI | J21: =IFERROR(__xludf.DUMMYFUNCTION("""COMPUTED_VALUE"""),45587.66803209491) -> 45587.668 | K21: =IFERROR(__xludf.DUMMYFUNCTION("""COMPUTED_VALUE"""),"SELESAI") -> SELESAI | L21: =IFERROR(__xludf.DUMMYFUNCTION("""COMPUTED_VALUE"""),45587.66803209491) -> 45587.668 | M21: =IFERROR(__xludf.DUMMYFUNCTION("""COMPUTED_VALUE"""),"") | N21: =IFERROR(__xludf.DUMMYFUNCTION("""COMPUTED_VALUE"""),45587.66803209491) -> 45587.668 | O21: =IF(N21="","",O20+1) -> 3
B22: =IFERROR(__xludf.DUMMYFUNCTION("""COMPUTED_VALUE"""),17.0) -> 17 | C22: =IFERROR(__xludf.DUMMYFUNCTION("""COMPUTED_VALUE"""),"HM 16138/SUKARAME I") -> HM 16138/SUKARAME I | D22: =IFERROR(__xludf.DUMMYFUNCTION("""COMPUTED_VALUE"""),"L/44/171024/1") -> L/44/171024/1 | E22: =IFERROR(__xludf.DUMMYFUNCTION("""COMPUTED_VALUE"""),"Nadian (BT)") -> Nadian (BT) | F22: =IFERROR(__xludf.DUMMYFUNCTION("""COMPUTED_VALUE"""),"SELESAI") -> SELESAI | G22: =IFERROR(__xludf.DUMMYFUNCTION("""COMPUTED_VALUE"""),45586.63057144676) -> 45586.631 | H22: =IFERROR(__xludf.DUMMYFUNCTION("""COMPUTED_VALUE"""),"Bu Eva (SU)") -> Bu Eva (SU) | I22: =IFERROR(__xludf.DUMMYFUNCTION("""COMPUTED_VALUE"""),"SELESAI") -> SELESAI | J22: =IFERROR(__xludf.DUMMYFUNCTION("""COMPUTED_VALUE"""),45587.66803209491) -> 45587.668 | K22: =IFERROR(__xludf.DUMMYFUNCTION("""COMPUTED_VALUE"""),"SELESAI") -> SELESAI | L22: =IFERROR(__xludf.DUMMYFUNCTION("""COMPUTED_VALUE"""),45587.66803209491) -> 45587.668 | M22: =IFERROR(__xludf.DUMMYFUNCTION("""COMPUTED_VALUE"""),"") | N22: =IFERROR(__xludf.DUMMYFUNCTION("""COMPUTED_VALUE"""),45587.66803209491) -> 45587.668 | O22: =IF(N22="","",O21+1) -> 4
B23: =IFERROR(__xludf.DUMMYFUNCTION("""COMPUTED_VALUE"""),18.0) -> 18 | C23: =IFERROR(__xludf.DUMMYFUNCTION("""COMPUTED_VALUE"""),"M. 377/ ENGGAL") -> M. 377/ ENGGAL | D23: =IFERROR(__xludf.DUMMYFUNCTION("""COMPUTED_VALUE"""),"K/56/171024/1") -> K/56/171024/1 | E23: =IFERROR(__xludf.DUMMYFUNCTION("""COMPUTED_VALUE"""),"Nadian (BT)") -> Nadian (BT) | F23: =IFERROR(__xludf.DUMMYFUNCTION("""COMPUTED_VALUE"""),"SELESAI") -> SELESAI | G23: =IFERROR(__xludf.DUMMYFUNCTION("""COMPUTED_VALUE"""),45586.630507650465) -> 45586.631 | H23: =IFERROR(__xludf.DUMMYFUNCTION("""COMPUTED_VALUE"""),"Bu Eva (SU)") -> Bu Eva (SU) | I23: =IFERROR(__xludf.DUMMYFUNCTION("""COMPUTED_VALUE"""),"SELESAI") -> SELESAI | J23: =IFERROR(__xludf.DUMMYFUNCTION("""COMPUTED_VALUE"""),45587.66803209491) -> 45587.668 | K23: =IFERROR(__xludf.DUMMYFUNCTION("""COMPUTED_VALUE"""),"SELESAI") -> SELESAI | L23: =IFERROR(__xludf.DUMMYFUNCTION("""COMPUTED_VALUE"""),45587.66803209491) -> 45587.668 | M23: =IFERROR(__xludf.DUMMYFUNCTION("""COMPUTED_VALUE"""),"") | N23: =IFERROR(__xludf.DUMMYFUNCTION("""COMPUTED_VALUE"""),45587.66803210648) -> 45587.668 | O23: =IF(N23="","",O22+1) -> 5
B24: =IFERROR(__xludf.DUMMYFUNCTION("""COMPUTED_VALUE"""),19.0) -> 19 | C24: =IFERROR(__xludf.DUMMYFUNCTION("""COMPUTED_VALUE"""),"B. 649/ Sumber Agung") -> B. 649/ Sumber Agung | D24: =IFERROR(__xludf.DUMMYFUNCTION("""COMPUTED_VALUE"""),"K/42/171024/1") -> K/42/171024/1 | E24: =IFERROR(__xludf.DUMMYFUNCTION("""COMPUTED_VALUE"""),"Nadian (BT)") -> Nadian (BT) | F24: =IFERROR(__xludf.DUMMYFUNCTION("""COMPUTED_VALUE"""),"SELESAI") -> SELESAI | G24: =IFERROR(__xludf.DUMMYFUNCTION("""COMPUTED_VALUE"""),45586.63040666666) -> 45586.63 | H24: =IFERROR(__xludf.DUMMYFUNCTION("""COMPUTED_VALUE"""),"Bu Eva (SU)") -> Bu Eva (SU) | I24: =IFERROR(__xludf.DUMMYFUNCTION("""COMPUTED_VALUE"""),"SELESAI") -> SELESAI | J24: =IFERROR(__xludf.DUMMYFUNCTION("""COMPUTED_VALUE"""),45587.66803210648) -> 45587.668 | K24: =IFERROR(__xludf.DUMMYFUNCTION("""COMPUTED_VALUE"""),"SELESAI") -> SELESAI | L24: =IFERROR(__xludf.DUMMYFUNCTION("""COMPUTED_VALUE"""),45587.66803210648) -> 45587.668 | M24: =IFERROR(__xludf.DUMMYFUNCTION("""COMPUTED_VALUE"""),"") | N24: =IFERROR(__xludf.DUMMYFUNCTION("""COMPUTED_VALUE"""),45587.66803210648) -> 45587.668 | O24: =IF(N24="","",O23+1) -> 6
B25: =IFERROR(__xludf.DUMMYFUNCTION("""COMPUTED_VALUE"""),20.0) -> 20 | C25: =IFERROR(__xludf.DUMMYFUNCTION("""COMPUTED_VALUE"""),"HM 296/RAJABASA RAYA") -> HM 296/RAJABASA RAYA | D25: =IFERROR(__xludf.DUMMYFUNCTION("""COMPUTED_VALUE"""),"L/35/171024/1") -> L/35/171024/1 | E25: =IFERROR(__xludf.DUMMYFUNCTION("""COMPUTED_VALUE"""),"Nadian (BT)") -> Nadian (BT) | F25: =IFERROR(__xludf.DUMMYFUNCTION("""COMPUTED_VALUE"""),"SELESAI") -> SELESAI | G25: =IFERROR(__xludf.DUMMYFUNCTION("""COMPUTED_VALUE"""),45586.6303046875) -> 45586.63 | H25: =IFERROR(__xludf.DUMMYFUNCTION("""COMPUTED_VALUE"""),"Bu Eva (SU)") -> Bu Eva (SU) | I25: =IFERROR(__xludf.DUMMYFUNCTION("""COMPUTED_VALUE"""),"SELESAI") -> SELESAI | J25: =IFERROR(__xludf.DUMMYFUNCTION("""COMPUTED_VALUE"""),45587.66803210648) -> 45587.668 | K25: =IFERROR(__xludf.DUMMYFUNCTION("""COMPUTED_VALUE"""),"SELESAI") -> SELESAI | L25: =IFERROR(__xludf.DUMMYFUNCTION("""COMPUTED_VALUE"""),45587.66803210648) -> 45587.668 | M25: =IFERROR(__xludf.DUMMYFUNCTION("""COMPUTED_VALUE"""),"") | N25: =IFERROR(__xludf.DUMMYFUNCTION("""COMPUTED_VALUE"""),45587.66803210648) -> 45587.668 | O25: =IF(N25="","",O24+1) -> 7
B26: =IFERROR(__xludf.DUMMYFUNCTION("""COMPUTED_VALUE"""),21.0) -> 21 | C26: =IFERROR(__xludf.DUMMYFUNCTION("""COMPUTED_VALUE"""),"M.13833/RAJABASA") -> M.13833/RAJABASA | D26: =IFERROR(__xludf.DUMMYFUNCTION("""COMPUTED_VALUE"""),"L/57/181024/1") -> L/57/181024/1 | E26: =IFERROR(__xludf.DUMMYFUNCTION("""COMPUTED_VALUE"""),"Afriza (BT)") -> Afriza (BT) | F26: =IFERROR(__xludf.DUMMYFUNCTION("""COMPUTED_VALUE"""),"SELESAI") -> SELESAI | G26: =IFERROR(__xludf.DUMMYFUNCTION("""COMPUTED_VALUE"""),45587.48331087963) -> 45587.483 | H26: =IFERROR(__xludf.DUMMYFUNCTION("""COMPUTED_VALUE"""),"Bu Eva (SU)") -> Bu Eva (SU) | I26: =IFERROR(__xludf.DUMMYFUNCTION("""COMPUTED_VALUE"""),"SELESAI") -> SELESAI | J26: =IFERROR(__xludf.DUMMYFUNCTION("""COMPUTED_VALUE"""),45587.69071259259) -> 45587.691 | K26: =IFERROR(__xludf.DUMMYFUNCTION("""COMPUTED_VALUE"""),"SELESAI") -> SELESAI | L26: =IFERROR(__xludf.DUMMYFUNCTION("""COMPUTED_VALUE"""),45587.69071259259) -> 45587.691 | M26: =IFERROR(__xludf.DUMMYFUNCTION("""COMPUTED_VALUE"""),"") | N26: =IFERROR(__xludf.DUMMYFUNCTION("""COMPUTED_VALUE"""),45587.69077752315) -> 45587.691 | O26: =IF(N26="","",O25+1) -> 8
B27: =IFERROR(__xludf.DUMMYFUNCTION("""COMPUTED_VALUE"""),22.0) -> 22 | C27: =IFERROR(__xludf.DUMMYFUNCTION("""COMPUTED_VALUE"""),"M.598/GUNUNG TERANG") -> M.598/GUNUNG TERANG | D27: =IFERROR(__xludf.DUMMYFUNCTION("""COMPUTED_VALUE"""),"K/46/181024/2") -> K/46/181024/2 | E27: =IFERROR(__xludf.DUMMYFUNCTION("""COMPUTED_VALUE"""),"Afriza (BT)") -> Afriza (BT) | F27: =IFERROR(__xludf.DUMMYFUNCTION("""COMPUTED_VALUE"""),"SELESAI") -> SELESAI | G27: =IFERROR(__xludf.DUMMYFUNCTION("""COMPUTED_VALUE"""),45587.66803210648) -> 45587.668 | H27: =IFERROR(__xludf.DUMMYFUNCTION("""COMPUTED_VALUE"""),"Aprill (SU)") -> Aprill (SU) | I27: =IFERROR(__xludf.DUMMYFUNCTION("""COMPUTED_VALUE"""),"SELESAI") -> SELESAI | J27: =IFERROR(__xludf.DUMMYFUNCTION("""COMPUTED_VALUE"""),45588.39084087963) -> 45588.391 | K27: =IFERROR(__xludf.DUMMYFUNCTION("""COMPUTED_VALUE"""),"SELESAI") -> SELESAI | L27: =IFERROR(__xludf.DUMMYFUNCTION("""COMPUTED_VALUE"""),45588.39084087963) -> 45588.391 | M27: =IFERROR(__xludf.DUMMYFUNCTION("""COMPUTED_VALUE"""),"") | N27: =IFERROR(__xludf.DUMMYFUNCTION("""COMPUTED_VALUE"""),45588.39087440972) -> 45588.391 | O27: =IF(N27="","",O26+1) -> 9
B28: =IFERROR(__xludf.DUMMYFUNCTION("""COMPUTED_VALUE"""),23.0) -> 23 | C28: =IFERROR(__xludf.DUMMYFUNCTION("""COMPUTED_VALUE"""),"M.2473/RAJABASA JAYA") -> M.2473/RAJABASA JAYA | D28: =IFERROR(__xludf.DUMMYFUNCTION("""COMPUTED_VALUE"""),"K/45/181024/1") -> K/45/181024/1 | E28: =IFERROR(__xludf.DUMMYFUNCTION("""COMPUTED_VALUE"""),"Afriza (BT)") -> Afriza (BT) | F28: =IFERROR(__xludf.DUMMYFUNCTION("""COMPUTED_VALUE"""),"SELESAI") -> SELESAI | G28: =IFERROR(__xludf.DUMMYFUNCTION("""COMPUTED_VALUE"""),45587.668032118054) -> 45587.668 | H28: =IFERROR(__xludf.DUMMYFUNCTION("""COMPUTED_VALUE"""),"Bu Eva (SU)") -> Bu Eva (SU) | I28: =IFERROR(__xludf.DUMMYFUNCTION("""COMPUTED_VALUE"""),"SELESAI") -> SELESAI | J28: =IFERROR(__xludf.DUMMYFUNCTION("""COMPUTED_VALUE"""),45587.68955173611) -> 45587.69 | K28: =IFERROR(__xludf.DUMMYFUNCTION("""COMPUTED_VALUE"""),"SELESAI") -> SELESAI | L28: =IFERROR(__xludf.DUMMYFUNCTION("""COMPUTED_VALUE"""),45587.68955173611) -> 45587.69 | M28: =IFERROR(__xludf.DUMMYFUNCTION("""COMPUTED_VALUE"""),"") | N28: =IFERROR(__xludf.DUMMYFUNCTION("""COMPUTED_VALUE"""),45587.689599108795) -> 45587.69 | O28: =IF(N28="","",O27+1) -> 10
B29: =IFERROR(__xludf.DUMMYFUNCTION("""COMPUTED_VALUE"""),24.0) -> 24 | C29: =IFERROR(__xludf.DUMMYFUNCTION("""COMPUTED_VALUE"""),"HM 180/PINANG JAYA") -> HM 180/PINANG JAYA | D29: =IFERROR(__xludf.DUMMYFUNCTION("""COMPUTED_VALUE"""),"L/33/211024/1") -> L/33/211024/1 | E29: =IFERROR(__xludf.DUMMYFUNCTION("""COMPUTED_VALUE"""),"Nadian (BT)") -> Nadian (BT) | F29: =IFERROR(__xludf.DUMMYFUNCTION("""COMPUTED_VALUE"""),"SELESAI") -> SELESAI | G29: =IFERROR(__xludf.DUMMYFUNCTION("""COMPUTED_VALUE"""),45587.689260520834) -> 45587.689 | H29: =IFERROR(__xludf.DUMMYFUNCTION("""COMPUTED_VALUE"""),"Bu Eva (SU)") -> Bu Eva (SU) | I29: =IFERROR(__xludf.DUMMYFUNCTION("""COMPUTED_VALUE"""),"SELESAI") -> SELESAI | J29: =IFERROR(__xludf.DUMMYFUNCTION("""COMPUTED_VALUE"""),45588.46065230324) -> 45588.461 | K29: =IFERROR(__xludf.DUMMYFUNCTION("""COMPUTED_VALUE"""),"SELESAI") -> SELESAI | L29: =IFERROR(__xludf.DUMMYFUNCTION("""COMPUTED_VALUE"""),45588.46065230324) -> 45588.461 | M29: =IFERROR(__xludf.DUMMYFUNCTION("""COMPUTED_VALUE"""),"") | N29: =IFERROR(__xludf.DUMMYFUNCTION("""COMPUTED_VALUE"""),45588.46068664352) -> 45588.461 | O29: =IF(N29="","",O28+1) -> 11
B30: =IFERROR(__xludf.DUMMYFUNCTION("""COMPUTED_VALUE"""),25.0) -> 25 | C30: =IFERROR(__xludf.DUMMYFUNCTION("""COMPUTED_VALUE"""),"HM 2414/KUPANG TEBA") -> HM 2414/KUPANG TEBA | D30: =IFERROR(__xludf.DUMMYFUNCTION("""COMPUTED_VALUE"""),"L/28/211024/1") -> L/28/211024/1 | E30: =IFERROR(__xludf.DUMMYFUNCTION("""COMPUTED_VALUE"""),"Nadian (BT)") -> Nadian (BT) | F30: =IFERROR(__xludf.DUMMYFUNCTION("""COMPUTED_VALUE"""),"SELESAI") -> SELESAI | G30: =IFERROR(__xludf.DUMMYFUNCTION("""COMPUTED_VALUE"""),45587.68946028935) -> 45587.689 | H30: =IFERROR(__xludf.DUMMYFUNCTION("""COMPUTED_VALUE"""),"Bu Eva (SU)") -> Bu Eva (SU) | I30: =IFERROR(__xludf.DUMMYFUNCTION("""COMPUTED_VALUE"""),"SELESAI") -> SELESAI | J30: =IFERROR(__xludf.DUMMYFUNCTION("""COMPUTED_VALUE"""),45588.46035569445) -> 45588.46 | K30: =IFERROR(__xludf.DUMMYFUNCTION("""COMPUTED_VALUE"""),"SELESAI") -> SELESAI | L30: =IFERROR(__xludf.DUMMYFUNCTION("""COMPUTED_VALUE"""),45588.46035569445) -> 45588.46 | M30: =IFERROR(__xludf.DUMMYFUNCTION("""COMPUTED_VALUE"""),"") | N30: =IFERROR(__xludf.DUMMYFUNCTION("""COMPUTED_VALUE"""),45588.46038564815) -> 45588.46 | O30: =IF(N30="","",O29+1) -> 12
B31: =IFERROR(__xludf.DUMMYFUNCTION("""COMPUTED_VALUE"""),26.0) -> 26 | C31: =IFERROR(__xludf.DUMMYFUNCTION("""COMPUTED_VALUE"""),"M. 467/ Sumur Putri") -> M. 467/ Sumur Putri | D31: =IFERROR(__xludf.DUMMYFUNCTION("""COMPUTED_VALUE"""),"K/16/211024/2") -> K/16/211024/2 | E31: =IFERROR(__xludf.DUMMYFUNCTION("""COMPUTED_VALUE"""),"Nadian (BT)") -> Nadian (BT) | F31: =IFERROR(__xludf.DUMMYFUNCTION("""COMPUTED_VALUE"""),"SELESAI") -> SELESAI | G31: =IFERROR(__xludf.DUMMYFUNCTION("""COMPUTED_VALUE"""),45587.689651215274) -> 45587.69 | H31: =IFERROR(__xludf.DUMMYFUNCTION("""COMPUTED_VALUE"""),"Aprill (SU)") -> Aprill (SU) | I31: =IFERROR(__xludf.DUMMYFUNCTION("""COMPUTED_VALUE"""),"SELESAI") -> SELESAI | J31: =IFERROR(__xludf.DUMMYFUNCTION("""COMPUTED_VALUE"""),45588.46004950232) -> 45588.46 | K31: =IFERROR(__xludf.DUMMYFUNCTION("""COMPUTED_VALUE"""),"SELESAI") -> SELESAI | L31: =IFERROR(__xludf.DUMMYFUNCTION("""COMPUTED_VALUE"""),45588.46004950232) -> 45588.46 | M31: =IFERROR(__xludf.DUMMYFUNCTION("""COMPUTED_VALUE"""),"") | N31: =IFERROR(__xludf.DUMMYFUNCTION("""COMPUTED_VALUE"""),45588.46010527777) -> 45588.46 | O31: =IF(N31="","",O30+1) -> 13
B32: =IFERROR(__xludf.DUMMYFUNCTION("""COMPUTED_VALUE"""),27.0) -> 27 | C32: =IFERROR(__xludf.DUMMYFUNCTION("""COMPUTED_VALUE"""),"M.2704/SUKARAME BARU-SEKARANG;B.986/SUKARAME -DAHULU") -> M.2704/SUKARAME BARU-SEKARANG;B.986/SUKARAME -DAHULU | D32: =IFERROR(__xludf.DUMMYFUNCTION("""COMPUTED_VALUE"""),"K/47/211024/1") -> K/47/211024/1 | E32: =IFERROR(__xludf.DUMMYFUNCTION("""COMPUTED_VALUE"""),"Nadian (BT)") -> Nadian (BT) | F32: =IFERROR(__xludf.DUMMYFUNCTION("""COMPUTED_VALUE"""),"SELESAI") -> SELESAI | G32: =IFERROR(__xludf.DUMMYFUNCTION("""COMPUTED_VALUE"""),45587.68979775463) -> 45587.69 | H32: =IFERROR(__xludf.DUMMYFUNCTION("""COMPUTED_VALUE"""),"Bu Eva (SU)") -> Bu Eva (SU) | I32: =IFERROR(__xludf.DUMMYFUNCTION("""COMPUTED_VALUE"""),"SELESAI") -> SELESAI | J32: =IFERROR(__xludf.DUMMYFUNCTION("""COMPUTED_VALUE"""),45588.46085725694) -> 45588.461 | K32: =IFERROR(__xludf.DUMMYFUNCTION("""COMPUTED_VALUE"""),"SELESAI") -> SELESAI | L32: =IFERROR(__xludf.DUMMYFUNCTION("""COMPUTED_VALUE"""),45588.46085725694) -> 45588.461 | M32: =IFERROR(__xludf.DUMMYFUNCTION("""COMPUTED_VALUE"""),"") | N32: =IFERROR(__xludf.DUMMYFUNCTION("""COMPUTED_VALUE"""),45588.46089155093) -> 45588.461 | O32: =IF(N32="","",O31+1) -> 14
B33: =IFERROR(__xludf.DUMMYFUNCTION("""COMPUTED_VALUE"""),28.0) -> 28 | C33: =IFERROR(__xludf.DUMMYFUNCTION("""COMPUTED_VALUE"""),"HM 101/KEMILING RAYA") -> HM 101/KEMILING RAYA | D33: =IFERROR(__xludf.DUMMYFUNCTION("""COMPUTED_VALUE"""),"L/40/211024/1") -> L/40/211024/1 | E33: =IFERROR(__xludf.DUMMYFUNCTION("""COMPUTED_VALUE"""),"Nadian (BT)") -> Nadian (BT) | F33: =IFERROR(__xludf.DUMMYFUNCTION("""COMPUTED_VALUE"""),"SELESAI") -> SELESAI | G33: =IFERROR(__xludf.DUMMYFUNCTION("""COMPUTED_VALUE"""),45587.69007590278) -> 45587.69 | H33: =IFERROR(__xludf.DUMMYFUNCTION("""COMPUTED_VALUE"""),"Bu Eva (SU)") -> Bu Eva (SU) | I33: =IFERROR(__xludf.DUMMYFUNCTION("""COMPUTED_VALUE"""),"SELESAI") -> SELESAI | J33: =IFERROR(__xludf.DUMMYFUNCTION("""COMPUTED_VALUE"""),45588.461573078705) -> 45588.462 | K33: =IFERROR(__xludf.DUMMYFUNCTION("""COMPUTED_VALUE"""),"SELESAI") -> SELESAI | L33: =IFERROR(__xludf.DUMMYFUNCTION("""COMPUTED_VALUE"""),45588.461573078705) -> 45588.462 | M33: =IFERROR(__xludf.DUMMYFUNCTION("""COMPUTED_VALUE"""),"") | N33: =IFERROR(__xludf.DUMMYFUNCTION("""COMPUTED_VALUE"""),45588.46159810185) -> 45588.462 | O33: =IF(N33="","",O32+1) -> 15
B34: =IFERROR(__xludf.DUMMYFUNCTION("""COMPUTED_VALUE"""),29.0) -> 29 | C34: =IFERROR(__xludf.DUMMYFUNCTION("""COMPUTED_VALUE"""),"HGB 3764/BERINGIN RAYA") -> HGB 3764/BERINGIN RAYA | D34: =IFERROR(__xludf.DUMMYFUNCTION("""COMPUTED_VALUE"""),"L/23/211024/1") -> L/23/211024/1 | E34: =IFERROR(__xludf.DUMMYFUNCTION("""COMPUTED_VALUE"""),"Nadian (BT)") -> Nadian (BT) | F34: =IFERROR(__xludf.DUMMYFUNCTION("""COMPUTED_VALUE"""),"SELESAI") -> SELESAI | G34: =IFERROR(__xludf.DUMMYFUNCTION("""COMPUTED_VALUE"""),45587.690326724536) -> 45587.69 | H34: =IFERROR(__xludf.DUMMYFUNCTION("""COMPUTED_VALUE"""),"Aprill (SU)") -> Aprill (SU) | I34: =IFERROR(__xludf.DUMMYFUNCTION("""COMPUTED_VALUE"""),"SELESAI") -> SELESAI | J34: =IFERROR(__xludf.DUMMYFUNCTION("""COMPUTED_VALUE"""),45588.45916158565) -> 45588.459 | K34: =IFERROR(__xludf.DUMMYFUNCTION("""COMPUTED_VALUE"""),"SELESAI") -> SELESAI | L34: =IFERROR(__xludf.DUMMYFUNCTION("""COMPUTED_VALUE"""),45588.45916158565) -> 45588.459 | M34: =IFERROR(__xludf.DUMMYFUNCTION("""COMPUTED_VALUE"""),"") | N34: =IFERROR(__xludf.DUMMYFUNCTION("""COMPUTED_VALUE"""),45588.45919435185) -> 45588.459 | O34: =IF(N34="","",O33+1) -> 16
B35: =IFERROR(__xludf.DUMMYFUNCTION("""COMPUTED_VALUE"""),30.0) -> 30 | C35: =IFERROR(__xludf.DUMMYFUNCTION("""COMPUTED_VALUE"""),"M. 240/ Kemiling Permai") -> M. 240/ Kemiling Permai | D35: =IFERROR(__xludf.DUMMYFUNCTION("""COMPUTED_VALUE"""),"K/48/211024/1") -> K/48/211024/1 | E35: =IFERROR(__xludf.DUMMYFUNCTION("""COMPUTED_VALUE"""),"Nadian (BT)") -> Nadian (BT) | F35: =IFERROR(__xludf.DUMMYFUNCTION("""COMPUTED_VALUE"""),"SELESAI") -> SELESAI | G35: =IFERROR(__xludf.DUMMYFUNCTION("""COMPUTED_VALUE"""),45587.690614861116) -> 45587.691 | H35: =IFERROR(__xludf.DUMMYFUNCTION("""COMPUTED_VALUE"""),"Bu Eva (SU)") -> Bu Eva (SU) | I35: =IFERROR(__xludf.DUMMYFUNCTION("""COMPUTED_VALUE"""),"SELESAI") -> SELESAI | J35: =IFERROR(__xludf.DUMMYFUNCTION("""COMPUTED_VALUE"""),45588.46133453704) -> 45588.461 | K35: =IFERROR(__xludf.DUMMYFUNCTION("""COMPUTED_VALUE"""),"SELESAI") -> SELESAI | L35: =IFERROR(__xludf.DUMMYFUNCTION("""COMPUTED_VALUE"""),45588.46133453704) -> 45588.461 | M35: =IFERROR(__xludf.DUMMYFUNCTION("""COMPUTED_VALUE"""),"") | N35: =IFERROR(__xludf.DUMMYFUNCTION("""COMPUTED_VALUE"""),45588.46139483796) -> 45588.461 | O35: =IF(N35="","",O34+1) -> 17
B36: =IFERROR(__xludf.DUMMYFUNCTION("""COMPUTED_VALUE"""),31.0) -> 31 | C36: =IFERROR(__xludf.DUMMYFUNCTION("""COMPUTED_VALUE"""),"HM 15995/SUKARAME I") -> HM 15995/SUKARAME I | D36: =IFERROR(__xludf.DUMMYFUNCTION("""COMPUTED_VALUE"""),"L/8/211024/1") -> L/8/211024/1 | E36: =IFERROR(__xludf.DUMMYFUNCTION("""COMPUTED_VALUE"""),"Afriza (BT)") -> Afriza (BT) | F36: =IFERROR(__xludf.DUMMYFUNCTION("""COMPUTED_VALUE"""),"SELESAI") -> SELESAI | G36: =IFERROR(__xludf.DUMMYFUNCTION("""COMPUTED_VALUE"""),45587.74088471065) -> 45587.741 | H36: =IFERROR(__xludf.DUMMYFUNCTION("""COMPUTED_VALUE"""),"Bu Eva (SU)") -> Bu Eva (SU) | I36: =IFERROR(__xludf.DUMMYFUNCTION("""COMPUTED_VALUE"""),"SELESAI") -> SELESAI | J36: =IFERROR(__xludf.DUMMYFUNCTION("""COMPUTED_VALUE"""),45588.61665216435) -> 45588.617 | K36: =IFERROR(__xludf.DUMMYFUNCTION("""COMPUTED_VALUE"""),"SELESAI") -> SELESAI | L36: =IFERROR(__xludf.DUMMYFUNCTION("""COMPUTED_VALUE"""),45588.61665216435) -> 45588.617 | M36: =IFERROR(__xludf.DUMMYFUNCTION("""COMPUTED_VALUE"""),"") | N36: =IFERROR(__xludf.DUMMYFUNCTION("""COMPUTED_VALUE"""),45588.61670496528) -> 45588.617 | O36: =IF(N36="","",O35+1) -> 18
