Workbook

Sheet Sheet6
A1: . | B1: .
A2: K/13/141024/2 | B2: Ada di Dashboard | D2: K/13/141024/2 | E2: =VLOOKUP(D2,$A$2:$B$1353,2,0) -> Ada di Dashboard | H2: K/41/251124/1-P0
A3: L/18/141024/1 | B3: Ada di Dashboard | D3: L/18/141024/1 | E3: =VLOOKUP(D3,$A$2:$B$1353,2,0) -> Ada di Dashboard | H3: K/13/141024/2-P0
A4: K/28/141024/1 | B4: Ada di Dashboard | D4: K/28/141024/1 | E4: =VLOOKUP(D4,$A$2:$B$1353,2,0) -> Ada di Dashboard | H4: L/18/141024/1-P0
A5: L/34/141024/1 | B5: Ada di Dashboard | D5: L/34/141024/1 | E5: =VLOOKUP(D5,$A$2:$B$1353,2,0) -> Ada di Dashboard | H5: K/28/141024/1-P0
A6: L/10/151024/1 | B6: Ada di Dashboard | D6: L/10/151024/1 | E6: =VLOOKUP(D6,$A$2:$B$1353,2,0) -> Ada di Dashboard | H6: L/34/141024/1-P0
A7: K/12/151024/2 | B7: Ada di Dashboard | D7: K/12/151024/2 | E7: =VLOOKUP(D7,$A$2:$B$1353,2,0) -> Ada di Dashboard | H7: L/10/151024/1-P0
A8: L/18/151024/1 | B8: Ada di Dashboard | D8: L/18/151024/1 | E8: =VLOOKUP(D8,$A$2:$B$1353,2,0) -> Ada di Dashboard | H8: K/12/151024/2-P0
A9: L/20/151024/1 | B9: Ada di Dashboard | D9: L/20/151024/1 | E9: =VLOOKUP(D9,$A$2:$B$1353,2,0) -> Ada di Dashboard | H9: L/18/151024/1-P0
A10: K/21/151024/1 | B10: Ada di Dashboard | D10: K/21/151024/1 | E10: =VLOOKUP(D10,$A$2:$B$1353,2,0) -> Ada di Dashboard | H10: L/20/151024/1-P0
A11: L/26/151024/1 | B11: Ada di Dashboard | D11: L/26/151024/1 | E11: =VLOOKUP(D11,$A$2:$B$1353,2,0) -> Ada di Dashboard | H11: K/21/151024/1-P0
A12: K/36/151024/1 | B12: Ada di Dashboard | D12: K/36/151024/1 | E12: =VLOOKUP(D12,$A$2:$B$1353,2,0) -> Ada di Dashboard | H12: L/26/151024/1-P0
A13: L/35/151024/1 | B13: Ada di Dashboard | D13: L/35/151024/1 | E13: =VLOOKUP(D13,$A$2:$B$1353,2,0) -> Ada di Dashboard | H13: K/36/151024/1-P0
... A1276: K/16/301224/1 | B1276: Ada di Dashboard | D1276: K/41/311224/1 | E1276: =VLOOKUP(D1276,$A$2:$B$1353,2,0) -> Ada di Dashboard | H1276: K/25/131224/2-P1
A1277: K/18/301225/1 | B1277: Ada di Dashboard | H1277: K/14/301225/1-P0
A1278: K/19/301225/1 | B1278: Ada di Dashboard | H1278: K/15/301225/1-P0
A1279: K/20/301225/1 | B1279: Ada di Dashboard | H1279: L/17/301225/1-P0
A1280: K/21/301225/1 | B1280: Ada di Dashboard | H1280: K/16/301224/1-P0
A1281: K/22/301225/2 | B1281: Ada di Dashboard | H1281: K/18/301225/1-P0
A1282: L/23/301225/1 | B1282: Ada di Dashboard | H1282: K/19/301225/1-P0
A1283: K/24/301224/1 | B1283: Ada di Dashboard | H1283: K/20/301225/1-P0
A1284: K/25/301224/1 | B1284: Ada di Dashboard | H1284: K/21/301225/1-P0
A1285: K/26/301224/2 | B1285: Ada di Dashboard | H1285: K/22/301225/2-P0
A1286: K/27/301224/3 | B1286: Ada di Dashboard | H1286: L/23/301225/1-P0
A1287: K/28/301224/4 | B1287: Ada di Dashboard | H1287: K/24/301224/1-P0
A1288: K/29/301224/1 | B1288: Ada di Dashboard | H1288: K/25/301224/1-P0
... A1353: K/41/311224/1 | B1353: Ada di Dashboard | H1353: K/37/311224/1-P0
H1354: K/40/311224/1-P0
H1355: K/38/311224/2-P0
H1356: K/39/311224/3-P0
H1357: K/41/311224/1-P0

Sheet Dashboard
A1: No | B1: Kode Tiket | C1: Tanggal Permohonan Masuk | D1: Nama Pemohon | E1: Nomor Hak | F1: Jenis Permohonan | G1: Nama Petugas Loket | H1: Verifikator Start Date | I1: Verifikator End Date | J1: Nama Petugas | K1: Kesimpulan Verifikator | L1: Warkah Start Date | M1: Warkah End Date | N1: Nama Petugas | O1: Kesimpulan Warkah | P1: Validator Start Date | Q1: Validator End Date | R1: Kesimpulan Validator | S1: Alih Media Start Date | T1: Alih Media End Date | U1: Kesimpulan Alih Media | V1: SPS Loket
A2: 13 | B2: K/13/141024/2 | C2: 45579.448 | D2: APRILIA/PANARY SITOPU | E2: M.1088/NEGERI OLOK GADING-SEKARANG;B.1201/NEGERI OLOK GADING-DAHULU | F2: ROYA | G2: Baynur | H2: 45580 | I2: 45580 | J2: Maharani | K2: SELESAI (LENGKAP) | O2: DISERAHKAN | P2: 45579 | Q2: 45580 | R2: SELESAI | V2: BELUM SPS
A3: 19 | B3: L/18/141024/1 | C3: 45579.484 | D3: SUNILA HAKI | E3: M.331/NUSANTARA PERMAI;B.389/CAMPANG RAYA-DAHULU | F3: BLOKIR | G3: Nuraini | H3: 45580 | I3: 45580 | J3: Fikka | K3: SELESAI (LENGKAP) | O3: DISERAHKAN | V3: BELUM SPS
A4: 28 | B4: K/28/141024/1 | C4: 45579.573 | D4: ADE HERDIANYAH/WHINDA YULIANTI | E4: B.895/BERINGIN JAYA | F4: PERALIHAN JUAL BELI | G4: Baynur | H4: 45580 | I4: 45580 | J4: Kholfa | K4: SELESAI (LENGKAP) | O4: DISERAHKAN | P4: 45579 | Q4: 45580 | R4: SELESAI | S4: 45581.42 | T4: 45594 | U4: SELESAI | V4: BELUM SPS
A5: 32 | B5: L/34/141024/1 | C5: 45579.592 | D5: RENNY SILALAHI | E5: KORPRI JAYA | F5: PERTAMA KALI | G5: Deby | H5: 45607 | I5: 45607 | J5: Zevina | K5: PERBAIKAN | V5: BELUM SPS
A6: 56 | B6: L/10/151024/1 | C6: 45580.422 | D6: AHMAD SUKRI | E6: B.561/NUSANTARA PERMAI;B.329/CAMPANG RAYA-DAHULU | F6: PERUBAHAN HAK | G6: Nuraini | H6: 45580 | I6: 45581 | J6: Kholfa | K6: SELESAI (LENGKAP) | O6: DISERAHKAN | P6: 45580 | Q6: 45580 | R6: SELESAI | S6: 45581.419 | U6: BT atau SU Belum Alih Media | V6: BELUM SPS
A7: 58 | B7: K/12/151024/2 | C7: 45580.426 | D7: Maryanti K/ Joko Setiawan | E7: M. 288/ Kaliawi | F7: BN Jual Beli | G7: Rapita | H7: 45580 | I7: 45581 | J7: Maharani | K7: SELESAI (LENGKAP) | O7: DISERAHKAN | P7: 45587 | Q7: 45587 | R7: SELESAI | S7: 45587.668 | U7: BT atau SU Belum Alih Media | V7: BELUM SPS
A8: 63 | B8: L/18/151024/1 | C8: 45580.443 | D8: ABU BAKAR | E8: HM 1527/RAJABASA NUNYAI (SUPER PRIORITAS) | F8: BN JUAL BELI | G8: Deby | O8: DISERAHKAN | P8: 45581 | Q8: 45581 | R8: SELESAI | V8: BELUM SPS
A9: 65 | B9: L/20/151024/1 | C9: 45580.455 | D9: BUDY RAHARJO | E9: NIB 0801000023950/SUKARAME | F9: GANTI NAMA | G9: Deby | H9: 45580 | I9: 45582 | J9: Maharani | K9: SELESAI (LENGKAP) | V9: BELUM SPS
A10: 67 | B10: K/21/151024/1 | C10: 45580.473 | D10: RAHMADIYANTI / SORAYA SOPHA | E10: M. 652/ PINANG JAYA | F10: BN JUAL BELI | G10: Hananda | H10: 45587 | I10: 45593 | J10: Ginta Monita | K10: SELESAI (LENGKAP) | O10: PROSES | Q10: 45594 | R10: Selesai | U10: BT atau SU Belum Alih Media | V10: BELUM SPS
A11: 69 | B11: L/26/151024/1 | C11: 45580.474 | D11: MUHAMMAD ROCYCH | E11: HM 401/KALI BALAU KENCANA | F11: ROYA | G11: Deby | H11: 45580 | I11: 45581 | J11: Fikka | K11: PERBAIKAN | O11: DISERAHKAN | P11: 45581 | Q11: 45594 | R11: SELESAI | V11: BELUM SPS
A12: 80 | B12: K/36/151024/1 | C12: 45580.582 | D12: LINA YOSEPA/HERIYANSYAH | E12: M.4791/BERINGIN RAYA-SEKARANG;B.1135/SUMBERREJO-DAHULU | F12: PERALIHAN LELANG | G12: Baynur | H12: 45586 | I12: 45586 | J12: Ginta Monita | K12: SELESAI (LENGKAP) | O12: PROSES | Q12: 45593 | R12: Selesai | U12: BT atau SU Belum Alih Media | V12: BELUM SPS
A13: 83 | B13: L/35/151024/1 | C13: 45580.585 | D13: FIRMANSYAH/CS | E13: HM 479/HARAPAN JAYA (DAHULU)-HM 49/KORPRI JAYA (SEKARANG) | F13: BN PUTUSAN PENGADILAN (AHLI WARIS) | G13: Deby | H13: 45580 | I13: 45581 | J13: Kholfa | K13: PERBAIKAN | O13: DISERAHKAN | P13: 45581 | Q13: 45582 | R13: SELESAI | V13: BELUM SPS
A14: 87 | B14: L/43/151024/1 | C14: 45580.592 | D14: SEPTA RENI | E14: HM 4010/TANJUNG SENANG | F14: ROYA | G14: Deby | H14: 45587 | I14: 45587 | J14: Ginta Monita | K14: SELESAI (LENGKAP) | O14: DISERAHKAN | P14: 45581 | Q14: 45582 | R14: SELESAI | V14: BELUM SPS
A15: 88 | B15: K/41/151024/2 | C15: 45580.594 | D15: Fahrul Rozi/Novarida | E15: M. 11294/ Labuhan Ratu | F15: BN Jual Beli | G15: Rapita | H15: 45580 | I15: 45617 | J15: Maharani | K15: SELESAI (LENGKAP) | O15: DISERAHKAN | P15: 45581 | Q15: 45582 | R15: SELESAI | S15: 45582.614 | U15: BT atau SU Belum Alih Media | V15: BELUM SPS
A16: 90 | B16: K/42/151024/3 | C16: 45580.597 | D16: Fahrul Rozi/ Winarni | E16: M. 2589/ Kota Baru | F16: BN Kewarisan | G16: Rapita | H16: 45580 | I16: 45610 | J16: Ila Nofri | K16: SELESAI (LENGKAP) | O16: DISERAHKAN | P16: 45581 | Q16: 45582 | R16: SELESAI | S16: 45582.613 | U16: BT atau SU Belum Alih Media | V16: BELUM SPS
A17: 93 | B17: L/49/151024/1 | C17: 45580.609 | D17: SOENANTO | E17: B.238/BERINGIN RAYA;B.238/BERINGIN JAYA-DAHULU | F17: PERUBAHAN HAK | G17: Nuraini | H17: 45587 | I17: 45587 | J17: Ginta Monita | K17: SELESAI (LENGKAP) | O17: DISERAHKAN | P17: 45581 | Q17: 45582 | R17: SELESAI | S17: 45582.615 | T17: 45650 | U17: SELESAI | V17: BELUM SPS
A18: 103 | B18: K/59/151024/1 | C18: 45580.647 | D18: IRMA SILVIA/ I MADE RETUG | E18: B.522/BERINGIN JAYA | F18: PERALIHAN JUAL BELI | G18: Baynur | H18: 45580 | I18: 45582 | J18: Maharani | K18: PERBAIKAN | O18: DISERAHKAN | V18: BELUM SPS
A19: 107 | B19: L/4/161024/1 | C19: 45581.4 | D19: HELDAYANI CS | E19: B.3464/SUKABUMI | F19: PENGUKURAN UNTUK PEMBAHARUAN SERTIPIKAT | G19: Nuraini | H19: 45590 | I19: 45597 | J19: Fikka | K19: SELESAI (LENGKAP) | V19: BELUM SPS
A20: 115 | B20: K/12/161024/3 | C20: 45581.437 | D20: CHRISTYNA BELLY/PANARY SITOPU | E20: B.545/GUNUNG SULAH | F20: PERALIHAN JUAL BELI | G20: Baynur | H20: 45583 | I20: 45607 | J20: Ila Nofri | K20: SELESAI (LENGKAP) | O20: PROSES | Q20: 45609 | R20: Selesai | U20: BT atau SU Belum Alih Media | V20: BELUM SPS
A21: 116 | B21: K/13/161024/1 | C21: 45581.438 | D21: A. Roswantama/ Mardi | E21: M. 1186/ Enggal | F21: BN Jual Beli | G21: Rapita | H21: 45583 | I21: 45587 | J21: Maharani | K21: PERBAIKAN | O21: DISERAHKAN | P21: 45582 | Q21: 45583 | R21: SELESAI | V21: BELUM SPS
A22: 119 | B22: L/16/161024/1 | C22: 45581.45 | D22: LILY KURNIATI | E22: M.1095/NOG | F22: ROYA | G22: Nuraini | H22: 45583 | I22: 45589 | J22: Ila Nofri | K22: SELESAI (LENGKAP) | O22: DISERAHKAN | P22: 45582 | Q22: 45583 | R22: SELESAI | U22: BT atau SU Belum Alih Media | V22: BELUM SPS
A23: 126 | B23: L/26/161024/1 | C23: 45581.57 | D23: FACHRUDDIN | E23: - | F23: ASPEK | G23: Deby | V23: BELUM SPS
A24: 127 | B24: K/25/161024/1 | C24: 45581.571 | D24: Asmara/Samah | E24: M. 1443/ Batu Putuk | F24: Hapus BPHTB | G24: Rapita | V24: BELUM SPS
A25: 129 | B25: K/27/161024/1 | C25: 45581.58 | D25: Fahrul Rozi/ Kevin A S P | E25: M. 12564/ Rajabasa Nunyai; 1137/ Rajabasa Dahulu | F25: BN Jual Beli | G25: Rapita | H25: 45583 | I25: 45590 | J25: Maharani | K25: SELESAI (LENGKAP) | O25: DISERAHKAN | P25: 45601 | Q25: 45596 | R25: Selesai | U25: BT atau SU Belum Alih Media | V25: BELUM SPS
A26: 138 | B26: K/30/161024/1 | C26: 45581.603 | D26: Atiansya Febra/ Candra Putra | E26: M. 4485/ Beringin Raya; B. 1808/ Beringin Raya | F26: BN Jual Beli | G26: Rapita | H26: 45586 | I26: 45593 | J26: Ginta Monita | K26: SELESAI (LENGKAP) | O26: DISERAHKAN BT | P26: 45608 | Q26: 45602 | R26: Selesai | U26: BT atau SU Belum Alih Media | V26: BELUM SPS
A27: 140 | B27: K/38/161024/1 | C27: 45581.61 | D27: Chandra Alam/ Heri S. cs | E27: M. 2904/ Gedong Air | F27: Hapus BPHTB | G27: Rapita | V27: BELUM SPS
A28: 148 | B28: L/6/171024/1 | C28: 45582.424 | D28: GUSMAYANTI | E28: M.13036/SUKABUMI | F28: ROYA | G28: Nuraini | H28: 45583 | I28: 45589 | J28: Ila Nofri | K28: SELESAI (LENGKAP) | O28: DISERAHKAN | P28: 45582 | Q28: 45583 | R28: SELESAI | S28: 45583.71 | T28: 45597 | U28: SELESAI | V28: BELUM SPS
A29: 153 | B29: L/11/171024/1 | C29: 45582.459 | D29: SYAMSUARDI | E29: HGB 416/WAY KANDIS | F29: ROYA | G29: Deby | H29: 45583 | I29: 45597 | J29: Maharani | K29: SELESAI (LENGKAP) | O29: DISERAHKAN | P29: 45582 | Q29: 45583 | R29: SELESAI | V29: BELUM SPS
A30: 154 | B30: K/12/171024/3 | C30: 45582.46 | D30: eka sari taherah/m azmi | E30: M. 243/ Pinang Jaya | F30: BN Jual beli | G30: Hananda | H30: 45586 | I30: 45586 | J30: Ginta Monita | K30: SELESAI (LENGKAP) | O30: DISERAHKAN | P30: 45582 | Q30: 45587 | R30: SELESAI | S30: 45587.668 | U30: BT atau SU Belum Alih Media | V30: BELUM SPS
A31: 156 | B31: K/14/171024/5 | C31: 45582.467 | D31: eka sari taherah/ yayan kesuma | E31: M. 2465/ Pinang jaya | F31: BN Jual Beli | G31: Hananda | H31: 45583 | I31: 45610 | J31: Ila Nofri | K31: SELESAI (LENGKAP) | O31: DISERAHKAN | P31: 45582 | Q31: 45594 | R31: SELESAI | U31: BT atau SU Belum Alih Media | V31: BELUM SPS
A32: 176 | B32: L/35/171024/1 | C32: 45582.578 | D32: SUSYANA | E32: HM 296/RAJABASA RAYA | F32: ROYA | G32: Deby | H32: 45586 | I32: 45586 | J32: Ginta Monita | K32: SELESAI (LENGKAP) | O32: DISERAHKAN | P32: 45586 | Q32: 45587 | R32: SELESAI | S32: 45587.668 | T32: 45594 | U32: SELESAI | V32: BELUM SPS
A33: 182 | B33: L/40/171024/1 | C33: 45582.593 | D33: ACENG SOLEHUDIN | E33: HM 1375/TANJUNG SENENG | F33: ROYA | G33: Deby | H33: 45583 | I33: 45583 | J33: Fikka | K33: SELESAI (LENGKAP) | O33: DISERAHKAN | P33: 45586 | Q33: 45587 | R33: SELESAI | S33: 45587.668 | T33: 45595 | U33: SELESAI | V33: BELUM SPS
A34: 184 | B34: K/42/171024/1 | C34: 45582.597 | D34: endang aprilia/okta kaisar saputra | E34: B. 649/ Sumber Agung | F34: BN Jual Beli | G34: Hananda | H34: 45583 | I34: 45607 | J34: Ila Nofri | K34: SELESAI (LENGKAP) | O34: DISERAHKAN | P34: 45586 | Q34: 45587 | R34: SELESAI | S34: 45587.668 | U34: BT atau SU Belum Alih Media | V34: BELUM SPS
A35: 186 | B35: L/44/171024/1 | C35: 45582.602 | D35: MAYLINA | E35: HM 16138/SUKARAME I | F35: ROYA | G35: Deby | H35: 45587 | I35: 45587 | J35: Kholfa | K35: SELESAI (LENGKAP) | O35: DISERAHKAN | P35: 45586 | Q35: 45587 | R35: SELESAI | S35: 45587.668 | T35: 45595 | U35: SELESAI | V35: BELUM SPS
A36: 197 | B36: K/56/171024/1 | C36: 45582.655 | D36: RIKA WISANGRATRI/ JULIUS BUTAR BUTAR | E36: M. 377/ ENGGAL | F36: ROYA | G36: Hananda | H36: 45583 | I36: 45583 | J36: Fikka | K36: SELESAI (LENGKAP) | O36: DISERAHKAN | P36: 45586 | Q36: 45587 | R36: SELESAI | S36: 45587.668 | U36: BT atau SU Belum Alih Media | V36: BELUM SPS
A37: 198 | B37: L/57/181024/1 | C37: 45583.397 | D37: MUJAMIL | E37: M.13833/RAJABASA | F37: ROYA | G37: Nuraini | H37: 45589 | I37: 45589 | J37: Ila Nofri | K37: SELESAI (LENGKAP) | O37: DISERAHKAN | P37: 45586 | Q37: 45587 | R37: SELESAI | S37: 45587.691 | T37: 45601 | U37: SELESAI | V37: BELUM SPS
A38: 205 | B38: K/6/181024/1 | C38: 45583.438 | D38: Afrizal/ Welly H | E38: B. 653; 654/ Pesawahan dan SHT 1213/2008 dan SHT 3013/2006 | F38: Roya | G38: Rapita | H38: 45583 | I38: 45592 | J38: Maharani | K38: SELESAI (LENGKAP) | O38: DISERAHKAN | P38: 45586 | Q38: 45587 | R38: SELESAI | S38: 45587.691 | U38: BT atau SU Belum Alih Media | V38: BELUM SPS
A39: 208 | B39: L/10/181024/1 | C39: 45583.449 | D39: HAPPY JOY PW SIREGAR | E39: HGB.4629/BERINGIN RAYA | F39: SERTIPIKAT HILANG | G39: Nuraini | H39: 45581 | I39: 45609 | J39: Ila Nofri | K39: SELESAI (LENGKAP) | O39: DISERAHKAN | P39: 45588 | Q39: 45594 | R39: SELESAI | V39: BELUM SPS
A40: 209 | B40: K/11/181024/1 | C40: 45583.451 | D40: DRS.M NADJIB RIPHAT/DRA HJ MASDALIZA JN | E40: M.1637/BUMI KEDAMAIAN-SEKARANG;M.13670/KEDAMAIAN-DAHULU | F40: PEMECAHAN | G40: Baynur | H40: 45587 | I40: 45595 | J40: Ila Nofri | K40: PERBAIKAN | O40: PROSES | Q40: 45597 | R40: Selesai | U40: BT atau SU Belum Alih Media | V40: BELUM SPS
...

Sheet Sheet1

Sheet Verifikator
A1: Nomor Tiket | B1: Tanggal Pemohonan Masuk | C1: Combine | D1: Nama Pemohon | E1: Nomor Telpon | F1: Jenis Permohonan | G1: Nomor Hak | H1: Kelurahan | I1: Nama Petugas Loket | J1: Nama Verifikator | K1: Tanggal Terima Berkas (Verifikator) | L1: Catatan 1 | M1: Catatan 2 | N1: Catatan 3 | O1: Catatan 4 | P1: Catatan 5 | Q1: Catatan 6 | R1: Catatan 7 | S1: Catatan 8 | T1: Catatan 9 | U1: Catatan 10 | V1: Status Berkas | W1: Tanggal Selesai Verifikasi | X1: cek hapus
A2: L/17/141024/1 | B2: 45579.478 | C2: L/17/141024/1_45579.4777229977 | D2: SARIFUDDIN HUTAGALUNG | E2: 81369303456 | F2: ROYA | G2: HM 2144/WAY KANDIS | H2: WAY KANDIS | I2: Deby | J2: Fikka | K2: 45579.712 | L2: PLOTING + VALBID | M2: BEDA NAMA PEMILIK ANTARA SERTIPIKAT DAN KTP | V2: SELESAI (LENGKAP) | W2: 45615.673 | X2: =_xlfn.IFNA(VLOOKUP(A2,Dashboard!$B$2:$V$1276,21,0),"HAPUS") -> HAPUS
A3: K/41/141024/1 | B3: 45579.616 | C3: K/41/141024/1_45579.6163003704 | D3: RAHMADIYANTI | E3: 82182090051 | F3: ROYA | G3: M. 2283/ GEDONG AIR | H3: GEDONG AIR | I3: Hananda | J3: Ila Nofri | K3: 45579.712 | L3: Validator (Tanggal lahir berbeda pada sertipikat dan kkp) (15-10-2024) | V3: SELESAI (LENGKAP) | W3: 45580.626 | X3: =_xlfn.IFNA(VLOOKUP(A3,Dashboard!$B$2:$V$1276,21,0),"HAPUS") -> HAPUS
A4: K/9/141024/1 | B4: 45579.424 | C4: K/9/141024/1_45579.4239733565 | D4: LEOSA AUGDETA/LINGGA AYU B | E4: 82175944544 | F4: ROYA | G4: M.11980/JAGABAYA II | H4: JAGABAYA II | I4: Baynur | J4: Ila Nofri | K4: 45579.712 | L4: Validasi bidang /TT (15-10-2024) | M4: Legalisir KTP kreditur | V4: PERBAIKAN | W4: 45580.583 | X4: =_xlfn.IFNA(VLOOKUP(A4,Dashboard!$B$2:$V$1276,21,0),"HAPUS") -> HAPUS
A5: K/30/141024/1 | B5: 45579.58 | C5: K/30/141024/1_45579.5802127199 | D5: SUHARTONO/KRISTINA SIAHAAN | E5: 85359481748 | F5: ROYA | G5: M.2617/WAY KANDIS | H5: WAY KANDIS | I5: Baynur | J5: Ila Nofri | L5: ACC TGL 22-10-2024 | V5: SELESAI (LENGKAP) | W5: 45583.598 | X5: =_xlfn.IFNA(VLOOKUP(A5,Dashboard!$B$2:$V$1276,21,0),"HAPUS") -> HAPUS
A6: L/8/141024/1 | B6: 45579.416 | C6: L/8/141024/1_45579.4161745139 | D6: JUNAIDI | E6: 82377111476 | F6: HAPUS BPHTB | G6: M.1134/GULAK GALIK | H6: GULAK GALIK | I6: Nuraini | J6: Ila Nofri | K6: 45579.712 | L6: ACC TGL15-10-2024 | V6: SELESAI (LENGKAP) | W6: 45580.617 | X6: =_xlfn.IFNA(VLOOKUP(A6,Dashboard!$B$2:$V$1276,21,0),"HAPUS") -> HAPUS
A7: K/36/141024/1 | B7: 45579.598 | C7: K/36/141024/1_45579.5983292708 | D7: YUDA SAPUTRA/I MADE RETUG | E7: 0853-8479-7293 | F7: PERALIHAN JUAL BELI | G7: M.250/LANGKAPURA BARU | H7: LANGKAPURA BARU | I7: Baynur | J7: Ila Nofri | K7: 45579.713 | L7: Lampirkan fotokopi KTP penerima kuasa (15-10-2024) | M7: Tanda tangan pembeli berbeda pada KTP, akta, surat kuasa, surat pernyataan | N7: PERBAIKAN | V7: SELESAI (LENGKAP) | W7: 45621.399 | X7: =_xlfn.IFNA(VLOOKUP(A7,Dashboard!$B$2:$V$1276,21,0),"HAPUS") -> HAPUS
A8: K/22/141024/1 | B8: 45579.497 | C8: K/22/141024/1_45579.4967951736 | D8: MURSALIN | E8: 85383885939 | F8: PERALIHAN JUAL BELI | G8: M. 6977/ TANJUNG SENANG | H8: TANJUNG SENANG | I8: Hananda | J8: Ila Nofri | K8: 45579.713 | L8: Lampirkan PJB No.3 tgl. 2-8-2024 (15-10-2024) | M8: Kalimat penutup akta agar dilengkapi | N8: Lampirkan bukti Bayar BPHTB yang terbaca | O8: Nama pembeli pada SP BPHTB M. Ismunadi | P8: Nama pembeli pada SP keterlambatan pendaftaran yusuf hasyim | Q8: acc | V8: SELESAI (LENGKAP) | W8: 45589.42 | X8: =_xlfn.IFNA(VLOOKUP(A8,Dashboard!$B$2:$V$1276,21,0),"HAPUS") -> HAPUS
A9: L/21/141024/1 | B9: 45579.493 | C9: L/21/141024/1_45579.4926688773 | D9: DWI ASTANTO | E9: 81369408334 | F9: ROYA | G9: HM 1812/TANJUNG SENANG | H9: TANJUNG SENANG | I9: Deby | J9: Ginta Monita | K9: 45580.372 | V9: SELESAI (LENGKAP) | W9: 45580.433 | X9: =_xlfn.IFNA(VLOOKUP(A9,Dashboard!$B$2:$V$1276,21,0),"HAPUS") -> HAPUS
A10: L/2/141024/1 | C10: L/2/141024/1_ | J10: Ginta Monita | K10: 45580.373 | V10: SELESAI (LENGKAP) | W10: 45580.426 | X10: =_xlfn.IFNA(VLOOKUP(A10,Dashboard!$B$2:$V$1276,21,0),"HAPUS") -> HAPUS
A11: L/35/141024/1 | B11: 45579.596 | C11: L/35/141024/1_45579.5956670602 | D11: DEBY JULISDA | E11: 88276777557 | F11: ROYA LELANG | G11: M.676/SAWAH BREBES | H11: SAWAH BREBES | I11: Nuraini | J11: Ginta Monita | K11: 45580.374 | V11: SELESAI (LENGKAP) | W11: 45580.437 | X11: =_xlfn.IFNA(VLOOKUP(A11,Dashboard!$B$2:$V$1276,21,0),"HAPUS") -> HAPUS
A12: K/37/141024/1 | B12: 45579.601 | C12: K/37/141024/1_45579.600917419 | D12: PT KEONG NUSANTARA ABADI/KHRESNA DJUAINI | E12: 81369381711 | F12: PERALIHAN JUAL BELI | G12: - | H12: TELUK BETUNG | I12: Baynur | J12: Ginta Monita | K12: 45580.374 | L12: ktp susy marduli | M12: PKKPR | V12: SELESAI (LENGKAP) | W12: 45590.486 | X12: =_xlfn.IFNA(VLOOKUP(A12,Dashboard!$B$2:$V$1276,21,0),"HAPUS") -> HAPUS
A13: K/15/141024/4 | B13: 45579.451 | C13: K/15/141024/4_45579.4505724884 | D13: PANGGARA PAGARISI/PANARY SITOPU | E13: 81361444098 | F13: PENINGKATAN HAK | G13: - | H13: NEGERI OLOK GADING | I13: Baynur | J13: Ginta Monita | K13: 45580.374 | L13: Alamat di PBB dan IMB berbeda | M13: IMB nya ruko? | V13: SELESAI (LENGKAP) | W13: 45580.401 | X13: =_xlfn.IFNA(VLOOKUP(A13,Dashboard!$B$2:$V$1276,21,0),"HAPUS") -> HAPUS
A14: K/27/141024/4 | B14: 45579.57 | C14: K/27/141024/4_45579.5701433218 | D14: MURSALIN | E14: 85383885939 | F14: PERALIHAN JUAL BELI | G14: M. 13414/ SUKABUMI | H14: SUKABUMI | I14: Hananda | J14: Ginta Monita | K14: 45580.374 | L14: Renvoi pekerjaan Henny Dewi (belum direnvoi) | V14: SELESAI (LENGKAP) | W14: 45595.359 | X14: =_xlfn.IFNA(VLOOKUP(A14,Dashboard!$B$2:$V$1276,21,0),"HAPUS") -> HAPUS
A15: K/25/141024/3 | B15: 45579.56 | C15: K/25/141024/3_45579.5598141551 | D15: MURSALIN | E15: 85383885939 | F15: PERALIHAN JUAL BELI | G15: M. 133/ SUKARAME BARU- SEKARANG; B. 144/ SUKARAME BARU-DAHULU; B. 4605/SUKARAME I-DAHULU | H15: SUKARAME BARU | I15: Hananda | J15: Ginta Monita | K15: 45580.375 | L15: Renvoi NIB di AJB (15-10-2024) | V15: SELESAI (LENGKAP) | W15: 45593.436 | X15: =_xlfn.IFNA(VLOOKUP(A15,Dashboard!$B$2:$V$1276,21,0),"HAPUS") -> HAPUS
A16: L/33/141024/1 | B16: 45579.592 | C16: L/33/141024/1_45579.5919665972 | D16: MOCHAMAD MA'RUF | E16: 81369994969 | F16: ROYA | G16: M.1540/GUNUNG TERANG;B.17/GU TERANG-DAHULU | H16: GUNUNG TERANG | I16: Nuraini | J16: Fikka | K16: 45580.375 | L16: VALBID | M16: KENAPA SHT PERINGKAT I TIDAK DI ROYA ? | V16: SELESAI (LENGKAP) | W16: 45580.411 | X16: =_xlfn.IFNA(VLOOKUP(A16,Dashboard!$B$2:$V$1276,21,0),"HAPUS") -> HAPUS
A17: K/14/141024/3 | B17: 45579.449 | C17: K/14/141024/3_45579.4491384607 | D17: APRILIA/PANARY SITOPU | E17: 81361444098 | F17: ROYA | G17: M.988/NEGERI OLOK GADING-SEKARANG;B.1050/NEGERI OLOK GADING-DAHULU | H17: NEGERI OLOK GADING | I17: Baynur | J17: Fikka | K17: 45580.376 | V17: SELESAI (LENGKAP) | W17: 45580.419 | X17: =_xlfn.IFNA(VLOOKUP(A17,Dashboard!$B$2:$V$1276,21,0),"HAPUS") -> HAPUS
A18: L/18/141024/1 | B18: 45579.484 | C18: L/18/141024/1_45579.4840388426 | D18: SUNILA HAKI | E18: 82279144608 | F18: BLOKIR | G18: M.331/NUSANTARA PERMAI;B.389/CAMPANG RAYA-DAHULU | H18: NUSANTARA PERMAI | I18: Nuraini | J18: Fikka | K18: 45580.376 | V18: SELESAI (LENGKAP) | W18: 45580.57 | X18: =_xlfn.IFNA(VLOOKUP(A18,Dashboard!$B$2:$V$1276,21,0),"HAPUS") -> BELUM SPS
A19: K/7/141024/1 | C19: K/7/141024/1_ | J19: Fikka | K19: 45580.376 | V19: SELESAI (LENGKAP) | W19: 45580.571 | X19: =_xlfn.IFNA(VLOOKUP(A19,Dashboard!$B$2:$V$1276,21,0),"HAPUS") -> HAPUS
A20: K/26/141024/1 | B20: 45579.566 | C20: K/26/141024/1_45579.5656653125 | D20: KHARISMA MANISHA CECILIYA/ILANUR | E20: 81295653816 | F20: PERALIHAN JUAL BELI | G20: M.2094/CAMPANG JAYA | H20: CAMPANG JAYA | I20: Baynur | J20: Fikka | K20: 45580.376 | L20: PERBAIKI KELURAHAN PADA KUITANSI | V20: SELESAI (LENGKAP) | W20: 45580.449 | X20: =_xlfn.IFNA(VLOOKUP(A20,Dashboard!$B$2:$V$1276,21,0),"HAPUS") -> HAPUS
A21: K/19/141024/1 | B21: 45579.484 | C21: K/19/141024/1_45579.4839514005 | D21: ROSIDA LINGSA KENCANA/RAHMADIYANTI | E21: 82182090051 | F21: PERALIHAN JUAL BELI | G21: M.16678/SUKABUMI | H21: SUKABUMI | I21: Baynur | J21: Fikka | K21: 45580.376 | V21: SELESAI (LENGKAP) | W21: 45580.435 | X21: =_xlfn.IFNA(VLOOKUP(A21,Dashboard!$B$2:$V$1276,21,0),"HAPUS") -> HAPUS
A22: K/16/141024/1 | B22: 45579.464 | C22: K/16/141024/1_45579.4638286343 | D22: TITIK WIJAYANTI/SENDI DINI HARIYATI | E22: 89618401409 | F22: SKPT | G22: M.9137/GEDONG MENENG | H22: GEDONG MENENG | I22: Baynur | J22: Kholfa | K22: 45580.377 | L22: Beda nama pemilik SHAT pada Surat Permohonan KPKNL dengan Fc SHAT terlampir | M22: Kurang input data pemilik SHAT di KKP | V22: SELESAI (LENGKAP) | W22: 45580.406 | X22: =_xlfn.IFNA(VLOOKUP(A22,Dashboard!$B$2:$V$1276,21,0),"HAPUS") -> HAPUS
A23: L/5/141024/1 | B23: 45579.403 | C23: L/5/141024/1_45579.403285787 | D23: SITI NAZROH | E23: 8117208600 | F23: ROYA | G23: M.9974/TANJUNG BARU | H23: TANJUNG BARU | I23: Nuraini | J23: Kholfa | K23: 45580.377 | L23: Beda tgl lahir pemilik pada SHAT dengan Fc KTP terlampir | V23: SELESAI (LENGKAP) | W23: 45580.43 | X23: =_xlfn.IFNA(VLOOKUP(A23,Dashboard!$B$2:$V$1276,21,0),"HAPUS") -> HAPUS
A24: K/12/141024/1 | B24: 45579.446 | C24: K/12/141024/1_45579.4464756366 | D24: META ARIDHOTU PRANATA /PANARY SITOPU | E24: 81361444098 | F24: ROYA | G24: M.3326/LANGKAPURA | H24: LANGKAPURA | I24: Baynur | J24: Kholfa | K24: 45580.377 | V24: SELESAI (LENGKAP) | W24: 45580.43 | X24: =_xlfn.IFNA(VLOOKUP(A24,Dashboard!$B$2:$V$1276,21,0),"HAPUS") -> HAPUS
A25: K/38/141024/1 | B25: 45579.601 | C25: K/38/141024/1_45579.6011142245 | D25: ISMARINA | E25: 81377641549 | F25: PERALIHAN HAK JUAL BELI | G25: M. 3157/ LABUHAN DALAM | H25: LABUHAN DALAM | I25: Hananda | J25: Kholfa | K25: 45580.377 | L25: Surat Pernyataan Kuasa Jual masih berlaku dari pemberi kuasa | V25: SELESAI (LENGKAP) | W25: 45580.435 | X25: =_xlfn.IFNA(VLOOKUP(A25,Dashboard!$B$2:$V$1276,21,0),"HAPUS") -> HAPUS
A26: K/28/141024/1 | B26: 45579.573 | C26: K/28/141024/1_45579.5727725694 | D26: ADE HERDIANYAH/WHINDA YULIANTI | E26: 81255572168 | F26: PERALIHAN JUAL BELI | G26: B.895/BERINGIN JAYA | H26: BERINGIN JAYA | I26: Baynur | J26: Kholfa | K26: 45580.377 | V26: SELESAI (LENGKAP) | W26: 45580.448 | X26: =_xlfn.IFNA(VLOOKUP(A26,Dashboard!$B$2:$V$1276,21,0),"HAPUS") -> BELUM SPS
A27: K/3/141024/1 | C27: K/3/141024/1_ | J27: Kholfa | K27: 45580.377 | V27: SELESAI (LENGKAP) | W27: 45580.456 | X27: =_xlfn.IFNA(VLOOKUP(A27,Dashboard!$B$2:$V$1276,21,0),"HAPUS") -> HAPUS
A28: K/29/141024/1 | B28: 45579.578 | C28: K/29/141024/1_45579.5779375116 | D28: GUNAWAN | E28: 85273192152 | F28: PTPGT PEMECAHAN | G28: M. 2445/ SUKADANA HAM | H28: SUKADANA HAM | I28: Hananda | J28: Maharani | K28: 45580.381 | L28: Beda nama antara KTP (Caecilia Sri Uji Hardiyanti) dan Sertipikat (Sri Uji Hardiyanti) terlalu jauh. Berkas sudah pernah masuk di loket 1 tgl 16/07/2024, lengkapi perbaikan sesuai catatan | V28: SELESAI (LENGKAP) | W28: 45594.362 | X28: =_xlfn.IFNA(VLOOKUP(A28,Dashboard!$B$2:$V$1276,21,0),"HAPUS") -> HAPUS
A29: K/31/141024/1 | B29: 45579.585 | C29: K/31/141024/1_45579.584890625 | D29: APRILLIYANI | E29: 81367846284 | F29: PERUBAHAN HAK | G29: NIBEL 1691/ SUKABUMI INDAH | H29: SUKABUMI INDAH | I29: Hananda | J29: Maharani | K29: 45580.382 | L29: Data tidak di temukan di KKP dan TT | V29: SELESAI (LENGKAP) | W29: 45580.46 | X29: =_xlfn.IFNA(VLOOKUP(A29,Dashboard!$B$2:$V$1276,21,0),"HAPUS") -> HAPUS
A30: L/11/141024/1 | B30: 45579.435 | C30: L/11/141024/1_45579.4347999884 | D30: HENNY INDRIYANI | E30: 81369690601 | F30: ROYA | G30: HM 1505 LABUHAN DALAM & HM 1506 LABUHAN DALAM | H30: LABUHAN DALAM | I30: Deby | J30: Maharani | K30: 45580.383 | V30: SELESAI (LENGKAP) | W30: 45580.489 | X30: =_xlfn.IFNA(VLOOKUP(A30,Dashboard!$B$2:$V$1276,21,0),"HAPUS") -> HAPUS
A31: L/24/141024/1 | B31: 45579.5 | C31: L/24/141024/1_45579.5003502199 | D31: DEWI YULIANA | E31: 82269444244 | F31: ROYA | G31: M.2064/GUNUNG TERANG | H31: GUNUNG TERANG | I31: Nuraini | J31: Maharani | K31: 45580.383 | V31: SELESAI (LENGKAP) | W31: 45580.46 | X31: =_xlfn.IFNA(VLOOKUP(A31,Dashboard!$B$2:$V$1276,21,0),"HAPUS") -> HAPUS
A32: K/40/141024/5 | B32: 45579.608 | C32: K/40/141024/5_45579.6084455787 | D32: MURSALIN | E32: 85383885939 | F32: PERALIHAN JUAL BELI | G32: NIBEL 2507/ SUMUR BATU | H32: SUMUR BATU | I32: Hananda | J32: Maharani | K32: 45580.384 | L32: Pada Surat Permohonan, Surat Kuasa, Surat Pernyataan Absentee, dan Surat Pernyataan BPHTB perbaiki alamat I Made Sukantra | M32: Beda Nama Aya Sophia dan Aya Sofia serta Beda Nama Eddy Mahdi dan Eddi Mahdi | N32: Kenapa di AJB anak Aya Sophia yang bernama Derra Rizka tidak memberi persetujuan ? | O32: AJB hlm 2 perbaiki nomor Akta Kematian, AJB hlm. 3 perbaiki tgl lahir I Made Sukantra dan Nomor NIBEL | P32: Di AJB saksi bernama Cori Anggraini tetapi yang ttd saksinya bernama Selvi Meilinda ? | Q32: Perbaikan ke dua : Poin 2 belum dipenuhi dan AJB setiap hlm kurang paraf | V32: SELESAI (LENGKAP) | W32: 45607.417 | X32: =_xlfn.IFNA(VLOOKUP(A32,Dashboard!$B$2:$V$1276,21,0),"HAPUS") -> HAPUS
A33: K/4/141024/2 | C33: K/4/141024/2_ | J33: Maharani | K33: 45580.384 | V33: SELESAI (LENGKAP) | W33: 45580.586 | X33: =_xlfn.IFNA(VLOOKUP(A33,Dashboard!$B$2:$V$1276,21,0),"HAPUS") -> HAPUS
A34: K/13/141024/2 | B34: 45579.448 | C34: K/13/141024/2_45579.4480105324 | D34: APRILIA/PANARY SITOPU | E34: 81361444098 | F34: ROYA | G34: M.1088/NEGERI OLOK GADING-SEKARANG;B.1201/NEGERI OLOK GADING-DAHULU | H34: NEGERI OLOK GADING | I34: Baynur | J34: Maharani | K34: 45580.466 | V34: SELESAI (LENGKAP) | W34: 45580.469 | X34: =_xlfn.IFNA(VLOOKUP(A34,Dashboard!$B$2:$V$1276,21,0),"HAPUS") -> BELUM SPS
A35: L/35/151024/1 | B35: 45580.585 | C35: L/35/151024/1_45580.5852084491 | D35: FIRMANSYAH/CS | E35: 82278291330 | F35: BN PUTUSAN PENGADILAN (AHLI WARIS) | G35: HM 479/HARAPAN JAYA (DAHULU)-HM 49/KORPRI JAYA (SEKARANG) | H35: KORPRI JAYA | I35: Deby | J35: Kholfa | K35: 45580.666 | L35: NIB 50 BLM VALBID | M35: S.Pernyataan BPHTB blm ditandatangani seluruh ahli waris | N35: Ada catatan Perkara di KKP(terlampir surat keterangan dari PN Tanjungkarang terkait Perkara No.67/Pdt.G/2023/PN.Tjk | O35: Lampirkan Bukti Bayar PBB 2024 | V35: PERBAIKAN | W35: 45581.67 | X35: =_xlfn.IFNA(VLOOKUP(A35,Dashboard!$B$2:$V$1276,21,0),"HAPUS") -> BELUM SPS
A36: K/47/151024/1 | B36: 45580.6 | C36: K/47/151024/1_45580.6001020602 | D36: NEDI HERYANDI/ YULIA IKA W | E36: 811721165 | F36: BN JUAL BELI | G36: B. 176/ LABUHAN RATU RAYA | H36: LABUHAN RATU RAYA | I36: Hananda | J36: Kholfa | K36: 45580.666 | L36: Perbaikan AJB= Alamat Direktur Utama PT, beda dengan Fc KTP terlampir | V36: SELESAI (LENGKAP) | W36: 45588.391 | X36: =_xlfn.IFNA(VLOOKUP(A36,Dashboard!$B$2:$V$1276,21,0),"HAPUS") -> HAPUS
A37: K/23/151024/3 | B37: 45580.48 | C37: K/23/151024/3_45580.4800118287 | D37: RAHMADIYANTI/ SELVI HELINA | E37: +62 821-8209-0051 | F37: BN JUAL BELI | G37: M. 509/ LABUHAN RATU RAYA | H37: LABUHAN RATU RAYA | I37: Hananda | J37: Kholfa | K37: 45580.667 | V37: SELESAI (LENGKAP) | W37: 45581.67 | X37: =_xlfn.IFNA(VLOOKUP(A37,Dashboard!$B$2:$V$1276,21,0),"HAPUS") -> HAPUS
A38: K/11/151024/1 | B38: 45580.424 | C38: K/11/151024/1_45580.4240903357 | D38: Maryanti Kurniawan/ Suprapti R | E38: +62 811-7212-168 | F38: BN Jual Beli | G38: Nibel. M. 1869/ Sepang Jaya | H38: Sepang Jaya | I38: Rapita | J38: Kholfa | K38: 45580.667 | V38: SELESAI (LENGKAP) | W38: 45581.487 | X38: =_xlfn.IFNA(VLOOKUP(A38,Dashboard!$B$2:$V$1276,21,0),"HAPUS") -> HAPUS
A39: K/34/151024/2 | B39: 45580.579 | C39: K/34/151024/2_45580.5789332523 | D39: Ayi Ruhiat/ Eri Yulianti | E39: 81272519799 | F39: BN Hibah | G39: M. 1311/ Beringin Jaya; dahulu B. 2093/ Beringin Raya | H39: Beringin Jaya | I39: Rapita | J39: Kholfa | K39: 45580.667 | L39: Surat Keterlambatan Pendaftaran | V39: SELESAI (LENGKAP) | W39: 45581.436 | X39: =_xlfn.IFNA(VLOOKUP(A39,Dashboard!$B$2:$V$1276,21,0),"HAPUS") -> HAPUS
A40: K/4/151024/1 | B40: 45580.398 | C40: K/4/151024/1_45580.3981238426 | D40: Renaldi Pratama S/ Rahmat Mirzani D | E40: +62 823-7375-9878 | F40: Roya | G40: M. 10315/ Rajabasa | H40: Rajabasa | I40: Rapita | J40: Kholfa | K40: 45580.667 | L40: Beda nama pemilik SHAT dengan Fc KTP terlampir | V40: SELESAI (LENGKAP) | W40: 45589.664 | X40: =_xlfn.IFNA(VLOOKUP(A40,Dashboard!$B$2:$V$1276,21,0),"HAPUS") -> HAPUS
...

Sheet Warkah
A1: No | B1: Kode Tiket | C1: Nomor Sertipikat | D1: Tanggal Input Loket | E1: Jenis Permohonan | F1: Nama Petugas Warkah | G1: Status Sertipikat | H1: Tanggal diserahkan kepada Validator/Back Office | I1: Tanggal Kembali | J1: Tanggal Kembali | K1: Count | L1: Combine | M1: Cek Hapus
A2: 1 | I2: FALSE | K2: 0 | L2: _0 | M2: =_xlfn.IFNA(VLOOKUP(B2,Dashboard!$B$2:$V$1276,21,0),"HAPUS") -> HAPUS
A3: 2 | B3: L/1/141024/1 | C3: HM 9463/GEDUNG MENENG | D3: 45579.361 | E3: ROYA | G3: DISERAHKAN | H3: 45616.458 | I3: FALSE | K3: 1 | L3: DISERAHKAN_1 | M3: =_xlfn.IFNA(VLOOKUP(B3,Dashboard!$B$2:$V$1276,21,0),"HAPUS") -> HAPUS
A4: 3 | B4: L/2/141024/1 | C4: HM 17565/SUKARAME I | D4: 45579.377 | E4: ROYA | F4: Berry | G4: DISERAHKAN | H4: 45579.631 | I4: FALSE | K4: 2 | L4: DISERAHKAN_2 | M4: =_xlfn.IFNA(VLOOKUP(B4,Dashboard!$B$2:$V$1276,21,0),"HAPUS") -> HAPUS
A5: 4 | B5: L/5/141024/1 | C5: M.9974/TANJUNG BARU | D5: 45579.403 | E5: ROYA | F5: Berry | G5: DISERAHKAN | H5: 45579.629 | I5: FALSE | K5: 3 | L5: DISERAHKAN_3 | M5: =_xlfn.IFNA(VLOOKUP(B5,Dashboard!$B$2:$V$1276,21,0),"HAPUS") -> HAPUS
A6: 5 | B6: L/6/141024/1 | C6: HM 154/SUSUNAN BARU | D6: 45579.405 | E6: PLOT SERTIPIKAT HILANG | F6: David | G6: DISERAHKAN | H6: 45579.626 | I6: FALSE | K6: 4 | L6: DISERAHKAN_4 | M6: =_xlfn.IFNA(VLOOKUP(B6,Dashboard!$B$2:$V$1276,21,0),"HAPUS") -> HAPUS
A7: 6 | B7: K/7/141024/1 | C7: M. 631/Pahoman- sekarang; M. 631/Pahoman-Dahulu | D7: 45579.41 | E7: ANGKAT SITA | F7: Berry | G7: DISERAHKAN | H7: 45579.629 | I7: FALSE | K7: 5 | L7: DISERAHKAN_5 | M7: =_xlfn.IFNA(VLOOKUP(B7,Dashboard!$B$2:$V$1276,21,0),"HAPUS") -> HAPUS
A8: 7 | B8: L/8/141024/1 | C8: M.1134/GULAK GALIK | D8: 45579.416 | E8: HAPUS BPHTB | F8: Berry | G8: DISERAHKAN | H8: 45579.63 | I8: FALSE | K8: 6 | L8: DISERAHKAN_6 | M8: =_xlfn.IFNA(VLOOKUP(B8,Dashboard!$B$2:$V$1276,21,0),"HAPUS") -> HAPUS
A9: 8 | B9: K/9/141024/1 | C9: M.11980/JAGABAYA II | D9: 45579.424 | E9: ROYA | F9: Berry | G9: DISERAHKAN | H9: 45579.63 | I9: FALSE | K9: 7 | L9: DISERAHKAN_7 | M9: =_xlfn.IFNA(VLOOKUP(B9,Dashboard!$B$2:$V$1276,21,0),"HAPUS") -> HAPUS
A10: 9 | B10: L/11/141024/1 | C10: HM 1505 LABUHAN DALAM & HM 1506 LABUHAN DALAM | D10: 45579.435 | E10: ROYA | G10: TIDAK DITEMUKAN | I10: FALSE | K10: 1 | L10: TIDAK DITEMUKAN_1 | M10: =_xlfn.IFNA(VLOOKUP(B10,Dashboard!$B$2:$V$1276,21,0),"HAPUS") -> HAPUS
A11: 10 | B11: K/12/141024/1 | C11: M.3326/LANGKAPURA | D11: 45579.446 | E11: ROYA | F11: Berry | G11: DISERAHKAN | H11: 45579.627 | I11: FALSE | K11: 8 | L11: DISERAHKAN_8 | M11: =_xlfn.IFNA(VLOOKUP(B11,Dashboard!$B$2:$V$1276,21,0),"HAPUS") -> HAPUS
A12: 11 | B12: K/13/141024/2 | C12: M.1088/NEGERI OLOK GADING-SEKARANG;B.1201/NEGERI OLOK GADING-DAHULU | D12: 45579.448 | E12: ROYA | F12: Berry | G12: DISERAHKAN | H12: 45579.63 | I12: FALSE | K12: 9 | L12: DISERAHKAN_9 | M12: =_xlfn.IFNA(VLOOKUP(B12,Dashboard!$B$2:$V$1276,21,0),"HAPUS") -> BELUM SPS
A13: 12 | B13: K/14/141024/3 | C13: M.988/NEGERI OLOK GADING-SEKARANG;B.1050/NEGERI OLOK GADING-DAHULU | D13: 45579.449 | E13: ROYA | F13: Berry | G13: DISERAHKAN | H13: 45579.631 | I13: FALSE | K13: 10 | L13: DISERAHKAN_10 | M13: =_xlfn.IFNA(VLOOKUP(B13,Dashboard!$B$2:$V$1276,21,0),"HAPUS") -> HAPUS
A14: 13 | B14: K/16/141024/1 | C14: M.9137/GEDONG MENENG | D14: 45579.464 | E14: SKPT | F14: Berry | G14: DISERAHKAN | H14: 45579.627 | I14: FALSE | K14: 11 | L14: DISERAHKAN_11 | M14: =_xlfn.IFNA(VLOOKUP(B14,Dashboard!$B$2:$V$1276,21,0),"HAPUS") -> HAPUS
A15: 14 | B15: L/17/141024/1 | C15: HM 2144/WAY KANDIS | D15: 45579.478 | E15: ROYA | F15: Berry | G15: DISERAHKAN | H15: 45579.63 | I15: FALSE | K15: 12 | L15: DISERAHKAN_12 | M15: =_xlfn.IFNA(VLOOKUP(B15,Dashboard!$B$2:$V$1276,21,0),"HAPUS") -> HAPUS
A16: 15 | B16: K/19/141024/1 | C16: M.16678/SUKABUMI | D16: 45579.484 | E16: PERALIHAN JUAL BELI | F16: Berry | G16: DISERAHKAN | H16: 45579.627 | I16: TRUE | J16: 45622.503 | K16: 13 | L16: DISERAHKAN_13 | M16: =_xlfn.IFNA(VLOOKUP(B16,Dashboard!$B$2:$V$1276,21,0),"HAPUS") -> HAPUS
A17: 16 | B17: L/18/141024/1 | C17: M.331/NUSANTARA PERMAI;B.389/CAMPANG RAYA-DAHULU | D17: 45579.484 | E17: BLOKIR | F17: Berry | G17: DISERAHKAN | H17: 45579.628 | I17: FALSE | K17: 14 | L17: DISERAHKAN_14 | M17: =_xlfn.IFNA(VLOOKUP(B17,Dashboard!$B$2:$V$1276,21,0),"HAPUS") -> BELUM SPS
A18: 17 | B18: K/20/141024/1 | C18: M.12883/RAJABASA-SEKARANG;B.1210/RAJABASA-DAHULU | D18: 45579.49 | E18: GANDES | F18: Berry | G18: DISERAHKAN | H18: 45579.628 | I18: FALSE | K18: 15 | L18: DISERAHKAN_15 | M18: =_xlfn.IFNA(VLOOKUP(B18,Dashboard!$B$2:$V$1276,21,0),"HAPUS") -> HAPUS
A19: 18 | B19: L/21/141024/1 | C19: HM 1812/TANJUNG SENANG | D19: 45579.493 | E19: ROYA | F19: Berry | G19: DISERAHKAN | H19: 45579.628 | I19: FALSE | K19: 16 | L19: DISERAHKAN_16 | M19: =_xlfn.IFNA(VLOOKUP(B19,Dashboard!$B$2:$V$1276,21,0),"HAPUS") -> HAPUS
A20: 19 | B20: K/22/141024/1 | C20: M. 6977/ TANJUNG SENANG | D20: 45579.497 | E20: PERALIHAN JUAL BELI | F20: Berry | G20: DISERAHKAN | H20: 45579.628 | I20: TRUE | J20: 45645.42 | K20: 17 | L20: DISERAHKAN_17 | M20: =_xlfn.IFNA(VLOOKUP(B20,Dashboard!$B$2:$V$1276,21,0),"HAPUS") -> HAPUS
A21: 20 | B21: K/23/141024/2 | C21: M. 246/ GUNUNG SULAH | D21: 45579.5 | E21: PLOTTING | F21: Berry | G21: DISERAHKAN | H21: 45579.63 | I21: FALSE | K21: 18 | L21: DISERAHKAN_18 | M21: =_xlfn.IFNA(VLOOKUP(B21,Dashboard!$B$2:$V$1276,21,0),"HAPUS") -> HAPUS
A22: 21 | B22: L/24/141024/1 | C22: M.2064/GUNUNG TERANG | D22: 45579.5 | E22: ROYA | F22: Berry | G22: DISERAHKAN | H22: 45579.626 | I22: TRUE | J22: 45602.632 | K22: 19 | L22: DISERAHKAN_19 | M22: =_xlfn.IFNA(VLOOKUP(B22,Dashboard!$B$2:$V$1276,21,0),"HAPUS") -> HAPUS
A23: 22 | B23: K/25/141024/3 | C23: M. 133/ SUKARAME BARU- SEKARANG; B. 144/ SUKARAME BARU-DAHULU; B. 4605/SUKARAME I-DAHULU | D23: 45579.56 | E23: PERALIHAN JUAL BELI | F23: Berry | G23: DISERAHKAN | H23: 45579.629 | I23: FALSE | K23: 20 | L23: DISERAHKAN_20 | M23: =_xlfn.IFNA(VLOOKUP(B23,Dashboard!$B$2:$V$1276,21,0),"HAPUS") -> HAPUS
A24: 23 | B24: K/26/141024/1 | C24: M.2094/CAMPANG JAYA | D24: 45579.566 | E24: PERALIHAN JUAL BELI | F24: Berry | G24: DISERAHKAN | H24: 45579.627 | I24: FALSE | K24: 21 | L24: DISERAHKAN_21 | M24: =_xlfn.IFNA(VLOOKUP(B24,Dashboard!$B$2:$V$1276,21,0),"HAPUS") -> HAPUS
A25: 24 | B25: K/27/141024/4 | C25: M. 13414/ SUKABUMI | D25: 45579.57 | E25: PERALIHAN JUAL BELI | F25: Alfiansyah | G25: DISERAHKAN BT | H25: 45610.364 | I25: FALSE | K25: 1 | L25: DISERAHKAN BT_1 | M25: =_xlfn.IFNA(VLOOKUP(B25,Dashboard!$B$2:$V$1276,21,0),"HAPUS") -> HAPUS
A26: 25 | B26: K/28/141024/1 | C26: B.895/BERINGIN JAYA | D26: 45579.573 | E26: PERALIHAN JUAL BELI | F26: Berry | G26: DISERAHKAN | H26: 45579.63 | I26: FALSE | K26: 22 | L26: DISERAHKAN_22 | M26: =_xlfn.IFNA(VLOOKUP(B26,Dashboard!$B$2:$V$1276,21,0),"HAPUS") -> BELUM SPS
A27: 26 | B27: K/29/141024/1 | C27: M. 2445/ SUKADANA HAM | D27: 45579.578 | E27: PTPGT PEMECAHAN | G27: PROSES | I27: FALSE | K27: 1 | L27: PROSES_1 | M27: =_xlfn.IFNA(VLOOKUP(B27,Dashboard!$B$2:$V$1276,21,0),"HAPUS") -> HAPUS
A28: 27 | B28: K/30/141024/1 | C28: M.2617/WAY KANDIS | D28: 45579.58 | E28: ROYA | F28: Berry | G28: DISERAHKAN | H28: 45579.632 | I28: FALSE | K28: 23 | L28: DISERAHKAN_23 | M28: =_xlfn.IFNA(VLOOKUP(B28,Dashboard!$B$2:$V$1276,21,0),"HAPUS") -> HAPUS
A29: 28 | B29: K/31/141024/1 | C29: NIBEL 1691/ SUKABUMI INDAH | D29: 45579.585 | E29: PERUBAHAN HAK | I29: FALSE | K29: 0 | L29: _0 | M29: =_xlfn.IFNA(VLOOKUP(B29,Dashboard!$B$2:$V$1276,21,0),"HAPUS") -> HAPUS
A30: 29 | B30: L/34/141024/1 | C30: KORPRI JAYA | D30: 45579.592 | E30: PERTAMA KALI | I30: FALSE | K30: 0 | L30: _0 | M30: =_xlfn.IFNA(VLOOKUP(B30,Dashboard!$B$2:$V$1276,21,0),"HAPUS") -> BELUM SPS
A31: 30 | B31: L/33/141024/1 | C31: M.1540/GUNUNG TERANG;B.17/GU TERANG-DAHULU | D31: 45579.592 | E31: ROYA | F31: David | G31: DISERAHKAN BT | H31: 45580.668 | I31: TRUE | J31: 45602.62 | K31: 2 | L31: DISERAHKAN BT_2 | M31: =_xlfn.IFNA(VLOOKUP(B31,Dashboard!$B$2:$V$1276,21,0),"HAPUS") -> HAPUS
A32: 31 | B32: K/32/141024/1 | C32: M.10108/LABUHAN RATU | D32: 45579.593 | E32: GANDES | F32: Bayu | G32: DISERAHKAN | H32: 45580.661 | I32: FALSE | K32: 24 | L32: DISERAHKAN_24 | M32: =_xlfn.IFNA(VLOOKUP(B32,Dashboard!$B$2:$V$1276,21,0),"HAPUS") -> HAPUS
A33: 32 | B33: L/35/141024/1 | C33: M.676/SAWAH BREBES | D33: 45579.596 | E33: ROYA LELANG | F33: David | G33: DISERAHKAN BT | H33: 45580.668 | I33: TRUE | J33: 45615.645 | K33: 3 | L33: DISERAHKAN BT_3 | M33: =_xlfn.IFNA(VLOOKUP(B33,Dashboard!$B$2:$V$1276,21,0),"HAPUS") -> HAPUS
A34: 33 | B34: K/36/141024/1 | C34: M.250/LANGKAPURA BARU | D34: 45579.598 | E34: PERALIHAN JUAL BELI | F34: David | G34: DISERAHKAN BT | H34: 45580.668 | I34: FALSE | K34: 4 | L34: DISERAHKAN BT_4 | M34: =_xlfn.IFNA(VLOOKUP(B34,Dashboard!$B$2:$V$1276,21,0),"HAPUS") -> HAPUS
A35: 34 | B35: K/38/141024/1 | C35: M. 3157/ LABUHAN DALAM | D35: 45579.601 | E35: PERALIHAN HAK JUAL BELI | F35: David | G35: DISERAHKAN BT | H35: 45580.668 | I35: TRUE | J35: 45645.668 | K35: 5 | L35: DISERAHKAN BT_5 | M35: =_xlfn.IFNA(VLOOKUP(B35,Dashboard!$B$2:$V$1276,21,0),"HAPUS") -> HAPUS
A36: 35 | B36: K/39/141024/1 | C36: M.379/KALI BALAU KENCANA | D36: 45579.604 | E36: GANDES | I36: FALSE | K36: 0 | L36: _0 | M36: =_xlfn.IFNA(VLOOKUP(B36,Dashboard!$B$2:$V$1276,21,0),"HAPUS") -> HAPUS
A37: 36 | B37: K/40/141024/5 | C37: NIBEL 2507/ SUMUR BATU | D37: 45579.608 | E37: PERALIHAN JUAL BELI | I37: FALSE | K37: 0 | L37: _0 | M37: =_xlfn.IFNA(VLOOKUP(B37,Dashboard!$B$2:$V$1276,21,0),"HAPUS") -> HAPUS
A38: 37 | B38: K/42/141024/1 | C38: M.10676/KEDATON | D38: 45579.616 | E38: GANDES | I38: FALSE | K38: 0 | L38: _0 | M38: =_xlfn.IFNA(VLOOKUP(B38,Dashboard!$B$2:$V$1276,21,0),"HAPUS") -> HAPUS
A39: 38 | B39: K/41/141024/1 | C39: M. 2283/ GEDONG AIR | D39: 45579.616 | E39: ROYA | F39: David | G39: DISERAHKAN BT | H39: 45580.668 | I39: FALSE | K39: 6 | L39: DISERAHKAN BT_6 | M39: =_xlfn.IFNA(VLOOKUP(B39,Dashboard!$B$2:$V$1276,21,0),"HAPUS") -> HAPUS
A40: 39 | B40: K/43/141024/1 | C40: B.2096/CAMPANG RAYA | D40: 45579.627 | E40: GANDES | I40: FALSE | K40: 0 | L40: _0 | M40: =_xlfn.IFNA(VLOOKUP(B40,Dashboard!$B$2:$V$1276,21,0),"HAPUS") -> HAPUS
...

Sheet Validator
A1: No | B1: Nomor Sertipikat | C1: Nomor Tiket | D1: Tanggal Diserhkan BT SU | E1: Petugas Warkah | F1: Jenis Permohonan | G1: Nama Petugas BT | H1: Status BT | I1: Tanggal Selesai Validasi BT | J1: Nama Petugas Validator SU | K1: Status Validasi SU | L1: Tanggal Selesai Validasi SU | M1: Kesimupulan Validator | N1: Tangal BT SU Selesai | O1: Ceklis | P1: Diberikan kepada Petugas Alih Media | Q1: Ceklis kembali ke Warkah Sementara | R1: DIberikan Kepada Warkah Sementara | S1: Keterangan Validator | T1: Cek Hapus
A2: 1 | B2: M. 6977/ TANJUNG SENANG | C2: K/22/141024/1 | D2: 45579.628 | E2: Berry | F2: PERALIHAN JUAL BELI | G2: Nadian (BT) | H2: SELESAI | I2: 45580.466 | J2: Aprill (SU) | K2: SELESAI | L2: 45581.418 | M2: SELESAI | N2: 45581.418 | O2: FALSE | Q2: TRUE | R2: 45581.42 | T2: =_xlfn.IFNA(VLOOKUP(C2,Dashboard!$B$2:$V$1276,21,0),"HAPUS") -> HAPUS
A3: 2 | B3: M.16678/SUKABUMI | C3: K/19/141024/1 | D3: 45579.627 | E3: Berry | F3: PERALIHAN JUAL BELI | G3: Nadian (BT) | H3: SELESAI | I3: 45580.469 | J3: Aprill (SU) | K3: SELESAI | L3: 45581.418 | M3: SELESAI | N3: 45581.418 | O3: FALSE | Q3: TRUE | R3: 45581.42 | T3: =_xlfn.IFNA(VLOOKUP(C3,Dashboard!$B$2:$V$1276,21,0),"HAPUS") -> HAPUS
A4: 3 | B4: B. 613/ SUMUR PUTRI | C4: K/3/151024/1 | D4: 45580.668 | E4: David | F4: PERALIHAN JUAL BELI | G4: Nadian (BT) | H4: SELESAI | I4: 45580.472 | J4: Aprill (SU) | K4: SELESAI | L4: 45581.418 | M4: SELESAI | N4: 45581.418 | O4: FALSE | Q4: TRUE | R4: 45581.42 | T4: =_xlfn.IFNA(VLOOKUP(C4,Dashboard!$B$2:$V$1276,21,0),"HAPUS") -> HAPUS
A5: 4 | B5: HM 17565/SUKARAME I | C5: L/2/141024/1 | D5: 45579.631 | E5: Berry | F5: ROYA | G5: Afriza (BT) | H5: SELESAI | I5: 45580.701 | J5: Aprill (SU) | K5: SELESAI | L5: 45580.725 | M5: SELESAI | N5: 45580.725 | O5: FALSE | Q5: TRUE | R5: 45581.42 | T5: =_xlfn.IFNA(VLOOKUP(C5,Dashboard!$B$2:$V$1276,21,0),"HAPUS") -> HAPUS
A6: 5 | B6: M.1088/NEGERI OLOK GADING-SEKARANG;B.1201/NEGERI OLOK GADING-DAHULU | C6: K/13/141024/2 | D6: 45579.63 | E6: Berry | F6: ROYA | G6: Afriza (BT) | H6: SELESAI | I6: 45580.701 | J6: Aprill (SU) | K6: SELESAI | L6: 45580.725 | M6: SELESAI | N6: 45580.725 | O6: FALSE | Q6: TRUE | R6: 45581.42 | T6: =_xlfn.IFNA(VLOOKUP(C6,Dashboard!$B$2:$V$1276,21,0),"HAPUS") -> BELUM SPS
A7: 6 | B7: M.988/NEGERI OLOK GADING-SEKARANG;B.1050/NEGERI OLOK GADING-DAHULU | C7: K/14/141024/3 | D7: 45579.631 | E7: Berry | F7: ROYA | G7: Afriza (BT) | H7: SELESAI | I7: 45580.701 | J7: Aprill (SU) | K7: SELESAI | L7: 45581.42 | M7: SELESAI | N7: 45581.42 | O7: FALSE | Q7: TRUE | R7: 45581.42 | T7: =_xlfn.IFNA(VLOOKUP(C7,Dashboard!$B$2:$V$1276,21,0),"HAPUS") -> HAPUS
A8: 7 | B8: B.895/BERINGIN JAYA | C8: K/28/141024/1 | D8: 45579.63 | E8: Berry | F8: PERALIHAN JUAL BELI | G8: Afriza (BT) | H8: SELESAI | I8: 45580.701 | J8: Aprill (SU) | K8: SELESAI | L8: 45580.725 | M8: SELESAI | N8: 45580.725 | O8: FALSE | Q8: TRUE | R8: 45581.42 | T8: =_xlfn.IFNA(VLOOKUP(C8,Dashboard!$B$2:$V$1276,21,0),"HAPUS") -> BELUM SPS
A9: 8 | B9: M.11980/JAGABAYA II | C9: K/9/141024/1 | D9: 45579.63 | E9: Berry | F9: ROYA | G9: Afriza (BT) | H9: SELESAI | I9: 45580.701 | J9: Aprill (SU) | K9: SELESAI | L9: 45580.725 | M9: SELESAI | N9: 45580.725 | O9: FALSE | Q9: TRUE | R9: 45581.42 | T9: =_xlfn.IFNA(VLOOKUP(C9,Dashboard!$B$2:$V$1276,21,0),"HAPUS") -> HAPUS
A10: 9 | B10: HM 2144/WAY KANDIS | C10: L/17/141024/1 | D10: 45579.63 | E10: Berry | F10: ROYA | G10: Afriza (BT) | H10: SELESAI | I10: 45580.701 | J10: Aprill (SU) | K10: SELESAI | L10: 45580.725 | M10: SELESAI | N10: 45580.725 | O10: TRUE | P10: 45616.431 | Q10: / | T10: =_xlfn.IFNA(VLOOKUP(C10,Dashboard!$B$2:$V$1276,21,0),"HAPUS") -> HAPUS
A11: 10 | B11: M.2617/WAY KANDIS | C11: K/30/141024/1 | D11: 45579.632 | E11: Berry | F11: ROYA | G11: Afriza (BT) | H11: SELESAI | I11: 45580.701 | J11: Aprill (SU) | K11: SELESAI | L11: 45581.42 | M11: SELESAI | N11: 45581.42 | O11: FALSE | Q11: TRUE | R11: 45581.42 | T11: =_xlfn.IFNA(VLOOKUP(C11,Dashboard!$B$2:$V$1276,21,0),"HAPUS") -> HAPUS
A12: 11 | B12: M.9974/TANJUNG BARU | C12: L/5/141024/1 | D12: 45579.629 | E12: Berry | F12: ROYA | G12: Afriza (BT) | H12: SELESAI | I12: 45580.701 | J12: Aprill (SU) | K12: SELESAI | L12: 45580.726 | M12: SELESAI | N12: 45580.726 | O12: FALSE | Q12: TRUE | R12: 45581.419 | T12: =_xlfn.IFNA(VLOOKUP(C12,Dashboard!$B$2:$V$1276,21,0),"HAPUS") -> HAPUS
A13: 12 | B13: M. 133/ SUKARAME BARU- SEKARANG; B. 144/ SUKARAME BARU-DAHULU; B. 4605/SUKARAME I-DAHULU | C13: K/25/141024/3 | D13: 45579.629 | E13: Berry | F13: PERALIHAN JUAL BELI | G13: Afriza (BT) | H13: SELESAI | I13: 45580.701 | J13: Aprill (SU) | K13: SELESAI | L13: 45580.727 | M13: SELESAI | N13: 45580.727 | O13: TRUE | P13: 45636.707 | Q13: TRUE | R13: 45581.419 | T13: =_xlfn.IFNA(VLOOKUP(C13,Dashboard!$B$2:$V$1276,21,0),"HAPUS") -> HAPUS
A14: 13 | B14: M. 1952/ Langkapura | C14: K/5/151024/2 | D14: 45580.669 | E14: David | F14: Roya | G14: Afriza (BT) | H14: SELESAI | I14: 45580.701 | J14: Aprill (SU) | K14: SELESAI | L14: 45580.727 | M14: SELESAI | N14: 45580.727 | O14: FALSE | Q14: TRUE | R14: 45581.419 | T14: =_xlfn.IFNA(VLOOKUP(C14,Dashboard!$B$2:$V$1276,21,0),"HAPUS") -> HAPUS
A15: 14 | B15: M.250/LANGKAPURA BARU | C15: K/36/141024/1 | D15: 45580.668 | E15: David | F15: PERALIHAN JUAL BELI | G15: Afriza (BT) | H15: SELESAI | I15: 45580.701 | J15: Aprill (SU) | K15: SELESAI | L15: 45580.728 | M15: SELESAI | N15: 45580.728 | O15: FALSE | Q15: TRUE | R15: 45581.419 | T15: =_xlfn.IFNA(VLOOKUP(C15,Dashboard!$B$2:$V$1276,21,0),"HAPUS") -> HAPUS
A16: 15 | B16: M. 1931/ Campang Jaya | C16: K/6/151024/1 | D16: 45580.667 | E16: David | F16: BN Jual Beli | G16: Afriza (BT) | H16: SELESAI | I16: 45580.701 | J16: Aprill (SU) | K16: SELESAI | L16: 45580.701 | M16: SELESAI | N16: 45580.701 | O16: FALSE | Q16: TRUE | R16: 45581.419 | T16: =_xlfn.IFNA(VLOOKUP(C16,Dashboard!$B$2:$V$1276,21,0),"HAPUS") -> HAPUS
A17: 16 | B17: M. 2283/ GEDONG AIR | C17: K/41/141024/1 | D17: 45580.668 | E17: David | F17: ROYA | G17: Afriza (BT) | H17: SELESAI | I17: 45580.701 | J17: Aprill (SU) | K17: SELESAI | L17: 45580.701 | M17: SELESAI | N17: 45580.701 | O17: FALSE | Q17: TRUE | R17: 45581.419 | T17: =_xlfn.IFNA(VLOOKUP(C17,Dashboard!$B$2:$V$1276,21,0),"HAPUS") -> HAPUS
A18: 17 | B18: B.561/NUSANTARA PERMAI;B.329/CAMPANG RAYA-DAHULU | C18: L/10/151024/1 | D18: 45580.46 | E18: David | F18: PERUBAHAN HAK | G18: Afriza (BT) | H18: SELESAI | I18: 45580.701 | J18: Aprill (SU) | K18: SELESAI | L18: 45580.725 | M18: SELESAI | N18: 45580.725 | O18: TRUE | P18: 45593.599 | Q18: TRUE | R18: 45581.419 | T18: =_xlfn.IFNA(VLOOKUP(C18,Dashboard!$B$2:$V$1276,21,0),"HAPUS") -> BELUM SPS
A19: 18 | B19: M. 10315/ Rajabasa | C19: K/4/151024/1 | D19: 45580.669 | E19: David | F19: Roya | G19: Nadian (BT) | H19: SELESAI | I19: 45580.701 | J19: Aprill (SU) | K19: SELESAI | L19: 45581.415 | M19: SELESAI | N19: 45581.415 | O19: FALSE | Q19: TRUE | R19: 45581.419 | S19: minta di plot ulang tidak sesuai dengan di warkah di kkp | T19: =_xlfn.IFNA(VLOOKUP(C19,Dashboard!$B$2:$V$1276,21,0),"HAPUS") -> HAPUS
A20: 19 | B20: M.2094/CAMPANG JAYA | C20: K/26/141024/1 | D20: 45579.627 | E20: Berry | F20: PERALIHAN JUAL BELI | G20: Nadian (BT) | H20: SELESAI | I20: 45580.701 | J20: Aprill (SU) | K20: SELESAI | L20: 45581.417 | M20: SELESAI | N20: 45581.417 | O20: FALSE | Q20: TRUE | R20: 45581.418 | T20: =_xlfn.IFNA(VLOOKUP(C20,Dashboard!$B$2:$V$1276,21,0),"HAPUS") -> HAPUS
A21: 20 | B21: M.3326/LANGKAPURA | C21: K/12/141024/1 | D21: 45579.627 | E21: Berry | F21: ROYA | G21: Nadian (BT) | H21: SELESAI | I21: 45580.701 | J21: Aprill (SU) | K21: SELESAI | L21: 45581.415 | M21: SELESAI | N21: 45581.415 | O21: FALSE | Q21: TRUE | R21: 45581.418 | S21: minta di plot ulang tidak sesuai dengan di warkah di kkp | T21: =_xlfn.IFNA(VLOOKUP(C21,Dashboard!$B$2:$V$1276,21,0),"HAPUS") -> HAPUS
A22: 21 | B22: M.676/SAWAH BREBES | C22: L/35/141024/1 | D22: 45580.668 | E22: David | F22: ROYA LELANG | G22: Nadian (BT) | H22: SELESAI | I22: 45580.701 | J22: Aprill (SU) | K22: SELESAI | L22: 45581.417 | M22: SELESAI | N22: 45581.417 | O22: FALSE | Q22: TRUE | R22: 45581.418 | T22: =_xlfn.IFNA(VLOOKUP(C22,Dashboard!$B$2:$V$1276,21,0),"HAPUS") -> HAPUS
A23: 22 | B23: M. 3157/ LABUHAN DALAM | C23: K/38/141024/1 | D23: 45580.668 | E23: David | F23: PERALIHAN HAK JUAL BELI | G23: Nadian (BT) | H23: SELESAI | I23: 45580.701 | J23: Aprill (SU) | K23: SELESAI | L23: 45581.374 | M23: SELESAI | N23: 45581.374 | O23: FALSE | Q23: TRUE | R23: 45581.418 | T23: =_xlfn.IFNA(VLOOKUP(C23,Dashboard!$B$2:$V$1276,21,0),"HAPUS") -> HAPUS
A24: 23 | B24: M. 2400/ NOG; M. 811/ Bakung; M. 131/NOG: | C24: K/9/151024/2 | D24: 45580.668 | E24: David | F24: BN Jual Beli | G24: Nadian (BT) | H24: SELESAI | I24: 45580.701 | J24: Aprill (SU) | K24: SELESAI | L24: 45581.415 | M24: SELESAI | N24: 45581.415 | O24: FALSE | Q24: TRUE | R24: 45581.418 | T24: =_xlfn.IFNA(VLOOKUP(C24,Dashboard!$B$2:$V$1276,21,0),"HAPUS") -> HAPUS
A25: 24 | B25: M.2064/GUNUNG TERANG | C25: L/24/141024/1 | D25: 45579.626 | E25: Berry | F25: ROYA | G25: Nadian (BT) | H25: SELESAI | I25: 45580.701 | J25: Aprill (SU) | K25: SELESAI | L25: 45581.37 | M25: SELESAI | N25: 45581.37 | O25: FALSE | Q25: TRUE | R25: 45581.418 | T25: =_xlfn.IFNA(VLOOKUP(C25,Dashboard!$B$2:$V$1276,21,0),"HAPUS") -> HAPUS
A26: 25 | B26: M.9137/GEDONG MENENG | C26: K/16/141024/1 | D26: 45579.627 | E26: Berry | F26: SKPT | G26: Nadian (BT) | H26: SELESAI | I26: 45580.701 | J26: Aprill (SU) | K26: SELESAI | L26: 45581.345 | M26: SELESAI | N26: 45581.345 | O26: FALSE | Q26: TRUE | R26: 45581.418 | T26: =_xlfn.IFNA(VLOOKUP(C26,Dashboard!$B$2:$V$1276,21,0),"HAPUS") -> HAPUS
A27: 26 | B27: HM 1812/TANJUNG SENANG | C27: L/21/141024/1 | D27: 45579.628 | E27: Berry | F27: ROYA | G27: Nadian (BT) | H27: SELESAI | I27: 45580.701 | J27: Aprill (SU) | K27: SELESAI | L27: 45581.346 | M27: SELESAI | N27: 45581.346 | O27: FALSE | Q27: TRUE | R27: 45581.418 | T27: =_xlfn.IFNA(VLOOKUP(C27,Dashboard!$B$2:$V$1276,21,0),"HAPUS") -> HAPUS
A28: 27 | B28: M.1540/GUNUNG TERANG;B.17/GU TERANG-DAHULU | C28: L/33/141024/1 | D28: 45580.668 | E28: David | F28: ROYA | G28: Nadian (BT) | H28: SELESAI | I28: 45580.701 | J28: Aprill (SU) | M28: BT atau SU Belum Valid | O28: FALSE | Q28: TRUE | R28: 45581.42 | S28: minta di plot ulang tidak sesuai dengan di warkah di kkp | T28: =_xlfn.IFNA(VLOOKUP(C28,Dashboard!$B$2:$V$1276,21,0),"HAPUS") -> HAPUS
A29: 28 | B29: HM 1527/RAJABASA NUNYAI (SUPER PRIORITAS) | C29: L/18/151024/1 | D29: 45581.35 | E29: Berry | F29: BN JUAL BELI | G29: Afriza (BT) | H29: SELESAI | I29: 45581.486 | J29: Aprill (SU) | K29: SELESAI | L29: 45581.483 | M29: SELESAI | N29: 45581.483 | O29: TRUE | P29: 45581.483 | Q29: FALSE | T29: =_xlfn.IFNA(VLOOKUP(C29,Dashboard!$B$2:$V$1276,21,0),"HAPUS") -> BELUM SPS
A30: 29 | B30: M. 41/ Kota Sepang | C30: K/13/151024/3 | D30: 45581.408 | E30: Berry | F30: BN Jual Beli | G30: Afriza (BT) | H30: SELESAI | I30: 45581.493 | J30: Bu Eva (SU) | K30: SELESAI | L30: 45582.613 | M30: SELESAI | N30: 45582.613 | O30: FALSE | Q30: TRUE | R30: 45582.613 | T30: =_xlfn.IFNA(VLOOKUP(C30,Dashboard!$B$2:$V$1276,21,0),"HAPUS") -> HAPUS
A31: 30 | B31: M. 3901/ Tanjung Senang | C31: K/14/151024/1 | D31: 45581.35 | E31: Berry | F31: Roya | G31: Afriza (BT) | H31: SELESAI | I31: 45581.584 | J31: Bu Eva (SU) | K31: SELESAI | L31: 45582.613 | M31: SELESAI | N31: 45582.613 | O31: FALSE | Q31: TRUE | R31: 45582.613 | T31: =_xlfn.IFNA(VLOOKUP(C31,Dashboard!$B$2:$V$1276,21,0),"HAPUS") -> HAPUS
A32: 31 | B32: HM 4010/TANJUNG SENANG | C32: L/43/151024/1 | D32: 45581.35 | E32: Berry | F32: ROYA | G32: Afriza (BT) | H32: SELESAI | I32: 45581.587 | J32: Bu Eva (SU) | K32: SELESAI | L32: 45582.613 | M32: SELESAI | N32: 45582.613 | O32: FALSE | Q32: TRUE | R32: 45582.613 | T32: =_xlfn.IFNA(VLOOKUP(C32,Dashboard!$B$2:$V$1276,21,0),"HAPUS") -> BELUM SPS
A33: 32 | B33: M. 2589/ Kota Baru | C33: K/42/151024/3 | D33: 45581.35 | E33: Berry | F33: BN Kewarisan | G33: Afriza (BT) | H33: SELESAI | I33: 45581.589 | J33: Bu Eva (SU) | K33: SELESAI | L33: 45582.613 | M33: SELESAI | N33: 45582.613 | O33: FALSE | Q33: TRUE | R33: 45582.613 | T33: =_xlfn.IFNA(VLOOKUP(C33,Dashboard!$B$2:$V$1276,21,0),"HAPUS") -> BELUM SPS
A34: 33 | B34: M. 1311/ Beringin Jaya; dahulu B. 2093/ Beringin Raya | C34: K/34/151024/2 | D34: 45581.409 | E34: David | F34: BN Hibah | G34: Afriza (BT) | H34: SELESAI | I34: 45581.592 | J34: Bu Eva (SU) | K34: SELESAI | L34: 45582.613 | M34: SELESAI | N34: 45582.613 | O34: FALSE | Q34: TRUE | R34: 45582.613 | T34: =_xlfn.IFNA(VLOOKUP(C34,Dashboard!$B$2:$V$1276,21,0),"HAPUS") -> HAPUS
A35: 34 | B35: M.550/KORPRI RAYA-SEKARANG;M.10135/SUKARAME U-DAHULU | C35: K/48/151024/1 | D35: 45581.409 | E35: David | F35: PERALIHAN JUAL BELI | G35: Afriza (BT) | H35: SELESAI | I35: 45581.595 | J35: Bu Eva (SU) | K35: SELESAI | L35: 45583.71 | M35: SELESAI | N35: 45583.71 | O35: FALSE | Q35: TRUE | R35: 45583.71 | T35: =_xlfn.IFNA(VLOOKUP(C35,Dashboard!$B$2:$V$1276,21,0),"HAPUS") -> HAPUS
A36: 35 | B36: HM 401/KALI BALAU KENCANA | C36: L/26/151024/1 | D36: 45581.35 | E36: Berry | F36: ROYA | G36: Afriza (BT) | H36: SELESAI | I36: 45581.624 | J36: Bu Eva (SU) | K36: SELESAI | L36: 45594.404 | M36: SELESAI | N36: 45594.404 | O36: FALSE | Q36: FALSE | T36: =_xlfn.IFNA(VLOOKUP(C36,Dashboard!$B$2:$V$1276,21,0),"HAPUS") -> BELUM SPS
A37: 36 | B37: M. 2418/ KEDAUNG | C37: K/16/151024/2 | D37: 45581.421 | E37: David | F37: BN JUAL BELI | G37: Afriza (BT) | H37: SELESAI | I37: 45581.628 | J37: Bu Eva (SU) | K37: SELESAI | L37: 45582.613 | M37: SELESAI | N37: 45582.613 | O37: FALSE | Q37: TRUE | R37: 45582.613 | T37: =_xlfn.IFNA(VLOOKUP(C37,Dashboard!$B$2:$V$1276,21,0),"HAPUS") -> HAPUS
A38: 37 | B38: M. 2424/ KEDAUNG | C38: K/15/151024/1 | D38: 45581.421 | E38: David | F38: BN JUAL BELI | G38: Afriza (BT) | H38: SELESAI | I38: 45581.628 | J38: Bu Eva (SU) | K38: SELESAI | L38: 45582.613 | M38: SELESAI | N38: 45582.613 | O38: FALSE | Q38: TRUE | R38: 45582.613 | T38: =_xlfn.IFNA(VLOOKUP(C38,Dashboard!$B$2:$V$1276,21,0),"HAPUS") -> HAPUS
A39: 38 | B39: M. 13602/ SEGALA MIDER | C39: K/17/151024/1 | D39: 45581.349 | E39: Berry | F39: BN JUAL BELI | G39: Nadian (BT) | H39: SELESAI | I39: 45581.647 | J39: Bu Eva (SU) | K39: SELESAI | L39: 45582.614 | M39: SELESAI | N39: 45582.614 | O39: FALSE | Q39: TRUE | R39: 45582.614 | T39: =_xlfn.IFNA(VLOOKUP(C39,Dashboard!$B$2:$V$1276,21,0),"HAPUS") -> HAPUS
A40: 39 | B40: M. 509/ LABUHAN RATU RAYA | C40: K/23/151024/3 | D40: 45581.348 | E40: David | F40: BN JUAL BELI | G40: Nadian (BT) | H40: SELESAI | I40: 45581.647 | J40: Bu Eva (SU) | K40: SELESAI | L40: 45582.615 | M40: SELESAI | N40: 45582.615 | O40: FALSE | Q40: TRUE | R40: 45582.615 | T40: =_xlfn.IFNA(VLOOKUP(C40,Dashboard!$B$2:$V$1276,21,0),"HAPUS") -> HAPUS
...

Sheet Alih Media
A1: No | B1: Nomor Tiket | C1: Nomor Sertipikat | D1: Jenis Permohonan | E1: Tanggal Selesai Validasi | F1: Validator | G1: Nama Petugas Alih Media BT | H1: Status Alih Media BT | I1: Tanggal Selesai Alih Media BT | J1: Nama Petugas Alih Media SU | K1: Status Alih Media SU | L1: Tanggal Selesai Alih Media SU | M1: Kesimupulan Alih Media | N1: Tangal BT SU Selesai | O1: Ceklis Ke Warkah | P1: Pengembalian BT SU Ke Ruang Warkah | Q1: Ceklis Ke Loket u/ SPS | R1: Tanggal Kirim ke Loket U/ SPS | S1: Keterangan Petugas Alih Media (Kendala dan Hambatan) | T1: Cetak Tim Hady | U1: Count Tim Hady | V1: Combine Tim Hady | W1: Count List Hady | X1: Cetak Tim Rendy | Y1: Cek Hapus
A2: 1 | B2: K/23/151024/3 | C2: M. 509/ LABUHAN RATU RAYA | D2: BN JUAL BELI | E2: 45582.615 | F2: Nadian (BT) Bu Eva (SU) | G2: Olla (PHP) | H2: SELESAI | I2: 45595.659 | J2: Sri Sekar | K2: SELESAI | L2: 45594.685 | M2: SELESAI | N2: 45594.685 | O2: FALSE | Q2: FALSE | T2: 45587 | U2: 1 | V2: 45587/1 | W2: 1 | Y2: =_xlfn.IFNA(VLOOKUP(B2,Dashboard!$B$2:$V$1276,21,0),"HAPUS") -> HAPUS
A3: 2 | B3: K/38/141024/1 | C3: M. 3157/ LABUHAN DALAM | D3: PERALIHAN HAK JUAL BELI | E3: 45581.418 | F3: Nadian (BT) Aprill (SU) | G3: Olla (PHP) | H3: SELESAI | I3: 45596.487 | J3: Sri Sekar | K3: SELESAI | L3: 45594.717 | M3: SELESAI | N3: 45594.717 | O3: FALSE | T3: 45587 | U3: 2 | V3: 45587/2 | W3: 1 | Y3: =_xlfn.IFNA(VLOOKUP(B3,Dashboard!$B$2:$V$1276,21,0),"HAPUS") -> HAPUS
A4: 3 | B4: K/34/171024/2 | C4: M. 2924/ Sukarame II | D4: BN Jual Beli | E4: 45587.668 | F4: Nadian (BT) Bu Eva (SU) | G4: Olla (PHP) | H4: SELESAI | I4: 45596.488 | J4: Sri Sekar | K4: SELESAI | L4: 45594.719 | M4: SELESAI | N4: 45594.719 | O4: FALSE | T4: 45587 | U4: 3 | V4: 45587/3 | W4: 1 | Y4: =_xlfn.IFNA(VLOOKUP(B4,Dashboard!$B$2:$V$1276,21,0),"HAPUS") -> HAPUS
A5: 4 | B5: K/17/151024/1 | C5: M. 13602/ SEGALA MIDER | D5: BN JUAL BELI | E5: 45582.614 | F5: Nadian (BT) Bu Eva (SU) | G5: Olla (PHP) | H5: SELESAI | I5: 45622.511 | M5: BT atau SU Belum Alih Media | O5: FALSE | S5: Perlu perbaikan bidang sekitar | T5: 45587 | U5: 4 | V5: 45587/4 | W5: 1 | Y5: =_xlfn.IFNA(VLOOKUP(B5,Dashboard!$B$2:$V$1276,21,0),"HAPUS") -> HAPUS
A6: 5 | B6: K/20/161024/1 | C6: M.48/KALI BALAU KENCANA-SEKARANG;B.46/KALI BALAU KENCANA -DAHULU | D6: PERALIHAN KEWARISAN | F6: Afriza (BT) Bu Eva (SU) | G6: Olla (PHP) | H6: SELESAI | I6: 45596.487 | J6: Sri Sekar | K6: SELESAI | L6: 45594.691 | M6: SELESAI | N6: 45594.691 | O6: FALSE | T6: 45587 | U6: 5 | V6: 45587/5 | W6: 1 | Y6: =_xlfn.IFNA(VLOOKUP(B6,Dashboard!$B$2:$V$1276,21,0),"HAPUS") -> HAPUS
A7: 6 | B7: K/28/141024/1 | C7: B.895/BERINGIN JAYA | D7: PERALIHAN JUAL BELI | E7: 45581.42 | F7: Afriza (BT) Aprill (SU) | G7: Olla (PHP) | H7: SELESAI | I7: 45596.49 | J7: Sri Sekar | K7: SELESAI | L7: 45594.708 | M7: SELESAI | N7: 45594.708 | O7: FALSE | T7: 45587 | U7: 6 | V7: 45587/6 | W7: 1 | Y7: =_xlfn.IFNA(VLOOKUP(B7,Dashboard!$B$2:$V$1276,21,0),"HAPUS") -> BELUM SPS
A8: 7 | B8: K/19/141024/1 | C8: M.16678/SUKABUMI | D8: PERALIHAN JUAL BELI | E8: 45581.42 | F8: Nadian (BT) Aprill (SU) | G8: Olla (PHP) | H8: SELESAI | I8: 45596.484 | J8: Sri Sekar | K8: SELESAI | L8: 45594.702 | M8: SELESAI | N8: 45594.702 | O8: FALSE | T8: 45587 | U8: 7 | V8: 45587/7 | W8: 1 | Y8: =_xlfn.IFNA(VLOOKUP(B8,Dashboard!$B$2:$V$1276,21,0),"HAPUS") -> HAPUS
A9: 8 | B9: K/26/141024/1 | C9: M.2094/CAMPANG JAYA | D9: PERALIHAN JUAL BELI | E9: 45581.418 | F9: Nadian (BT) Aprill (SU) | G9: Olla (PHP) | H9: SELESAI | I9: 45639.683 | J9: Sri Sekar | K9: SELESAI | L9: 45638.239 | M9: SELESAI | N9: 45638.239 | O9: FALSE | S9: Perlu perbaikan bidang sekitar | T9: 45587 | U9: 8 | V9: 45587/8 | W9: 1 | Y9: =_xlfn.IFNA(VLOOKUP(B9,Dashboard!$B$2:$V$1276,21,0),"HAPUS") -> HAPUS
